<?xml version="1.0" ?>
<robot name="iai-kitchen" version="1.0">
  <material name="table_grey">
    <color rgba="0.255 0.62 0.223 1.0"/>
  </material>
  <material name="round_table_grey">
    <color rgba="0.8 0.8 0.8 1.0"/>
  </material>
  <material name="wall_pink">
    <color rgba="0.95 0.43 0.96 1.0"/>
  </material>
  <material name="shelf_blue">
    <color rgba="0.59 0.88 0.9 1.0"/>
  </material>
  <material name="shelf_door_green">
    <color rgba="0.64 0.87 0.82 1.0"/>
  </material>
  <material name="shelf_openable_handle_red">
    <color rgba="0.74 0.25 0.25 1.0"/>
  </material>
  <material name="shelf_hohc_handle_red">
    <color rgba="0.74 0.25 0.25 1.0"/>
  </material>
  <material name="door_green">
    <color rgba="0.0 0.31 0.22 1.0"/>
  </material>
  <material name="hinge_red">
    <color rgba="0.74 0.25 0.25 1.0"/>
  </material>
  <material name="handle_blue">
    <color rgba="0.3 0.5 0.78 1.0"/>
  </material>
  <material name="bucket_grey">
    <color rgba="0.8 0.8 0.8 1.0"/>
  </material>
  <material name="white">
    <color rgba="1.0 1.0 1.0 1.0"/>
  </material>
  <material name="orange">
    <color rgba="1.0 0.7 0.0 1.0"/>
  </material>
  <material name="handle_white">
    <color rgba="1.0 1.0 1.0 1.0"/>
  </material>
  <material name="bottom_white">
    <color rgba="1.0 1.0 1.0 1.0"/>
  </material>
  <material name="frame_wood">
    <color rgba="0.68 0.63 0.47 1.0"/>
  </material>
  <material name="handle_grey">
    <color rgba="0.7 0.7 0.7 1.0"/>
  </material>
  <material name="dishwasher_table_color">
    <color rgba="0.255 0.62 0.223 1.0"/>
  </material>
  <material name="dishwasher_robocup_table_color">
    <color rgba="0.255 0.62 0.223 1.0"/>
  </material>
  <material name="color_grey">
    <color rgba="0.8 0.8 0.8 1.0"/>
  </material>
  <material name="color_red">
    <color rgba="1.0 0.0 0.0 1.0"/>
  </material>
  <material name="color_blue">
    <color rgba="0.0 0.0 1.0 1.0"/>
  </material>
  <material name="simple_couch_color_grey">
    <color rgba="0.8 0.8 0.8 1.0"/>
  </material>
  <material name="simple_couch_color_red">
    <color rgba="1.0 0.0 0.0 1.0"/>
  </material>
  <material name="simple_couch_color_blue">
    <color rgba="0.0 0.0 1.0 1.0"/>
  </material>
  <material name="trashcan_color">
    <color rgba="0.8 0.8 0.8 1.0"/>
  </material>
  <material name="chair_color">
    <color rgba="0.0 0.0 0.5 1.0"/>
  </material>
  <material name="coathanger_color">
    <color rgba="0.255 0.62 0.223 1.0"/>
  </material>
  <material name="lamp_color">
    <color rgba="0.8 0.8 0.8 1.0"/>
  </material>
  <link name="tv_table:tv_table:table_center">
    <inertial>
      <origin xyz="0.0 0.0 0.0" rpy="0.0 0.0 0.0"/>
      <mass value="1.0"/>
      <inertia ixx="0.1" ixy="0.0" ixz="0.0" iyy="0.1" iyz="0.0" izz="0.1"/>
    </inertial>
    <visual>
      <origin xyz="0.0 0.0 -0.369" rpy="0.0 0.0 0.0"/>
      <geometry>
        <box size="0.412 1.2 0.738"/>
      </geometry>
      <material name="table_grey"/>
    </visual>
    <collision>
      <origin xyz="0.0 0.0 -0.369" rpy="0.0 0.0 0.0"/>
      <geometry>
        <box size="0.412 1.2 0.738"/>
      </geometry>
    </collision>
  </link>
  <link name="tv_table:tv_table:table_origin"/>
  <link name="tv_table:tv_table:table_front_edge_center"/>
  <joint name="tv_table:tv_table:table_origin_joint" type="fixed">
    <origin xyz="5.96 -0.24 0.0" rpy="0.0 0.0 3.17"/>
    <parent link="urdf_offset"/>
    <child link="tv_table:tv_table:table_origin"/>
  </joint>
  <joint name="tv_table:tv_table:center_joint" type="fixed">
    <origin xyz="0.206 0.6 0.738" rpy="0.0 0.0 0.0"/>
    <parent link="tv_table:tv_table:table_origin"/>
    <child link="tv_table:tv_table:table_center"/>
  </joint>
  <joint name="tv_table:tv_table:table_front_edge_center_joint" type="fixed">
    <origin xyz="0.0 0.6 0.738" rpy="0.0 0.0 0.0"/>
    <parent link="tv_table:tv_table:table_origin"/>
    <child link="tv_table:tv_table:table_front_edge_center"/>
  </joint>
  <link name="hallway_cabinet:hallway_cabinet:table_center">
    <inertial>
      <origin xyz="0.0 0.0 0.0" rpy="0.0 0.0 0.0"/>
      <mass value="1.0"/>
      <inertia ixx="0.1" ixy="0.0" ixz="0.0" iyy="0.1" iyz="0.0" izz="0.1"/>
    </inertial>
    <visual>
      <origin xyz="0.0 0.0 -0.404" rpy="0.0 0.0 0.0"/>
      <geometry>
        <box size="0.3503 0.795 0.808"/>
      </geometry>
      <material name="table_grey"/>
    </visual>
    <collision>
      <origin xyz="0.0 0.0 -0.404" rpy="0.0 0.0 0.0"/>
      <geometry>
        <box size="0.3503 0.795 0.808"/>
      </geometry>
    </collision>
  </link>
  <link name="hallway_cabinet:hallway_cabinet:table_origin"/>
  <link name="hallway_cabinet:hallway_cabinet:table_front_edge_center"/>
  <joint name="hallway_cabinet:hallway_cabinet:table_origin_joint" type="fixed">
    <origin xyz="2.41 -0.675 0.0" rpy="0.0 0.0 3.17"/>
    <parent link="urdf_offset"/>
    <child link="hallway_cabinet:hallway_cabinet:table_origin"/>
  </joint>
  <joint name="hallway_cabinet:hallway_cabinet:center_joint" type="fixed">
    <origin xyz="0.17515 0.3975 0.808" rpy="0.0 0.0 0.0"/>
    <parent link="hallway_cabinet:hallway_cabinet:table_origin"/>
    <child link="hallway_cabinet:hallway_cabinet:table_center"/>
  </joint>
  <joint name="hallway_cabinet:hallway_cabinet:table_front_edge_center_joint" type="fixed">
    <origin xyz="0.0 0.3975 0.808" rpy="0.0 0.0 0.0"/>
    <parent link="hallway_cabinet:hallway_cabinet:table_origin"/>
    <child link="hallway_cabinet:hallway_cabinet:table_front_edge_center"/>
  </joint>
  <link name="desk:desk:table_center">
    <inertial>
      <origin xyz="0.0 0.0 0.0" rpy="0.0 0.0 0.0"/>
      <mass value="1.0"/>
      <inertia ixx="0.1" ixy="0.0" ixz="0.0" iyy="0.1" iyz="0.0" izz="0.1"/>
    </inertial>
    <visual>
      <origin xyz="0.0 0.0 -0.3715" rpy="0.0 0.0 0.0"/>
      <geometry>
        <box size="0.901 2.017 0.743"/>
      </geometry>
      <material name="table_grey"/>
    </visual>
    <collision>
      <origin xyz="0.0 0.0 -0.3715" rpy="0.0 0.0 0.0"/>
      <geometry>
        <box size="0.901 2.017 0.743"/>
      </geometry>
    </collision>
  </link>
  <link name="desk:desk:table_origin"/>
  <link name="desk:desk:table_front_edge_center"/>
  <joint name="desk:desk:table_origin_joint" type="fixed">
    <origin xyz="2.33 2.49 0.0" rpy="0.0 0.0 -1.53"/>
    <parent link="urdf_offset"/>
    <child link="desk:desk:table_origin"/>
  </joint>
  <joint name="desk:desk:center_joint" type="fixed">
    <origin xyz="0.4505 1.0085 0.743" rpy="0.0 0.0 0.0"/>
    <parent link="desk:desk:table_origin"/>
    <child link="desk:desk:table_center"/>
  </joint>
  <joint name="desk:desk:table_front_edge_center_joint" type="fixed">
    <origin xyz="0.0 1.0085 0.743" rpy="0.0 0.0 0.0"/>
    <parent link="desk:desk:table_origin"/>
    <child link="desk:desk:table_front_edge_center"/>
  </joint>
  <link name="dinner_table:dinner_table:table_center">
    <inertial>
      <origin xyz="0.0 0.0 0.0" rpy="0.0 0.0 0.0"/>
      <mass value="1.0"/>
      <inertia ixx="0.1" ixy="0.0" ixz="0.0" iyy="0.1" iyz="0.0" izz="0.1"/>
    </inertial>
    <visual>
      <origin xyz="0.0 0.0 -0.385" rpy="0.0 0.0 0.0"/>
      <geometry>
        <box size="0.782 2.0 0.77"/>
      </geometry>
      <material name="table_grey"/>
    </visual>
    <collision>
      <origin xyz="0.0 0.0 -0.385" rpy="0.0 0.0 0.0"/>
      <geometry>
        <box size="0.782 2.0 0.77"/>
      </geometry>
    </collision>
  </link>
  <link name="dinner_table:dinner_table:table_origin"/>
  <link name="dinner_table:dinner_table:table_front_edge_center"/>
  <joint name="dinner_table:dinner_table:table_origin_joint" type="fixed">
    <origin xyz="7.42 3.69 0.0" rpy="0.0 0.0 0.05"/>
    <parent link="urdf_offset"/>
    <child link="dinner_table:dinner_table:table_origin"/>
  </joint>
  <joint name="dinner_table:dinner_table:center_joint" type="fixed">
    <origin xyz="0.391 1.0 0.77" rpy="0.0 0.0 0.0"/>
    <parent link="dinner_table:dinner_table:table_origin"/>
    <child link="dinner_table:dinner_table:table_center"/>
  </joint>
  <joint name="dinner_table:dinner_table:table_front_edge_center_joint" type="fixed">
    <origin xyz="0.0 1.0 0.77" rpy="0.0 0.0 0.0"/>
    <parent link="dinner_table:dinner_table:table_origin"/>
    <child link="dinner_table:dinner_table:table_front_edge_center"/>
  </joint>
  <link name="kitchen_counter:kitchen_counter:table_center">
    <inertial>
      <origin xyz="0.0 0.0 0.0" rpy="0.0 0.0 0.0"/>
      <mass value="1.0"/>
      <inertia ixx="0.1" ixy="0.0" ixz="0.0" iyy="0.1" iyz="0.0" izz="0.1"/>
    </inertial>
    <visual>
      <origin xyz="0.0 0.0 -0.4525" rpy="0.0 0.0 0.0"/>
      <geometry>
        <box size="0.68 1.82 0.905"/>
      </geometry>
      <material name="table_grey"/>
    </visual>
    <collision>
      <origin xyz="0.0 0.0 -0.4525" rpy="0.0 0.0 0.0"/>
      <geometry>
        <box size="0.68 1.82 0.905"/>
      </geometry>
    </collision>
  </link>
  <link name="kitchen_counter:kitchen_counter:table_origin"/>
  <link name="kitchen_counter:kitchen_counter:table_front_edge_center"/>
  <joint name="kitchen_counter:kitchen_counter:table_origin_joint" type="fixed">
    <origin xyz="10.2 5.06 0.0" rpy="0.0 0.0 0.05"/>
    <parent link="urdf_offset"/>
    <child link="kitchen_counter:kitchen_counter:table_origin"/>
  </joint>
  <joint name="kitchen_counter:kitchen_counter:center_joint" type="fixed">
    <origin xyz="0.34 0.91 0.905" rpy="0.0 0.0 0.0"/>
    <parent link="kitchen_counter:kitchen_counter:table_origin"/>
    <child link="kitchen_counter:kitchen_counter:table_center"/>
  </joint>
  <joint name="kitchen_counter:kitchen_counter:table_front_edge_center_joint" type="fixed">
    <origin xyz="0.0 0.91 0.905" rpy="0.0 0.0 0.0"/>
    <parent link="kitchen_counter:kitchen_counter:table_origin"/>
    <child link="kitchen_counter:kitchen_counter:table_front_edge_center"/>
  </joint>
  <link name="suturo_couch:couch:place_one">
    <inertial>
      <origin xyz="0.0 0.0 0.0" rpy="0.0 0.0 0.0"/>
      <mass value="1.0"/>
      <inertia ixx="0.1" ixy="0.0" ixz="0.0" iyy="0.1" iyz="0.0" izz="0.1"/>
    </inertial>
    <visual>
      <origin xyz="0.0 0.0 0.15" rpy="0.0 0.0 0.0"/>
      <geometry>
        <box size="0.65 1.45 0.3"/>
      </geometry>
      <material name="color_grey"/>
    </visual>
    <collision>
      <origin xyz="0.0 0.0 0.0" rpy="0.0 0.0 0.0"/>
      <geometry>
        <box size="0.65 1.45 0.3"/>
      </geometry>
    </collision>
  </link>
  <link name="suturo_couch:couch:place_two">
    <inertial>
      <origin xyz="0.0 0.0 0.0" rpy="0.0 0.0 0.0"/>
      <mass value="1.0"/>
      <inertia ixx="0.1" ixy="0.0" ixz="0.0" iyy="0.1" iyz="0.0" izz="0.1"/>
    </inertial>
  </link>
  <link name="suturo_couch:couch:place_three">
    <inertial>
      <origin xyz="0.0 0.0 0.0" rpy="0.0 0.0 0.0"/>
      <mass value="1.0"/>
      <inertia ixx="0.1" ixy="0.0" ixz="0.0" iyy="0.1" iyz="0.0" izz="0.1"/>
    </inertial>
  </link>
  <joint name="suturo_couch:couch:couch_origin_joint" type="fixed">
    <origin xyz="10.5 -0.1 0.0" rpy="0.0 0.0 0.05"/>
    <parent link="urdf_offset"/>
    <child link="suturo_couch:couch:place_one"/>
  </joint>
  <joint name="suturo_couch:couch:couch_left_joint" type="fixed">
    <origin xyz="0.0 -0.3625 0.15" rpy="0.0 0.0 0.0"/>
    <parent link="suturo_couch:couch:place_one"/>
    <child link="suturo_couch:couch:place_two"/>
  </joint>
  <joint name="suturo_couch:couch:couch_right_joint" type="fixed">
    <origin xyz="0.0 0.3625 0.15" rpy="0.0 0.0 0.0"/>
    <parent link="suturo_couch:couch:place_one"/>
    <child link="suturo_couch:couch:place_three"/>
  </joint>
  <link name="coffee_table:coffee_table:table_center">
    <inertial>
      <origin xyz="0.0 0.0 0.0" rpy="0.0 0.0 0.0"/>
      <mass value="1.0"/>
      <inertia ixx="0.1" ixy="0.0" ixz="0.0" iyy="0.1" iyz="0.0" izz="0.1"/>
    </inertial>
    <visual>
      <origin xyz="0.0 0.0 -0.245" rpy="0.0 0.0 0.0"/>
      <geometry>
        <cylinder radius="0.45" length="0.49"/>
      </geometry>
      <material name="round_table_grey"/>
    </visual>
    <collision>
      <origin xyz="0.0 0.0 -0.245" rpy="0.0 0.0 0.0"/>
      <geometry>
        <cylinder radius="0.45" length="0.49"/>
      </geometry>
    </collision>
  </link>
  <link name="coffee_table:coffee_table:table_origin"/>
  <link name="coffee_table:coffee_table:table_front_edge_center"/>
  <joint name="coffee_table:coffee_table:table_origin_joint" type="fixed">
    <origin xyz="8.91 -0.24 0.0" rpy="0.0 0.0 0.05"/>
    <parent link="urdf_offset"/>
    <child link="coffee_table:coffee_table:table_origin"/>
  </joint>
  <joint name="coffee_table:coffee_table:center_joint" type="fixed">
    <origin xyz="0.45 0.0 0.49" rpy="0.0 0.0 0.0"/>
    <parent link="coffee_table:coffee_table:table_origin"/>
    <child link="coffee_table:coffee_table:table_center"/>
  </joint>
  <joint name="coffee_table:coffee_table:table_front_edge_center_joint" type="fixed">
    <origin xyz="0.0 0.0 0.49" rpy="0.0 0.0 0.0"/>
    <parent link="coffee_table:coffee_table:table_origin"/>
    <child link="coffee_table:coffee_table:table_front_edge_center"/>
  </joint>
  <link name="shelf:shelf:shelf_origin"/>
  <link name="shelf:shelf:shelf_center"/>
  <link name="shelf:shelf:shelf_base_center"/>
  <joint name="shelf:shelf:shelf_origin_joint" type="fixed">
    <origin xyz="2.09 4.87 0.0" rpy="0.0 0.0 3.2"/>
    <parent link="urdf_offset"/>
    <child link="shelf:shelf:shelf_origin"/>
  </joint>
  <joint name="shelf:shelf:shelf_center_joint" type="fixed">
    <origin xyz="0.1375 0.3 0.7" rpy="0.0 0.0 0.0"/>
    <parent link="shelf:shelf:shelf_origin"/>
    <child link="shelf:shelf:shelf_center"/>
  </joint>
  <joint name="shelf:shelf:shelf_base_center_joint" type="fixed">
    <origin xyz="0.1375 0.3 0.0" rpy="0.0 0.0 0.0"/>
    <parent link="shelf:shelf:shelf_origin"/>
    <child link="shelf:shelf:shelf_base_center"/>
  </joint>
  <link name="shelf:shelf:shelf_back">
    <inertial>
      <origin xyz="0.0 0.0 0.0" rpy="0.0 0.0 0.0"/>
      <mass value="1.0"/>
      <inertia ixx="0.1" ixy="0.0" ixz="0.0" iyy="0.1" iyz="0.0" izz="0.1"/>
    </inertial>
    <visual>
      <origin xyz="0.0 0.0 0.0" rpy="0.0 0.0 0.0"/>
      <geometry>
        <box size="0.01 0.6 1.4"/>
      </geometry>
      <material name="shelf_blue"/>
    </visual>
    <collision>
      <origin xyz="0.0 0.0 0.0" rpy="0.0 0.0 0.0"/>
      <geometry>
        <box size="0.01 0.6 1.4"/>
      </geometry>
    </collision>
  </link>
  <joint name="shelf:shelf:shelf_back:joint" type="fixed">
    <origin xyz="0.275 0.3 0.7" rpy="0.0 0.0 0.0"/>
    <parent link="shelf:shelf:shelf_origin"/>
    <child link="shelf:shelf:shelf_back"/>
  </joint>
  <link name="shelf:shelf:shelf_right_side">
    <inertial>
      <origin xyz="0.0 0.0 0.0" rpy="0.0 0.0 0.0"/>
      <mass value="1.0"/>
      <inertia ixx="0.1" ixy="0.0" ixz="0.0" iyy="0.1" iyz="0.0" izz="0.1"/>
    </inertial>
    <visual>
      <origin xyz="0.0 0.0 0.0" rpy="0.0 0.0 0.0"/>
      <geometry>
        <box size="0.275 0.01 1.4"/>
      </geometry>
      <material name="shelf_blue"/>
    </visual>
    <collision>
      <origin xyz="0.0 0.0 0.0" rpy="0.0 0.0 0.0"/>
      <geometry>
        <box size="0.275 0.01 1.4"/>
      </geometry>
    </collision>
  </link>
  <joint name="shelf:shelf:shelf_right_side:joint" type="fixed">
    <origin xyz="0.1375 0.0 0.7" rpy="0.0 0.0 0.0"/>
    <parent link="shelf:shelf:shelf_origin"/>
    <child link="shelf:shelf:shelf_right_side"/>
  </joint>
  <link name="shelf:shelf:shelf_left_side">
    <inertial>
      <origin xyz="0.0 0.0 0.0" rpy="0.0 0.0 0.0"/>
      <mass value="1.0"/>
      <inertia ixx="0.1" ixy="0.0" ixz="0.0" iyy="0.1" iyz="0.0" izz="0.1"/>
    </inertial>
    <visual>
      <origin xyz="0.0 0.0 0.0" rpy="0.0 0.0 0.0"/>
      <geometry>
        <box size="0.275 0.01 1.4"/>
      </geometry>
      <material name="shelf_blue"/>
    </visual>
    <collision>
      <origin xyz="0.0 0.0 0.0" rpy="0.0 0.0 0.0"/>
      <geometry>
        <box size="0.275 0.01 1.4"/>
      </geometry>
    </collision>
  </link>
  <joint name="shelf:shelf:shelf_left_side:joint" type="fixed">
    <origin xyz="0.1375 0.6 0.7" rpy="0.0 0.0 0.0"/>
    <parent link="shelf:shelf:shelf_origin"/>
    <child link="shelf:shelf:shelf_left_side"/>
  </joint>
  <link name="shelf:shelf:shelf_floor_0">
    <inertial>
      <origin xyz="0.0 0.0 0.0" rpy="0.0 0.0 0.0"/>
      <mass value="1.0"/>
      <inertia ixx="0.1" ixy="0.0" ixz="0.0" iyy="0.1" iyz="0.0" izz="0.1"/>
    </inertial>
    <visual>
      <origin xyz="0.0 0.0 -0.02" rpy="0.0 0.0 0.0"/>
      <geometry>
        <box size="0.275 0.6 0.04"/>
      </geometry>
      <material name="shelf_blue"/>
    </visual>
    <collision>
      <origin xyz="0.0 0.0 -0.02" rpy="0.0 0.0 0.0"/>
      <geometry>
        <box size="0.275 0.6 0.04"/>
      </geometry>
    </collision>
  </link>
  <joint name="shelf:shelf:shelf_floor_0:joint" type="fixed">
    <origin xyz="0.0 0.0 0.115" rpy="0.0 0.0 0.0"/>
    <parent link="shelf:shelf:shelf_base_center"/>
    <child link="shelf:shelf:shelf_floor_0"/>
  </joint>
  <link name="shelf:shelf:shelf_floor_1">
    <inertial>
      <origin xyz="0.0 0.0 0.0" rpy="0.0 0.0 0.0"/>
      <mass value="1.0"/>
      <inertia ixx="0.1" ixy="0.0" ixz="0.0" iyy="0.1" iyz="0.0" izz="0.1"/>
    </inertial>
    <visual>
      <origin xyz="0.0 0.0 -0.02" rpy="0.0 0.0 0.0"/>
      <geometry>
        <box size="0.275 0.6 0.04"/>
      </geometry>
      <material name="shelf_blue"/>
    </visual>
    <collision>
      <origin xyz="0.0 0.0 -0.02" rpy="0.0 0.0 0.0"/>
      <geometry>
        <box size="0.275 0.6 0.04"/>
      </geometry>
    </collision>
  </link>
  <joint name="shelf:shelf:shelf_floor_1:joint" type="fixed">
    <origin xyz="0.0 0.0 0.54" rpy="0.0 0.0 0.0"/>
    <parent link="shelf:shelf:shelf_base_center"/>
    <child link="shelf:shelf:shelf_floor_1"/>
  </joint>
  <link name="shelf:shelf:shelf_floor_2">
    <inertial>
      <origin xyz="0.0 0.0 0.0" rpy="0.0 0.0 0.0"/>
      <mass value="1.0"/>
      <inertia ixx="0.1" ixy="0.0" ixz="0.0" iyy="0.1" iyz="0.0" izz="0.1"/>
    </inertial>
    <visual>
      <origin xyz="0.0 0.0 -0.02" rpy="0.0 0.0 0.0"/>
      <geometry>
        <box size="0.275 0.6 0.04"/>
      </geometry>
      <material name="shelf_blue"/>
    </visual>
    <collision>
      <origin xyz="0.0 0.0 -0.02" rpy="0.0 0.0 0.0"/>
      <geometry>
        <box size="0.275 0.6 0.04"/>
      </geometry>
    </collision>
  </link>
  <joint name="shelf:shelf:shelf_floor_2:joint" type="fixed">
    <origin xyz="0.0 0.0 0.96" rpy="0.0 0.0 0.0"/>
    <parent link="shelf:shelf:shelf_base_center"/>
    <child link="shelf:shelf:shelf_floor_2"/>
  </joint>
  <link name="shelf:shelf:shelf_floor_3">
    <inertial>
      <origin xyz="0.0 0.0 0.0" rpy="0.0 0.0 0.0"/>
      <mass value="1.0"/>
      <inertia ixx="0.1" ixy="0.0" ixz="0.0" iyy="0.1" iyz="0.0" izz="0.1"/>
    </inertial>
    <visual>
      <origin xyz="0.0 0.0 -0.02" rpy="0.0 0.0 0.0"/>
      <geometry>
        <box size="0.275 0.6 0.04"/>
      </geometry>
      <material name="shelf_blue"/>
    </visual>
    <collision>
      <origin xyz="0.0 0.0 -0.02" rpy="0.0 0.0 0.0"/>
      <geometry>
        <box size="0.275 0.6 0.04"/>
      </geometry>
    </collision>
  </link>
  <joint name="shelf:shelf:shelf_floor_3:joint" type="fixed">
    <origin xyz="0.0 0.0 1.39" rpy="0.0 0.0 0.0"/>
    <parent link="shelf:shelf:shelf_base_center"/>
    <child link="shelf:shelf:shelf_floor_3"/>
  </joint>
  <joint name="wall_1_center_joint" type="fixed">
    <origin xyz="10.14 6.91 0.3" rpy="0 0 0"/>
    <parent link="urdf_offset"/>
    <child link="wall_1_link"/>
  </joint>
  <link name="wall_1_link">
    <inertial>
      <origin xyz="0.0 0.0 0.0" rpy="0.0 0.0 0.0"/>
      <mass value="1.0"/>
      <inertia ixx="0.1" ixy="0.0" ixz="0.0" iyy="0.1" iyz="0.0" izz="0.1"/>
    </inertial>
    <visual>
      <origin xyz="0.0 0.0 0.0" rpy="0.0 0.0 0.03029375991877435"/>
      <geometry>
        <box size="1.3206059215375345 0.06 0.6"/>
      </geometry>
      <material name="wall_pink"/>
    </visual>
    <collision>
      <origin xyz="0.0 0.0 0.0" rpy="0.0 0.0 0.03029375991877435"/>
      <geometry>
        <box size="1.3206059215375345 0.06 0.6"/>
      </geometry>
    </collision>
  </link>
  <joint name="wall_2_center_joint" type="fixed">
    <origin xyz="10.85 4.3149999999999995 0.3" rpy="0 0 0"/>
    <parent link="urdf_offset"/>
    <child link="wall_2_link"/>
  </joint>
  <link name="wall_2_link">
    <inertial>
      <origin xyz="0.0 0.0 0.0" rpy="0.0 0.0 0.0"/>
      <mass value="1.0"/>
      <inertia ixx="0.1" ixy="0.0" ixz="0.0" iyy="0.1" iyz="0.0" izz="0.1"/>
    </inertial>
    <visual>
      <origin xyz="0.0 0.0 0.0" rpy="0.0 0.0 1.5707963267948966"/>
      <geometry>
        <box size="1.37 0.06 0.6"/>
      </geometry>
      <material name="wall_pink"/>
    </visual>
    <collision>
      <origin xyz="0.0 0.0 0.0" rpy="0.0 0.0 1.5707963267948966"/>
      <geometry>
        <box size="1.37 0.06 0.6"/>
      </geometry>
    </collision>
  </link>
  <joint name="wall_3_center_joint" type="fixed">
    <origin xyz="1.76 4.545 0.3" rpy="0 0 0"/>
    <parent link="urdf_offset"/>
    <child link="wall_3_link"/>
  </joint>
  <link name="wall_3_link">
    <inertial>
      <origin xyz="0.0 0.0 0.0" rpy="0.0 0.0 0.0"/>
      <mass value="1.0"/>
      <inertia ixx="0.1" ixy="0.0" ixz="0.0" iyy="0.1" iyz="0.0" izz="0.1"/>
    </inertial>
    <visual>
      <origin xyz="0.0 0.0 0.0" rpy="0.0 0.0 1.5707963267948966"/>
      <geometry>
        <box size="1.6300000000000003 0.06 0.6"/>
      </geometry>
      <material name="wall_pink"/>
    </visual>
    <collision>
      <origin xyz="0.0 0.0 0.0" rpy="0.0 0.0 1.5707963267948966"/>
      <geometry>
        <box size="1.6300000000000003 0.06 0.6"/>
      </geometry>
    </collision>
  </link>
  <joint name="wall_4_center_joint" type="fixed">
    <origin xyz="5.55 -1.665 0.3" rpy="0 0 0"/>
    <parent link="urdf_offset"/>
    <child link="wall_4_link"/>
  </joint>
  <link name="wall_4_link">
    <inertial>
      <origin xyz="0.0 0.0 0.0" rpy="0.0 0.0 0.0"/>
      <mass value="1.0"/>
      <inertia ixx="0.1" ixy="0.0" ixz="0.0" iyy="0.1" iyz="0.0" izz="0.1"/>
    </inertial>
    <visual>
      <origin xyz="0.0 0.0 0.0" rpy="0.0 0.0 1.5707963267948966"/>
      <geometry>
        <box size="0.42999999999999994 0.06 0.6"/>
      </geometry>
      <material name="wall_pink"/>
    </visual>
    <collision>
      <origin xyz="0.0 0.0 0.0" rpy="0.0 0.0 1.5707963267948966"/>
      <geometry>
        <box size="0.42999999999999994 0.06 0.6"/>
      </geometry>
    </collision>
  </link>
  <joint name="wall_5_center_joint" type="fixed">
    <origin xyz="11.0 0.925 0.3" rpy="0 0 0"/>
    <parent link="urdf_offset"/>
    <child link="wall_5_link"/>
  </joint>
  <link name="wall_5_link">
    <inertial>
      <origin xyz="0.0 0.0 0.0" rpy="0.0 0.0 0.0"/>
      <mass value="1.0"/>
      <inertia ixx="0.1" ixy="0.0" ixz="0.0" iyy="0.1" iyz="0.0" izz="0.1"/>
    </inertial>
    <visual>
      <origin xyz="0.0 0.0 0.0" rpy="0.0 0.0 1.5707963267948966"/>
      <geometry>
        <box size="1.25 0.06 0.6"/>
      </geometry>
      <material name="wall_pink"/>
    </visual>
    <collision>
      <origin xyz="0.0 0.0 0.0" rpy="0.0 0.0 1.5707963267948966"/>
      <geometry>
        <box size="1.25 0.06 0.6"/>
      </geometry>
    </collision>
  </link>
  <joint name="wall_6_center_joint" type="fixed">
    <origin xyz="1.9 2.0 0.3" rpy="0 0 0"/>
    <parent link="urdf_offset"/>
    <child link="wall_6_link"/>
  </joint>
  <link name="wall_6_link">
    <inertial>
      <origin xyz="0.0 0.0 0.0" rpy="0.0 0.0 0.0"/>
      <mass value="1.0"/>
      <inertia ixx="0.1" ixy="0.0" ixz="0.0" iyy="0.1" iyz="0.0" izz="0.1"/>
    </inertial>
    <visual>
      <origin xyz="0.0 0.0 0.0" rpy="0.0 0.0 1.5707963267948966"/>
      <geometry>
        <box size="2.0 0.06 0.6"/>
      </geometry>
      <material name="wall_pink"/>
    </visual>
    <collision>
      <origin xyz="0.0 0.0 0.0" rpy="0.0 0.0 1.5707963267948966"/>
      <geometry>
        <box size="2.0 0.06 0.6"/>
      </geometry>
    </collision>
  </link>
  <joint name="wall_7_center_joint" type="fixed">
    <origin xyz="5.25 4.775 0.3" rpy="0 0 0"/>
    <parent link="urdf_offset"/>
    <child link="wall_7_link"/>
  </joint>
  <link name="wall_7_link">
    <inertial>
      <origin xyz="0.0 0.0 0.0" rpy="0.0 0.0 0.0"/>
      <mass value="1.0"/>
      <inertia ixx="0.1" ixy="0.0" ixz="0.0" iyy="0.1" iyz="0.0" izz="0.1"/>
    </inertial>
    <visual>
      <origin xyz="0.0 0.0 0.0" rpy="0.0 0.0 1.5707963267948966"/>
      <geometry>
        <box size="1.1499999999999995 0.06 0.6"/>
      </geometry>
      <material name="wall_pink"/>
    </visual>
    <collision>
      <origin xyz="0.0 0.0 0.0" rpy="0.0 0.0 1.5707963267948966"/>
      <geometry>
        <box size="1.1499999999999995 0.06 0.6"/>
      </geometry>
    </collision>
  </link>
  <joint name="wall_8_center_joint" type="fixed">
    <origin xyz="6.125 6.725 0.3" rpy="0 0 0"/>
    <parent link="urdf_offset"/>
    <child link="wall_8_link"/>
  </joint>
  <link name="wall_8_link">
    <inertial>
      <origin xyz="0.0 0.0 0.0" rpy="0.0 0.0 0.0"/>
      <mass value="1.0"/>
      <inertia ixx="0.1" ixy="0.0" ixz="0.0" iyy="0.1" iyz="0.0" izz="0.1"/>
    </inertial>
    <visual>
      <origin xyz="0.0 0.0 0.0" rpy="0.0 0.0 0.02856365783875954"/>
      <geometry>
        <box size="1.7507141400011597 0.06 0.6"/>
      </geometry>
      <material name="wall_pink"/>
    </visual>
    <collision>
      <origin xyz="0.0 0.0 0.0" rpy="0.0 0.0 0.02856365783875954"/>
      <geometry>
        <box size="1.7507141400011597 0.06 0.6"/>
      </geometry>
    </collision>
  </link>
  <joint name="world_hallway:hallway:room_joint" type="fixed">
    <origin xyz="3.75 -0.446 -0.05" rpy="0.0 0.0 0.0"/>
    <parent link="urdf_offset"/>
    <child link="hallway:hallway:room_center_link"/>
  </joint>
  <link name="hallway:hallway:room_center_link">
    <inertial>
      <origin xyz="0.0 0.0 0.0" rpy="0.0 0.0 0.0"/>
      <mass value="1.0"/>
      <inertia ixx="0.1" ixy="0.0" ixz="0.0" iyy="0.1" iyz="0.0" izz="0.1"/>
    </inertial>
    <visual>
      <geometry>
        <box size="3.39 3.99 0.01"/>
      </geometry>
      <material name="hallway:hallway:color">
        <color rgba="0.0 0.0 1.0 0.1"/>
      </material>
    </visual>
    <collision>
      <geometry>
        <box size="3.39 3.99 0.01"/>
      </geometry>
    </collision>
  </link>
  <joint name="room_hallway_entry:entry:connection_joint" type="fixed">
    <origin xyz="-1.3399999999999999 0.946 0.0" rpy="0.0 0.0 0.0"/>
    <parent link="hallway:hallway:room_center_link"/>
    <child link="hallway_entry:entry:link"/>
  </joint>
  <link name="hallway_entry:entry:link"/>
  <joint name="room_hallway_living_room_exit:exit:connection_joint" type="fixed">
    <origin xyz="1.7800000000000002 0.666 0.0" rpy="0.0 0.0 0.0"/>
    <parent link="hallway:hallway:room_center_link"/>
    <child link="hallway_living_room_exit:exit:link"/>
  </joint>
  <link name="hallway_living_room_exit:exit:link"/>
  <joint name="room_hallway_office_exit:exit:connection_joint" type="fixed">
    <origin xyz="1.17 2.106 0.0" rpy="0.0 0.0 0.0"/>
    <parent link="hallway:hallway:room_center_link"/>
    <child link="hallway_office_exit:exit:link"/>
  </joint>
  <link name="hallway_office_exit:exit:link"/>
  <joint name="world_living_room:living_room:room_joint" type="fixed">
    <origin xyz="8.33 -0.2 -0.05" rpy="0.0 0.0 0.0"/>
    <parent link="urdf_offset"/>
    <child link="living_room:living_room:room_center_link"/>
  </joint>
  <link name="living_room:living_room:room_center_link">
    <inertial>
      <origin xyz="0.0 0.0 0.0" rpy="0.0 0.0 0.0"/>
      <mass value="1.0"/>
      <inertia ixx="0.1" ixy="0.0" ixz="0.0" iyy="0.1" iyz="0.0" izz="0.1"/>
    </inertial>
    <visual>
      <geometry>
        <box size="5.65 4.1 0.01"/>
      </geometry>
      <material name="living_room:living_room:color">
        <color rgba="0.5 0.5 0.0 0.1"/>
      </material>
    </visual>
    <collision>
      <geometry>
        <box size="5.65 4.1 0.01"/>
      </geometry>
    </collision>
  </link>
  <joint name="room_living_room_hallway_entry_exit:entry_exit:connection_joint" type="fixed">
    <origin xyz="-2.8 0.42000000000000004 0.0" rpy="0.0 0.0 0.0"/>
    <parent link="living_room:living_room:room_center_link"/>
    <child link="living_room_hallway_entry_exit:entry_exit:link"/>
  </joint>
  <link name="living_room_hallway_entry_exit:entry_exit:link"/>
  <joint name="room_living_room_kitchen_entry_exit:entry_exit:connection_joint" type="fixed">
    <origin xyz="0.4800000000000004 2.1 0.0" rpy="0.0 0.0 0.0"/>
    <parent link="living_room:living_room:room_center_link"/>
    <child link="living_room_kitchen_entry_exit:entry_exit:link"/>
  </joint>
  <link name="living_room_kitchen_entry_exit:entry_exit:link"/>
  <joint name="world_iai_kitchen:kitchen:room_joint" type="fixed">
    <origin xyz="8.1 4.3 -0.05" rpy="0.0 0.0 0.0"/>
    <parent link="urdf_offset"/>
    <child link="iai_kitchen:kitchen:room_center_link"/>
  </joint>
  <link name="iai_kitchen:kitchen:room_center_link">
    <inertial>
      <origin xyz="0.0 0.0 0.0" rpy="0.0 0.0 0.0"/>
      <mass value="1.0"/>
      <inertia ixx="0.1" ixy="0.0" ixz="0.0" iyy="0.1" iyz="0.0" izz="0.1"/>
    </inertial>
    <visual>
      <geometry>
        <box size="5.57 4.9 0.01"/>
      </geometry>
      <material name="iai_kitchen:kitchen:color">
        <color rgba="0.0 1.0 0.0 0.1"/>
      </material>
    </visual>
    <collision>
      <geometry>
        <box size="5.57 4.9 0.01"/>
      </geometry>
    </collision>
  </link>
  <joint name="room_kitchen_living_room_entry_exit:entry_exit:connection_joint" type="fixed">
    <origin xyz="0.7100000000000009 -4.08 0.0" rpy="0.0 0.0 0.0"/>
    <parent link="iai_kitchen:kitchen:room_center_link"/>
    <child link="kitchen_living_room_entry_exit:entry_exit:link"/>
  </joint>
  <link name="kitchen_living_room_entry_exit:entry_exit:link"/>
  <joint name="room_kitchen_office_entry_exit:entry_exit:connection_joint" type="fixed">
    <origin xyz="-2.76 -0.7199999999999998 0.0" rpy="0.0 0.0 0.0"/>
    <parent link="iai_kitchen:kitchen:room_center_link"/>
    <child link="kitchen_office_entry_exit:entry_exit:link"/>
  </joint>
  <link name="kitchen_office_entry_exit:entry_exit:link"/>
  <joint name="world_office:office:room_joint" type="fixed">
    <origin xyz="3.4 4.09 -0.05" rpy="0.0 0.0 0.0"/>
    <parent link="urdf_offset"/>
    <child link="office:office:room_center_link"/>
  </joint>
  <link name="office:office:room_center_link">
    <inertial>
      <origin xyz="0.0 0.0 0.0" rpy="0.0 0.0 0.0"/>
      <mass value="1.0"/>
      <inertia ixx="0.1" ixy="0.0" ixz="0.0" iyy="0.1" iyz="0.0" izz="0.1"/>
    </inertial>
    <visual>
      <geometry>
        <box size="3.66 4.92 0.01"/>
      </geometry>
      <material name="office:office:color">
        <color rgba="1.0 0.0 0.0 0.1"/>
      </material>
    </visual>
    <collision>
      <geometry>
        <box size="3.66 4.92 0.01"/>
      </geometry>
    </collision>
  </link>
  <joint name="room_office_living_room_entry_exit:entry_exit:connection_joint" type="fixed">
    <origin xyz="1.94 -0.5099999999999998 0.0" rpy="0.0 0.0 0.0"/>
    <parent link="office:office:room_center_link"/>
    <child link="office_living_room_entry_exit:entry_exit:link"/>
  </joint>
  <link name="office_living_room_entry_exit:entry_exit:link"/>
  <joint name="room_office_hallway_entry_exit:exit:connection_joint" type="fixed">
    <origin xyz="1.52 -2.4299999999999997 0.0" rpy="0.0 0.0 0.0"/>
    <parent link="office:office:room_center_link"/>
    <child link="office_hallway_entry_exit:exit:link"/>
  </joint>
  <link name="office_hallway_entry_exit:exit:link"/>
  <joint name="room_office_exit:exit:connection_joint" type="fixed">
    <origin xyz="1.3199999999999998 3.38 0.0" rpy="0.0 0.0 0.0"/>
    <parent link="office:office:room_center_link"/>
    <child link="office_exit:exit:link"/>
  </joint>
  <link name="office_exit:exit:link"/>
  <joint name="world_arena:arena:room_joint" type="fixed">
    <origin xyz="6.4 2.27 -0.05" rpy="0.0 0.0 0.0"/>
    <parent link="urdf_offset"/>
    <child link="arena:arena:room_center_link"/>
  </joint>
  <link name="arena:arena:room_center_link">
    <inertial>
      <origin xyz="0.0 0.0 0.0" rpy="0.0 0.0 0.0"/>
      <mass value="1.0"/>
      <inertia ixx="0.1" ixy="0.0" ixz="0.0" iyy="0.1" iyz="0.0" izz="0.1"/>
    </inertial>
    <visual>
      <geometry>
        <box size="9.5 9.3 0.01"/>
      </geometry>
      <material name="arena:arena:color">
        <color rgba="0.0 0.0 1.0 0.1"/>
      </material>
    </visual>
    <collision>
      <geometry>
        <box size="9.5 9.3 0.01"/>
      </geometry>
    </collision>
  </link>
  <joint name="room_arena_entry:entry:connection_joint" type="fixed">
    <origin xyz="-3.99 -1.77 0.0" rpy="0.0 0.0 0.0"/>
    <parent link="arena:arena:room_center_link"/>
    <child link="arena_entry:entry:link"/>
  </joint>
  <link name="arena_entry:entry:link"/>
  <joint name="room_arena_exit:exit:connection_joint" type="fixed">
    <origin xyz="-1.6800000000000006 5.199999999999999 0.0" rpy="0.0 0.0 0.0"/>
    <parent link="arena:arena:room_center_link"/>
    <child link="arena_exit:exit:link"/>
  </joint>
  <link name="arena_exit:exit:link"/>
  <link name="iai_kitchen:arena:door_center">
    <inertial>
      <origin xyz="0.0 0.0 0.0" rpy="0.0 0.0 0.0"/>
      <mass value="1.0"/>
      <inertia ixx="0.1" ixy="0.0" ixz="0.0" iyy="0.1" iyz="0.0" izz="0.1"/>
    </inertial>
    <visual>
      <origin xyz="0.4275 0.0 0.0" rpy="0.0 0.0 0.0"/>
      <geometry>
        <box size="0.855 0.038 2.0"/>
      </geometry>
      <material name="door_green"/>
    </visual>
    <collision>
      <origin xyz="0.4275 0.0 0.0" rpy="0.0 0.0 0.0"/>
      <geometry>
        <box size="0.855 0.038 2.0"/>
      </geometry>
    </collision>
  </link>
  <link name="iai_kitchen:arena:door_hinge">
    <inertial>
      <origin xyz="0.0 0.0 0.0" rpy="0.0 0.0 0.0"/>
      <mass value="1.0"/>
      <inertia ixx="0.1" ixy="0.0" ixz="0.0" iyy="0.1" iyz="0.0" izz="0.1"/>
    </inertial>
    <visual>
      <origin xyz="0.0 0.0 0.0" rpy="0.0 0.0 0.0"/>
      <geometry>
        <box size="0.05 0.05 2.0"/>
      </geometry>
      <material name="hinge_red"/>
    </visual>
    <collision>
      <origin xyz="0.0 0.0 0.0" rpy="0.0 0.0 0.0"/>
      <geometry>
        <box size="0.05 0.05 2.0"/>
      </geometry>
    </collision>
  </link>
  <link name="iai_kitchen:arena:door_handle_link">
    <inertial>
      <origin xyz="0.0 0.0 0.0" rpy="0.0 0.0 0.0"/>
      <mass value="1.0"/>
      <inertia ixx="0.1" ixy="0.0" ixz="0.0" iyy="0.1" iyz="0.0" izz="0.1"/>
    </inertial>
    <visual>
      <origin xyz="0.0 0.0 0.0" rpy="0.0 0.0 0.0"/>
      <geometry>
        <cylinder radius="0.013" length="0.1"/>
      </geometry>
    </visual>
    <collision>
      <origin xyz="0.0 0.0 0.0" rpy="0.0 0.0 0.0"/>
      <geometry>
        <cylinder radius="0.013" length="0.1"/>
      </geometry>
    </collision>
  </link>
  <gazebo reference="iai_kitchen:arena:door_handle_link">
    <turnGravityOff>true</turnGravityOff>
  </gazebo>
  <link name="iai_kitchen:arena:door_handle_outside">
    <inertial>
      <origin xyz="0.0 0.0 0.0" rpy="0.0 0.0 0.0"/>
      <mass value="1.0"/>
      <inertia ixx="0.1" ixy="0.0" ixz="0.0" iyy="0.1" iyz="0.0" izz="0.1"/>
    </inertial>
    <visual>
      <origin xyz="0.0 0.0 0.0" rpy="0.0 0.0 0.0"/>
      <geometry>
        <box size="0.015 0.15 0.01"/>
      </geometry>
      <material name="handle_blue"/>
    </visual>
    <collision>
      <origin xyz="0.0 0.0 0.0" rpy="0.0 0.0 0.0"/>
      <geometry>
        <box size="0.015 0.15 0.01"/>
      </geometry>
    </collision>
  </link>
  <gazebo reference="iai_kitchen:arena:door_handle_outside">
    <turnGravityOff>true</turnGravityOff>
  </gazebo>
  <link name="iai_kitchen:arena:door_handle_inside">
    <inertial>
      <origin xyz="0.0 0.0 0.0" rpy="0.0 0.0 0.0"/>
      <mass value="1.0"/>
      <inertia ixx="0.1" ixy="0.0" ixz="0.0" iyy="0.1" iyz="0.0" izz="0.1"/>
    </inertial>
    <visual>
      <origin xyz="0.0 0.0 0.0" rpy="0.0 0.0 0.0"/>
      <geometry>
        <box size="0.012 0.12 0.01"/>
      </geometry>
      <material name="handle_blue"/>
    </visual>
    <collision>
      <origin xyz="0.0 0.0 0.0" rpy="0.0 0.0 0.0"/>
      <geometry>
        <box size="0.015 0.15 0.01"/>
      </geometry>
    </collision>
  </link>
  <gazebo reference="iai_kitchen:arena:door_handle_inside">
    <turnGravityOff>true</turnGravityOff>
  </gazebo>
  <joint name="iai_kitchen:arena:door_origin_revolute_joint" type="revolute">
    <origin xyz="0.0 0.0 0.0" rpy="0.0 0.0 1.57"/>
    <axis xyz="0.0 0.0 1.0"/>
    <parent link="iai_kitchen:arena:door_hinge"/>
    <child link="iai_kitchen:arena:door_center"/>
    <limit effort="100.0" lower="-1.4" upper="0.0" velocity="10.0"/>
  </joint>
  <joint name="iai_kitchen:arena:door_hinge_joint" type="fixed">
    <origin xyz="1.961 0.08 1.04" rpy="0.0 0.0 0.0"/>
    <axis xyz="0.0 0.0 0.0"/>
    <parent link="urdf_offset"/>
    <child link="iai_kitchen:arena:door_hinge"/>
    <limit effort="1.0" lower="0.0" upper="1.5708" velocity="1.0"/>
  </joint>
  <joint name="iai_kitchen:arena:door_handle_joint" type="revolute">
    <origin xyz="0.82 0.0 0.02" rpy="1.5707963267948966 0.0 0.0"/>
    <axis xyz="0.0 0.0 1.0"/>
    <parent link="iai_kitchen:arena:door_center"/>
    <child link="iai_kitchen:arena:door_handle_link"/>
    <limit effort="1.0" lower="0.0" upper="0.6283185307179586" velocity="1.0"/>
  </joint>
  <joint name="iai_kitchen:arena:door_handle_inside_joint" type="fixed">
    <origin xyz="-0.069 0.0 0.06" rpy="0.0 0.0 1.5707963267948966"/>
    <parent link="iai_kitchen:arena:door_handle_link"/>
    <child link="iai_kitchen:arena:door_handle_inside"/>
  </joint>
  <joint name="iai_kitchen:arena:door_handle_outside_joint" type="fixed">
    <origin xyz="-0.075 0.0 -0.05" rpy="0.0 0.0 -1.5707963267948966"/>
    <parent link="iai_kitchen:arena:door_handle_link"/>
    <child link="iai_kitchen:arena:door_handle_outside"/>
  </joint>
  <link name="office:arena:door_center">
    <inertial>
      <origin xyz="0.0 0.0 0.0" rpy="0.0 0.0 0.0"/>
      <mass value="1.0"/>
      <inertia ixx="0.1" ixy="0.0" ixz="0.0" iyy="0.1" iyz="0.0" izz="0.1"/>
    </inertial>
    <visual>
      <origin xyz="0.41 0.0 0.0" rpy="0.0 0.0 0.0"/>
      <geometry>
        <box size="0.82 0.04 2.0"/>
      </geometry>
      <material name="door_green"/>
    </visual>
    <collision>
      <origin xyz="0.41 0.0 0.0" rpy="0.0 0.0 0.0"/>
      <geometry>
        <box size="0.82 0.04 2.0"/>
      </geometry>
    </collision>
  </link>
  <link name="office:arena:door_hinge">
    <inertial>
      <origin xyz="0.0 0.0 0.0" rpy="0.0 0.0 0.0"/>
      <mass value="1.0"/>
      <inertia ixx="0.1" ixy="0.0" ixz="0.0" iyy="0.1" iyz="0.0" izz="0.1"/>
    </inertial>
    <visual>
      <origin xyz="0.0 0.0 0.0" rpy="0.0 0.0 0.0"/>
      <geometry>
        <box size="0.05 0.05 2.0"/>
      </geometry>
      <material name="hinge_red"/>
    </visual>
    <collision>
      <origin xyz="0.0 0.0 0.0" rpy="0.0 0.0 0.0"/>
      <geometry>
        <box size="0.05 0.05 2.0"/>
      </geometry>
    </collision>
  </link>
  <link name="office:arena:door_handle_link">
    <inertial>
      <origin xyz="0.0 0.0 0.0" rpy="0.0 0.0 0.0"/>
      <mass value="1.0"/>
      <inertia ixx="0.1" ixy="0.0" ixz="0.0" iyy="0.1" iyz="0.0" izz="0.1"/>
    </inertial>
    <visual>
      <origin xyz="0.0 0.0 0.0" rpy="0.0 0.0 0.0"/>
      <geometry>
        <cylinder radius="0.013" length="0.1"/>
      </geometry>
    </visual>
    <collision>
      <origin xyz="0.0 0.0 0.0" rpy="0.0 0.0 0.0"/>
      <geometry>
        <cylinder radius="0.013" length="0.1"/>
      </geometry>
    </collision>
  </link>
  <gazebo reference="office:arena:door_handle_link">
    <turnGravityOff>true</turnGravityOff>
  </gazebo>
  <link name="office:arena:door_handle_outside">
    <inertial>
      <origin xyz="0.0 0.0 0.0" rpy="0.0 0.0 0.0"/>
      <mass value="1.0"/>
      <inertia ixx="0.1" ixy="0.0" ixz="0.0" iyy="0.1" iyz="0.0" izz="0.1"/>
    </inertial>
    <visual>
      <origin xyz="0.0 0.0 0.0" rpy="0.0 0.0 0.0"/>
      <geometry>
        <box size="0.015 0.15 0.01"/>
      </geometry>
      <material name="handle_blue"/>
    </visual>
    <collision>
      <origin xyz="0.0 0.0 0.0" rpy="0.0 0.0 0.0"/>
      <geometry>
        <box size="0.015 0.15 0.01"/>
      </geometry>
    </collision>
  </link>
  <gazebo reference="office:arena:door_handle_outside">
    <turnGravityOff>true</turnGravityOff>
  </gazebo>
  <link name="office:arena:door_handle_inside">
    <inertial>
      <origin xyz="0.0 0.0 0.0" rpy="0.0 0.0 0.0"/>
      <mass value="1.0"/>
      <inertia ixx="0.1" ixy="0.0" ixz="0.0" iyy="0.1" iyz="0.0" izz="0.1"/>
    </inertial>
    <visual>
      <origin xyz="0.0 0.0 0.0" rpy="0.0 0.0 0.0"/>
      <geometry>
        <box size="0.012 0.12 0.01"/>
      </geometry>
      <material name="handle_blue"/>
    </visual>
    <collision>
      <origin xyz="0.0 0.0 0.0" rpy="0.0 0.0 0.0"/>
      <geometry>
        <box size="0.015 0.15 0.01"/>
      </geometry>
    </collision>
  </link>
  <gazebo reference="office:arena:door_handle_inside">
    <turnGravityOff>true</turnGravityOff>
  </gazebo>
  <joint name="office:arena:door_origin_revolute_joint" type="revolute">
    <origin xyz="0.0 0.0 0.0" rpy="0.0 0.0 0.0"/>
    <axis xyz="0.0 0.0 1.0"/>
    <parent link="office:arena:door_hinge"/>
    <child link="office:arena:door_center"/>
    <limit effort="100.0" lower="-1.4" upper="0.0" velocity="10.0"/>
  </joint>
  <joint name="office:arena:door_hinge_joint" type="fixed">
    <origin xyz="4.24 6.68 1.04" rpy="0.0 0.0 0.0"/>
    <axis xyz="0.0 0.0 0.0"/>
    <parent link="urdf_offset"/>
    <child link="office:arena:door_hinge"/>
    <limit effort="1.0" lower="0.0" upper="1.5708" velocity="1.0"/>
  </joint>
  <joint name="office:arena:door_handle_joint" type="revolute">
    <origin xyz="0.77 0.0 0.02" rpy="1.5707963267948966 0.0 0.0"/>
    <axis xyz="0.0 0.0 1.0"/>
    <parent link="office:arena:door_center"/>
    <child link="office:arena:door_handle_link"/>
    <limit effort="1.0" lower="0.0" upper="0.6283185307179586" velocity="1.0"/>
  </joint>
  <joint name="office:arena:door_handle_inside_joint" type="fixed">
    <origin xyz="-0.069 0.0 0.06" rpy="0.0 0.0 1.5707963267948966"/>
    <parent link="office:arena:door_handle_link"/>
    <child link="office:arena:door_handle_inside"/>
  </joint>
  <joint name="office:arena:door_handle_outside_joint" type="fixed">
    <origin xyz="-0.075 0.0 -0.05" rpy="0.0 0.0 -1.5707963267948966"/>
    <parent link="office:arena:door_handle_link"/>
    <child link="office:arena:door_handle_outside"/>
  </joint>
  <link name="dishwasher_main">
    <inertial>
      <origin xyz="0.0 0.0 0.0" rpy="0.0 0.0 0.0"/>
      <mass value="1.0"/>
      <inertia ixx="1.0" ixy="0.0" ixz="0.0" iyy="1.0" iyz="0.0" izz="1.0"/>
    </inertial>
  </link>
  <joint name="dishwasher_main" type="fixed">
    <origin xyz="10.5 4.77 0.0" rpy="0.0 0.0 3.19"/>
    <parent link="urdf_offset"/>
    <child link="dishwasher_main"/>
  </joint>
  <link name="sink_area_dish_washer_main">
    <inertial>
      <origin xyz="0.0 0.0 0.0" rpy="0.0 0.0 0.0"/>
      <mass value="1.0"/>
      <inertia ixx="1.0" ixy="0.0" ixz="0.0" iyy="1.0" iyz="0.0" izz="1.0"/>
    </inertial>
    <visual>
      <origin xyz="0.0 0.0 0.0" rpy="0.0 0.0 0.0"/>
      <geometry>
        <mesh filename="package://iai_kitchen/meshes/misc/DishWasher.obj"/>
      </geometry>
    </visual>
    <collision>
      <origin xyz="0.0 0.0 0.0" rpy="0.0 0.0 0.0"/>
      <geometry>
        <mesh filename="package://iai_kitchen/meshes/misc/DishWasher.obj"/>
      </geometry>
    </collision>
  </link>
  <link name="sink_area_dish_washer_door">
    <inertial>
      <origin xyz="0.0 0.0 0.0" rpy="0.0 0.0 0.0"/>
      <mass value="1.0"/>
      <inertia ixx="1.0" ixy="0.0" ixz="0.0" iyy="1.0" iyz="0.0" izz="1.0"/>
    </inertial>
    <visual>
      <origin xyz="0.0 0.0 0.0" rpy="1.57079632679 0.0 0.0"/>
      <geometry>
        <mesh filename="package://iai_kitchen/meshes/misc/DishWasherDoor.obj"/>
      </geometry>
    </visual>
    <collision>
      <origin xyz="0.0 0.0 0.0" rpy="1.57079632679 0.0 0.0"/>
      <geometry>
        <mesh filename="package://iai_kitchen/meshes/misc/DishWasherDoor.obj"/>
      </geometry>
    </collision>
  </link>
  <gazebo reference="sink_area_dish_washer_door">
    <turnGravityOff>true</turnGravityOff>
  </gazebo>
  <link name="sink_area_dish_washer_door_handle">
    <inertial>
      <origin xyz="0.1 0.0 0.0" rpy="0.0 0.0 0.0"/>
      <mass value="1.0"/>
      <inertia ixx="1.0" ixy="0.0" ixz="0.0" iyy="1.0" iyz="0.0" izz="1.0"/>
    </inertial>
    <visual>
      <origin xyz="0.01 0.0 0.0" rpy="0.0 0.0 0.0"/>
      <geometry>
        <mesh filename="package://iai_kitchen/meshes/handles/Handle60.obj"/>
      </geometry>
    </visual>
    <collision>
      <origin xyz="0.01 0.0 0.0" rpy="0.0 0.0 0.0"/>
      <geometry>
        <mesh filename="package://iai_kitchen/meshes/handles/Handle60.obj"/>
      </geometry>
    </collision>
  </link>
  <gazebo reference="sink_area_dish_washer_door_handle">
    <turnGravityOff>true</turnGravityOff>
  </gazebo>
  <link name="dishwasher_tab"/>
  <link name="dishwasher_table:d_table:d_table_origin"/>
  <link name="dishwasher_table:d_table:table_front_edge_center"/>
  <link name="dishwasher_table:d_table:table_center">
    <visual>
      <origin xyz="0.0 0.0 0.0" rpy="0.0 0.0 0.0"/>
      <geometry>
        <box size="0.593 0.6 0.02"/>
      </geometry>
      <material name="dishwasher_robocup_table_color"/>
    </visual>
    <collision>
      <origin xyz="0.0 0.0 0.0" rpy="0.0 0.0 0.0"/>
      <geometry>
        <box size="0.593 0.6 0.02"/>
      </geometry>
    </collision>
  </link>
  <joint name="dishwasher_tab_joint" type="fixed">
    <origin xyz="-0.1 0.1 0.15" rpy="0.0 0.0 0.0"/>
    <parent link="sink_area_dish_washer_door_handle"/>
    <child link="dishwasher_tab"/>
  </joint>
  <joint name="sink_area_dish_washer_main_joint" type="fixed">
    <origin xyz="0.0 0.0 0.44" rpy="0.0 0.0 0.0"/>
    <axis xyz="1.0 0.0 0.0"/>
    <parent link="dishwasher_main"/>
    <child link="sink_area_dish_washer_main"/>
  </joint>
  <joint name="sink_area_dish_washer_door_joint" type="revolute">
    <origin xyz="0.27 0.0 -0.325" rpy="-1.57079632679 0.03 0.0"/>
    <axis xyz="0.0 0.0 1.0"/>
    <parent link="sink_area_dish_washer_main"/>
    <child link="sink_area_dish_washer_door"/>
    <limit effort="300.0" lower="0.0" upper="1.57079632679" velocity="10.0"/>
  </joint>
  <joint name="sink_area_dish_washer_door_handle_joint" type="fixed">
    <origin xyz="0.0625 -0.6625 0.0" rpy="-1.57079632679 0.0 0.0"/>
    <parent link="sink_area_dish_washer_door"/>
    <child link="sink_area_dish_washer_door_handle"/>
  </joint>
  <joint name="dish_washer_table_main_joint" type="fixed">
    <origin xyz="0.0 0.0 0.3971" rpy="0.0 0.0 3.141592653589793"/>
    <parent link="sink_area_dish_washer_main"/>
    <child link="dishwasher_table:d_table:d_table_origin"/>
  </joint>
  <joint name="dish_washer_table_center_joint" type="fixed">
    <origin xyz="-0.3 0.0 0.0" rpy="0.0 0.0 0.0"/>
    <parent link="dishwasher_table:d_table:d_table_origin"/>
    <child link="dishwasher_table:d_table:table_front_edge_center"/>
  </joint>
  <joint name="dish_washer_table_edge_joint" type="fixed">
    <origin xyz="0.0 0.0 0.0" rpy="0.0 0.0 0.0"/>
    <parent link="dishwasher_table:d_table:d_table_origin"/>
    <child link="dishwasher_table:d_table:table_center"/>
  </joint>
  <link name="chair:desk_chair:chair_center">
    <visual>
      <origin xyz="0.0 0.0 0.0" rpy="0.0 0.0 0.0"/>
      <geometry>
        <box size="0.42 0.435 0.47"/>
      </geometry>
      <material name="chair_color"/>
    </visual>
    <collision>
      <origin xyz="0.0 0.0 0.0" rpy="0.0 0.0 0.0"/>
      <geometry>
        <box size="0.42 0.435 0.47"/>
      </geometry>
    </collision>
  </link>
  <link name="chair:desk_chair:chair_backrest">
    <visual>
      <origin xyz="0.0 0.0 0.0" rpy="0.0 0.0 0.0"/>
      <geometry>
        <box size="0.42 0.05 0.47"/>
      </geometry>
      <material name="chair_color"/>
    </visual>
    <collision>
      <origin xyz="0.0 0.0 0.0" rpy="0.0 0.0 0.0"/>
      <geometry>
        <box size="0.42 0.05 0.47"/>
      </geometry>
    </collision>
  </link>
  <link name="chair:desk_chair:chair_origin"/>
  <link name="chair:desk_chair:chair_front_edge_center"/>
  <joint name="chair:desk_chair:chair_origin_joint" type="fixed">
    <origin xyz="3.38 3.07 0.0" rpy="0.0 0.0 3.15"/>
    <parent link="urdf_offset"/>
    <child link="chair:desk_chair:chair_origin"/>
  </joint>
  <joint name="chair:desk_chair:center_joint" type="fixed">
    <origin xyz="0.0 0.0 0.235" rpy="0.0 0.0 0.0"/>
    <parent link="chair:desk_chair:chair_origin"/>
    <child link="chair:desk_chair:chair_center"/>
  </joint>
  <joint name="chair:desk_chair:chair_front_edge_center_joint" type="fixed">
    <origin xyz="0.0 0.2175 0.47" rpy="0.0 0.0 0.0"/>
    <parent link="chair:desk_chair:chair_origin"/>
    <child link="chair:desk_chair:chair_front_edge_center"/>
  </joint>
  <joint name="chair:desk_chair:chair_backrest_joint" type="fixed">
    <origin xyz="0.0 -0.1875 0.235" rpy="0.0 0.0 0.0"/>
    <parent link="chair:desk_chair:chair_center"/>
    <child link="chair:desk_chair:chair_backrest"/>
  </joint>
  <link name="chair:lounge_chair:chair_center">
    <visual>
      <origin xyz="0.0 0.0 0.0" rpy="0.0 0.0 0.0"/>
      <geometry>
        <box size="0.71 0.825 0.415"/>
      </geometry>
      <material name="chair_color"/>
    </visual>
    <collision>
      <origin xyz="0.0 0.0 0.0" rpy="0.0 0.0 0.0"/>
      <geometry>
        <box size="0.71 0.825 0.415"/>
      </geometry>
    </collision>
  </link>
  <link name="chair:lounge_chair:chair_backrest">
    <visual>
      <origin xyz="0.0 0.0 0.0" rpy="0.0 0.0 0.0"/>
      <geometry>
        <box size="0.71 0.05 0.415"/>
      </geometry>
      <material name="chair_color"/>
    </visual>
    <collision>
      <origin xyz="0.0 0.0 0.0" rpy="0.0 0.0 0.0"/>
      <geometry>
        <box size="0.71 0.05 0.415"/>
      </geometry>
    </collision>
  </link>
  <link name="chair:lounge_chair:chair_origin"/>
  <link name="chair:lounge_chair:chair_front_edge_center"/>
  <joint name="chair:lounge_chair:chair_origin_joint" type="fixed">
    <origin xyz="9.3 -1.54 0.0" rpy="0.0 0.0 -0.1"/>
    <parent link="urdf_offset"/>
    <child link="chair:lounge_chair:chair_origin"/>
  </joint>
  <joint name="chair:lounge_chair:center_joint" type="fixed">
    <origin xyz="0.0 0.0 0.2075" rpy="0.0 0.0 0.0"/>
    <parent link="chair:lounge_chair:chair_origin"/>
    <child link="chair:lounge_chair:chair_center"/>
  </joint>
  <joint name="chair:lounge_chair:chair_front_edge_center_joint" type="fixed">
    <origin xyz="0.0 0.4125 0.415" rpy="0.0 0.0 0.0"/>
    <parent link="chair:lounge_chair:chair_origin"/>
    <child link="chair:lounge_chair:chair_front_edge_center"/>
  </joint>
  <joint name="chair:lounge_chair:chair_backrest_joint" type="fixed">
    <origin xyz="0.0 -0.38249999999999995 0.2075" rpy="0.0 0.0 0.0"/>
    <parent link="chair:lounge_chair:chair_center"/>
    <child link="chair:lounge_chair:chair_backrest"/>
  </joint>
  <link name="shelf_hohc:kitchen_cabinet:shelf_origin"/>
  <link name="shelf_hohc:kitchen_cabinet:shelf_center"/>
  <link name="shelf_hohc:kitchen_cabinet:shelf_base_center"/>
  <joint name="shelf_hohc:kitchen_cabinet:shelf_origin_joint" type="fixed">
    <origin xyz="5.42 6.2 0.0" rpy="0.0 0.0 3.23"/>
    <parent link="urdf_offset"/>
    <child link="shelf_hohc:kitchen_cabinet:shelf_origin"/>
  </joint>
  <joint name="shelf_hohc:kitchen_cabinet:shelf_center_joint" type="fixed">
    <origin xyz="0.15 0.4 1.01" rpy="0.0 0.0 0.0"/>
    <parent link="shelf_hohc:kitchen_cabinet:shelf_origin"/>
    <child link="shelf_hohc:kitchen_cabinet:shelf_center"/>
  </joint>
  <joint name="shelf_hohc:kitchen_cabinet:shelf_base_center_joint" type="fixed">
    <origin xyz="0.15 0.4 0.0" rpy="0.0 0.0 0.0"/>
    <parent link="shelf_hohc:kitchen_cabinet:shelf_origin"/>
    <child link="shelf_hohc:kitchen_cabinet:shelf_base_center"/>
  </joint>
  <link name="shelf_hohc:kitchen_cabinet:shelf_back">
    <inertial>
      <origin xyz="0.0 0.0 0.0" rpy="0.0 0.0 0.0"/>
      <mass value="1.0"/>
      <inertia ixx="0.1" ixy="0.0" ixz="0.0" iyy="0.1" iyz="0.0" izz="0.1"/>
    </inertial>
    <visual>
      <origin xyz="0.0 0.0 0.0" rpy="0.0 0.0 0.0"/>
      <geometry>
        <box size="0.02 0.8 2.02"/>
      </geometry>
      <material name="shelf_blue"/>
    </visual>
    <collision>
      <origin xyz="0.0 0.0 0.0" rpy="0.0 0.0 0.0"/>
      <geometry>
        <box size="0.02 0.8 2.02"/>
      </geometry>
    </collision>
  </link>
  <joint name="shelf_hohc:kitchen_cabinet:shelf_back:joint" type="fixed">
    <origin xyz="0.3 0.4 1.01" rpy="0.0 0.0 0.0"/>
    <parent link="shelf_hohc:kitchen_cabinet:shelf_origin"/>
    <child link="shelf_hohc:kitchen_cabinet:shelf_back"/>
  </joint>
  <link name="shelf_hohc:kitchen_cabinet:shelf_right_side">
    <inertial>
      <origin xyz="0.0 0.0 0.0" rpy="0.0 0.0 0.0"/>
      <mass value="1.0"/>
      <inertia ixx="0.1" ixy="0.0" ixz="0.0" iyy="0.1" iyz="0.0" izz="0.1"/>
    </inertial>
    <visual>
      <origin xyz="0.0 0.0 0.0" rpy="0.0 0.0 0.0"/>
      <geometry>
        <box size="0.3 0.02 2.02"/>
      </geometry>
      <material name="shelf_blue"/>
    </visual>
    <collision>
      <origin xyz="0.0 0.0 0.0" rpy="0.0 0.0 0.0"/>
      <geometry>
        <box size="0.3 0.02 2.02"/>
      </geometry>
    </collision>
  </link>
  <joint name="shelf_hohc:kitchen_cabinet:shelf_right_side:joint" type="fixed">
    <origin xyz="0.15 0.01 1.01" rpy="0.0 0.0 0.0"/>
    <parent link="shelf_hohc:kitchen_cabinet:shelf_origin"/>
    <child link="shelf_hohc:kitchen_cabinet:shelf_right_side"/>
  </joint>
  <link name="shelf_hohc:kitchen_cabinet:shelf_left_side">
    <inertial>
      <origin xyz="0.0 0.0 0.0" rpy="0.0 0.0 0.0"/>
      <mass value="1.0"/>
      <inertia ixx="0.1" ixy="0.0" ixz="0.0" iyy="0.1" iyz="0.0" izz="0.1"/>
    </inertial>
    <visual>
      <origin xyz="0.0 0.0 0.0" rpy="0.0 0.0 0.0"/>
      <geometry>
        <box size="0.3 0.02 2.02"/>
      </geometry>
      <material name="shelf_blue"/>
    </visual>
    <collision>
      <origin xyz="0.0 0.0 0.0" rpy="0.0 0.0 0.0"/>
      <geometry>
        <box size="0.3 0.02 2.02"/>
      </geometry>
    </collision>
  </link>
  <joint name="shelf_hohc:kitchen_cabinet:shelf_left_side:joint" type="fixed">
    <origin xyz="0.15 0.79 1.01" rpy="0.0 0.0 0.0"/>
    <parent link="shelf_hohc:kitchen_cabinet:shelf_origin"/>
    <child link="shelf_hohc:kitchen_cabinet:shelf_left_side"/>
  </joint>
  <link name="shelf_hohc:kitchen_cabinet:shelf_floor_0">
    <inertial>
      <origin xyz="0.0 0.0 0.0" rpy="0.0 0.0 0.0"/>
      <mass value="1.0"/>
      <inertia ixx="0.1" ixy="0.0" ixz="0.0" iyy="0.1" iyz="0.0" izz="0.1"/>
    </inertial>
    <visual>
      <origin xyz="0.0 0.0 -0.02" rpy="0.0 0.0 0.0"/>
      <geometry>
        <box size="0.3 0.8 0.04"/>
      </geometry>
      <material name="shelf_blue"/>
    </visual>
    <collision>
      <origin xyz="0.0 0.0 -0.02" rpy="0.0 0.0 0.0"/>
      <geometry>
        <box size="0.3 0.8 0.04"/>
      </geometry>
    </collision>
  </link>
  <joint name="shelf_hohc:kitchen_cabinet:shelf_floor_0:joint" type="fixed">
    <origin xyz="0.0 0.0 0.09" rpy="0.0 0.0 0.0"/>
    <parent link="shelf_hohc:kitchen_cabinet:shelf_base_center"/>
    <child link="shelf_hohc:kitchen_cabinet:shelf_floor_0"/>
  </joint>
  <link name="shelf_hohc:kitchen_cabinet:shelf_floor_1">
    <inertial>
      <origin xyz="0.0 0.0 0.0" rpy="0.0 0.0 0.0"/>
      <mass value="1.0"/>
      <inertia ixx="0.1" ixy="0.0" ixz="0.0" iyy="0.1" iyz="0.0" izz="0.1"/>
    </inertial>
    <visual>
      <origin xyz="0.0 0.0 -0.02" rpy="0.0 0.0 0.0"/>
      <geometry>
        <box size="0.3 0.8 0.04"/>
      </geometry>
      <material name="shelf_blue"/>
    </visual>
    <collision>
      <origin xyz="0.0 0.0 -0.02" rpy="0.0 0.0 0.0"/>
      <geometry>
        <box size="0.3 0.8 0.04"/>
      </geometry>
    </collision>
  </link>
  <joint name="shelf_hohc:kitchen_cabinet:shelf_floor_1:joint" type="fixed">
    <origin xyz="0.0 0.0 0.4" rpy="0.0 0.0 0.0"/>
    <parent link="shelf_hohc:kitchen_cabinet:shelf_base_center"/>
    <child link="shelf_hohc:kitchen_cabinet:shelf_floor_1"/>
  </joint>
  <link name="shelf_hohc:kitchen_cabinet:shelf_floor_2">
    <inertial>
      <origin xyz="0.0 0.0 0.0" rpy="0.0 0.0 0.0"/>
      <mass value="1.0"/>
      <inertia ixx="0.1" ixy="0.0" ixz="0.0" iyy="0.1" iyz="0.0" izz="0.1"/>
    </inertial>
    <visual>
      <origin xyz="0.0 0.0 -0.02" rpy="0.0 0.0 0.0"/>
      <geometry>
        <box size="0.3 0.8 0.04"/>
      </geometry>
      <material name="shelf_blue"/>
    </visual>
    <collision>
      <origin xyz="0.0 0.0 -0.02" rpy="0.0 0.0 0.0"/>
      <geometry>
        <box size="0.3 0.8 0.04"/>
      </geometry>
    </collision>
  </link>
  <joint name="shelf_hohc:kitchen_cabinet:shelf_floor_2:joint" type="fixed">
    <origin xyz="0.0 0.0 0.72" rpy="0.0 0.0 0.0"/>
    <parent link="shelf_hohc:kitchen_cabinet:shelf_base_center"/>
    <child link="shelf_hohc:kitchen_cabinet:shelf_floor_2"/>
  </joint>
  <link name="shelf_hohc:kitchen_cabinet:shelf_floor_3">
    <inertial>
      <origin xyz="0.0 0.0 0.0" rpy="0.0 0.0 0.0"/>
      <mass value="1.0"/>
      <inertia ixx="0.1" ixy="0.0" ixz="0.0" iyy="0.1" iyz="0.0" izz="0.1"/>
    </inertial>
    <visual>
      <origin xyz="0.0 0.0 -0.02" rpy="0.0 0.0 0.0"/>
      <geometry>
        <box size="0.3 0.8 0.04"/>
      </geometry>
      <material name="shelf_blue"/>
    </visual>
    <collision>
      <origin xyz="0.0 0.0 -0.02" rpy="0.0 0.0 0.0"/>
      <geometry>
        <box size="0.3 0.8 0.04"/>
      </geometry>
    </collision>
  </link>
  <joint name="shelf_hohc:kitchen_cabinet:shelf_floor_3:joint" type="fixed">
    <origin xyz="0.0 0.0 1.045" rpy="0.0 0.0 0.0"/>
    <parent link="shelf_hohc:kitchen_cabinet:shelf_base_center"/>
    <child link="shelf_hohc:kitchen_cabinet:shelf_floor_3"/>
  </joint>
  <link name="shelf_hohc:kitchen_cabinet:shelf_floor_4">
    <inertial>
      <origin xyz="0.0 0.0 0.0" rpy="0.0 0.0 0.0"/>
      <mass value="1.0"/>
      <inertia ixx="0.1" ixy="0.0" ixz="0.0" iyy="0.1" iyz="0.0" izz="0.1"/>
    </inertial>
    <visual>
      <origin xyz="0.0 0.0 -0.02" rpy="0.0 0.0 0.0"/>
      <geometry>
        <box size="0.3 0.8 0.04"/>
      </geometry>
      <material name="shelf_blue"/>
    </visual>
    <collision>
      <origin xyz="0.0 0.0 -0.02" rpy="0.0 0.0 0.0"/>
      <geometry>
        <box size="0.3 0.8 0.04"/>
      </geometry>
    </collision>
  </link>
  <joint name="shelf_hohc:kitchen_cabinet:shelf_floor_4:joint" type="fixed">
    <origin xyz="0.0 0.0 1.4" rpy="0.0 0.0 0.0"/>
    <parent link="shelf_hohc:kitchen_cabinet:shelf_base_center"/>
    <child link="shelf_hohc:kitchen_cabinet:shelf_floor_4"/>
  </joint>
  <link name="shelf_hohc:kitchen_cabinet:shelf_floor_5">
    <inertial>
      <origin xyz="0.0 0.0 0.0" rpy="0.0 0.0 0.0"/>
      <mass value="1.0"/>
      <inertia ixx="0.1" ixy="0.0" ixz="0.0" iyy="0.1" iyz="0.0" izz="0.1"/>
    </inertial>
    <visual>
      <origin xyz="0.0 0.0 -0.02" rpy="0.0 0.0 0.0"/>
      <geometry>
        <box size="0.3 0.8 0.04"/>
      </geometry>
      <material name="shelf_blue"/>
    </visual>
    <collision>
      <origin xyz="0.0 0.0 -0.02" rpy="0.0 0.0 0.0"/>
      <geometry>
        <box size="0.3 0.8 0.04"/>
      </geometry>
    </collision>
  </link>
  <joint name="shelf_hohc:kitchen_cabinet:shelf_floor_5:joint" type="fixed">
    <origin xyz="0.0 0.0 1.685" rpy="0.0 0.0 0.0"/>
    <parent link="shelf_hohc:kitchen_cabinet:shelf_base_center"/>
    <child link="shelf_hohc:kitchen_cabinet:shelf_floor_5"/>
  </joint>
  <link name="shelf_hohc:kitchen_cabinet:shelf_floor_6">
    <inertial>
      <origin xyz="0.0 0.0 0.0" rpy="0.0 0.0 0.0"/>
      <mass value="1.0"/>
      <inertia ixx="0.1" ixy="0.0" ixz="0.0" iyy="0.1" iyz="0.0" izz="0.1"/>
    </inertial>
    <visual>
      <origin xyz="0.0 0.0 -0.02" rpy="0.0 0.0 0.0"/>
      <geometry>
        <box size="0.3 0.8 0.04"/>
      </geometry>
      <material name="shelf_blue"/>
    </visual>
    <collision>
      <origin xyz="0.0 0.0 -0.02" rpy="0.0 0.0 0.0"/>
      <geometry>
        <box size="0.3 0.8 0.04"/>
      </geometry>
    </collision>
  </link>
  <joint name="shelf_hohc:kitchen_cabinet:shelf_floor_6:joint" type="fixed">
    <origin xyz="0.0 0.0 2.015" rpy="0.0 0.0 0.0"/>
    <parent link="shelf_hohc:kitchen_cabinet:shelf_base_center"/>
    <child link="shelf_hohc:kitchen_cabinet:shelf_floor_6"/>
  </joint>
  <link name="shelf_hohc:kitchen_cabinet:shelf_door_right">
    <inertial>
      <origin xyz="0.0 0.0 0.0" rpy="0.0 0.0 0.0"/>
      <mass value="1.0"/>
      <inertia ixx="0.1" ixy="0.0" ixz="0.0" iyy="0.1" iyz="0.0" izz="0.1"/>
    </inertial>
    <visual>
      <origin xyz="0.0 0.18 0.0" rpy="0.0 0.0 0.0"/>
      <geometry>
        <box size="0.02 0.38 0.97"/>
      </geometry>
      <material name="shelf_door_green"/>
    </visual>
    <collision>
      <origin xyz="0.0 0.18 0.0" rpy="0.0 0.0 0.0"/>
      <geometry>
        <box size="0.02 0.38 0.97"/>
      </geometry>
    </collision>
  </link>
  <link name="shelf_hohc:kitchen_cabinet:shelf_door_right:handle">
    <inertial>
      <origin xyz="0.0 0.0 0.0" rpy="0.0 0.0 0.0"/>
      <mass value="1.0"/>
      <inertia ixx="0.1" ixy="0.0" ixz="0.0" iyy="0.1" iyz="0.0" izz="0.1"/>
    </inertial>
    <visual>
      <origin xyz="0.0 0.0 0.0" rpy="0.0 0.0 0.0"/>
      <geometry>
        <box size="0.035 0.005 0.135"/>
      </geometry>
      <material name="shelf_hohc_handle_red"/>
    </visual>
    <collision>
      <origin xyz="0.0 0.0 0.0" rpy="0.0 0.0 0.0"/>
      <geometry>
        <box size="0.035 0.005 0.135"/>
      </geometry>
    </collision>
  </link>
  <joint name="shelf_hohc:kitchen_cabinet:shelf_door_right:handle_joint" type="fixed">
    <origin xyz="-0.037500000000000006 0.3525 0.15249999999999997" rpy="0.0 0.0 0.0"/>
    <axis xyz="0.0 0.0 1.0"/>
    <parent link="shelf_hohc:kitchen_cabinet:shelf_door_right"/>
    <child link="shelf_hohc:kitchen_cabinet:shelf_door_right:handle"/>
  </joint>
  <joint name="shelf_hohc:kitchen_cabinet:shelf_door_right:joint" type="revolute">
    <origin xyz="-0.13999999999999999 0.02 -0.48" rpy="0.0 0.0 0.0"/>
    <axis xyz="0.0 0.0 1.0"/>
    <parent link="shelf_hohc:kitchen_cabinet:shelf_right_side"/>
    <child link="shelf_hohc:kitchen_cabinet:shelf_door_right"/>
    <limit effort="30.0" lower="0.0" upper="1.7" velocity="1.0"/>
  </joint>
  <link name="shelf_hohc:kitchen_cabinet:shelf_door_left">
    <inertial>
      <origin xyz="0.0 0.0 0.0" rpy="0.0 0.0 0.0"/>
      <mass value="1.0"/>
      <inertia ixx="0.1" ixy="0.0" ixz="0.0" iyy="0.1" iyz="0.0" izz="0.1"/>
    </inertial>
    <visual>
      <origin xyz="0.0 -0.18 0.0" rpy="0.0 0.0 0.0"/>
      <geometry>
        <box size="0.02 0.38 0.97"/>
      </geometry>
      <material name="shelf_door_green"/>
    </visual>
    <collision>
      <origin xyz="0.0 -0.18 0.0" rpy="0.0 0.0 0.0"/>
      <geometry>
        <box size="0.02 0.38 0.97"/>
      </geometry>
    </collision>
  </link>
  <link name="shelf_hohc:kitchen_cabinet:shelf_door_left:handle">
    <inertial>
      <origin xyz="0.0 0.0 0.0" rpy="0.0 0.0 0.0"/>
      <mass value="1.0"/>
      <inertia ixx="0.1" ixy="0.0" ixz="0.0" iyy="0.1" iyz="0.0" izz="0.1"/>
    </inertial>
    <visual>
      <origin xyz="0.0 0.0 0.0" rpy="0.0 0.0 0.0"/>
      <geometry>
        <box size="0.035 0.005 0.135"/>
      </geometry>
      <material name="shelf_hohc_handle_red"/>
    </visual>
    <collision>
      <origin xyz="0.0 0.0 0.0" rpy="0.0 0.0 0.0"/>
      <geometry>
        <box size="0.035 0.005 0.135"/>
      </geometry>
    </collision>
  </link>
  <joint name="shelf_hohc:kitchen_cabinet:shelf_door_left:handle_joint" type="fixed">
    <origin xyz="-0.037500000000000006 -0.3525 0.15249999999999997" rpy="0.0 0.0 0.0"/>
    <axis xyz="0.0 0.0 1.0"/>
    <parent link="shelf_hohc:kitchen_cabinet:shelf_door_left"/>
    <child link="shelf_hohc:kitchen_cabinet:shelf_door_left:handle"/>
  </joint>
  <joint name="shelf_hohc:kitchen_cabinet:shelf_door_left:joint" type="revolute">
    <origin xyz="-0.13999999999999999 -0.02 -0.48" rpy="0.0 0.0 0.0"/>
    <axis xyz="0.0 0.0 1.0"/>
    <parent link="shelf_hohc:kitchen_cabinet:shelf_left_side"/>
    <child link="shelf_hohc:kitchen_cabinet:shelf_door_left"/>
    <limit effort="30.0" lower="-1.7" upper="0.0" velocity="1.0"/>
  </joint>
  <link name="trashcan:trashcan:trashcan_center">
    <inertial>
      <origin xyz="0.0 0.0 0.0" rpy="0.0 0.0 0.0"/>
      <mass value="1.0"/>
      <inertia ixx="0.1" ixy="0.0" ixz="0.0" iyy="0.1" iyz="0.0" izz="0.1"/>
    </inertial>
    <visual>
      <origin xyz="0.0 0.0 -0.245" rpy="0.0 0.0 0.0"/>
      <geometry>
        <cylinder radius="0.19" length="0.49"/>
      </geometry>
      <material name="trashcan_color"/>
    </visual>
    <collision>
      <origin xyz="0.0 0.0 -0.245" rpy="0.0 0.0 0.0"/>
      <geometry>
        <cylinder radius="0.19" length="0.49"/>
      </geometry>
    </collision>
  </link>
  <link name="trashcan:trashcan:trashcan_origin"/>
  <link name="trashcan:trashcan:trashcan_front_edge_center"/>
  <joint name="trashcan:trashcan:trashcan_origin_joint" type="fixed">
    <origin xyz="5.86 2.03 0.0" rpy="0.0 0.0 3.2"/>
    <parent link="urdf_offset"/>
    <child link="trashcan:trashcan:trashcan_origin"/>
  </joint>
  <joint name="trashcan:trashcan:center_joint" type="fixed">
    <origin xyz="0.19 0.0 0.49" rpy="0.0 0.0 0.0"/>
    <parent link="trashcan:trashcan:trashcan_origin"/>
    <child link="trashcan:trashcan:trashcan_center"/>
  </joint>
  <joint name="trashcan:trashcan:trashcan_front_edge_center_joint" type="fixed">
    <origin xyz="0.0 0.0 0.49" rpy="0.0 0.0 0.0"/>
    <parent link="trashcan:trashcan:trashcan_origin"/>
    <child link="trashcan:trashcan:trashcan_front_edge_center"/>
  </joint>
  <link name="coathanger:coathanger:coathanger_center">
    <inertial>
      <origin xyz="0.0 0.0 0.0" rpy="0.0 0.0 0.0"/>
      <mass value="1.0"/>
      <inertia ixx="0.1" ixy="0.0" ixz="0.0" iyy="0.1" iyz="0.0" izz="0.1"/>
    </inertial>
    <visual>
      <origin xyz="0.0 0.0 -0.9" rpy="0.0 0.0 0.0"/>
      <geometry>
        <box size="0.5 0.5 1.8"/>
      </geometry>
      <material name="coathanger_color"/>
    </visual>
    <collision>
      <origin xyz="0.0 0.0 -0.9" rpy="0.0 0.0 0.0"/>
      <geometry>
        <box size="0.5 0.5 1.8"/>
      </geometry>
    </collision>
  </link>
  <link name="coathanger:coathanger:coathanger_origin"/>
  <link name="coathanger:coathanger:coathanger_front_edge_center"/>
  <joint name="coathanger:coathanger:coathanger_origin_joint" type="fixed">
    <origin xyz="3.9 1.55 0.0" rpy="0.0 0.0 3.17"/>
    <parent link="urdf_offset"/>
    <child link="coathanger:coathanger:coathanger_origin"/>
  </joint>
  <joint name="coathanger:coathanger:center_joint" type="fixed">
    <origin xyz="0.25 0.25 1.8" rpy="0.0 0.0 0.0"/>
    <parent link="coathanger:coathanger:coathanger_origin"/>
    <child link="coathanger:coathanger:coathanger_center"/>
  </joint>
  <joint name="coathanger:coathanger:coathanger_front_edge_center_joint" type="fixed">
    <origin xyz="0.0 0.25 1.8" rpy="0.0 0.0 0.0"/>
    <parent link="coathanger:coathanger:coathanger_origin"/>
    <child link="coathanger:coathanger:coathanger_front_edge_center"/>
  </joint>
  <link name="lamp:lamp:lamp_center">
    <inertial>
      <origin xyz="0.0 0.0 0.0" rpy="0.0 0.0 0.0"/>
      <mass value="1.0"/>
      <inertia ixx="0.1" ixy="0.0" ixz="0.0" iyy="0.1" iyz="0.0" izz="0.1"/>
    </inertial>
    <visual>
      <origin xyz="0.0 0.0 -0.9" rpy="0.0 0.0 0.0"/>
      <geometry>
        <cylinder radius="0.09" length="1.8"/>
      </geometry>
      <material name="lamp_color"/>
    </visual>
    <collision>
      <origin xyz="0.0 0.0 -0.9" rpy="0.0 0.0 0.0"/>
      <geometry>
        <cylinder radius="0.09" length="1.8"/>
      </geometry>
    </collision>
  </link>
  <link name="lamp:lamp:lamp_origin"/>
  <link name="lamp:lamp:lamp_front_edge_center"/>
  <joint name="lamp:lamp:lamp_origin_joint" type="fixed">
    <origin xyz="10.7 -1.6 0.0" rpy="0.0 0.0 0.0"/>
    <parent link="urdf_offset"/>
    <child link="lamp:lamp:lamp_origin"/>
  </joint>
  <joint name="lamp:lamp:center_joint" type="fixed">
    <origin xyz="0.09 0.0 1.8" rpy="0.0 0.0 0.0"/>
    <parent link="lamp:lamp:lamp_origin"/>
    <child link="lamp:lamp:lamp_center"/>
  </joint>
  <joint name="lamp:lamp:lamp_front_edge_center_joint" type="fixed">
    <origin xyz="0.0 0.0 1.8" rpy="0.0 0.0 0.0"/>
    <parent link="lamp:lamp:lamp_origin"/>
    <child link="lamp:lamp:lamp_front_edge_center"/>
  </joint>
  <link name="urdf_main"/>
  <joint name="map_urdf_joint" type="fixed">
    <origin xyz="0.0 0.0 0.0" rpy="0.0 0.0 0.0"/>
    <parent link="urdf_main"/>
    <child link="urdf_offset"/>
  </joint>
  <link name="urdf_offset"/>
</robot>