<?xml version="1.0" ?>
<robot name="iai-kitchen" version="1.0">
  <material name="table_grey">
    <color rgba="0.255 0.62 0.223 1.0"/>
  </material>
  <material name="round_table_grey">
    <color rgba="0.8 0.8 0.8 1.0"/>
  </material>
  <material name="wall_pink">
    <color rgba="0.95 0.43 0.96 1.0"/>
  </material>
  <material name="shelf_blue">
    <color rgba="0.59 0.88 0.9 1.0"/>
  </material>
  <material name="shelf_door_green">
    <color rgba="0.64 0.87 0.82 1.0"/>
  </material>
  <material name="shelf_openable_handle_red">
    <color rgba="0.74 0.25 0.25 1.0"/>
  </material>
  <material name="shelf_hohc_handle_red">
    <color rgba="0.74 0.25 0.25 1.0"/>
  </material>
  <material name="door_green">
    <color rgba="0.0 0.31 0.22 1.0"/>
  </material>
  <material name="hinge_red">
    <color rgba="0.74 0.25 0.25 1.0"/>
  </material>
  <material name="handle_blue">
    <color rgba="0.3 0.5 0.78 1.0"/>
  </material>
  <material name="bucket_grey">
    <color rgba="0.8 0.8 0.8 1.0"/>
  </material>
  <material name="white">
    <color rgba="1.0 1.0 1.0 1.0"/>
  </material>
  <material name="orange">
    <color rgba="1.0 0.7 0.0 1.0"/>
  </material>
  <material name="handle_white">
    <color rgba="1.0 1.0 1.0 1.0"/>
  </material>
  <material name="bottom_white">
    <color rgba="1.0 1.0 1.0 1.0"/>
  </material>
  <material name="frame_wood">
    <color rgba="0.68 0.63 0.47 1.0"/>
  </material>
  <material name="handle_grey">
    <color rgba="0.7 0.7 0.7 1.0"/>
  </material>
  <material name="dishwasher_table_color">
    <color rgba="0.255 0.62 0.223 1.0"/>
  </material>
  <material name="color_grey">
    <color rgba="0.8 0.8 0.8 1.0"/>
  </material>
  <material name="color_red">
    <color rgba="1.0 0.0 0.0 1.0"/>
  </material>
  <material name="color_blue">
    <color rgba="0.0 0.0 1.0 1.0"/>
  </material>
  <material name="simple_couch_color_grey">
    <color rgba="0.8 0.8 0.8 1.0"/>
  </material>
  <material name="simple_couch_color_red">
    <color rgba="1.0 0.0 0.0 1.0"/>
  </material>
  <material name="simple_couch_color_blue">
    <color rgba="0.0 0.0 1.0 1.0"/>
  </material>
  <material name="chair_color">
    <color rgba="0.0 0.0 0.5 1.0"/>
  </material>
  <link name="popcorn_table:p_table:table_center">
    <visual>
      <origin xyz="0.0 0.0 -0.355" rpy="0.0 0.0 0.0"/>
      <geometry>
        <box size="0.55 1.8 0.71"/>
      </geometry>
      <material name="table_grey"/>
    </visual>
    <collision>
      <origin xyz="0.0 0.0 -0.355" rpy="0.0 0.0 0.0"/>
      <geometry>
        <box size="0.55 1.8 0.71"/>
      </geometry>
    </collision>
  </link>
  <link name="popcorn_table:p_table:table_origin"/>
  <link name="popcorn_table:p_table:table_front_edge_center"/>
  <joint name="popcorn_table:p_table:table_origin_joint" type="fixed">
    <origin xyz="3.03 5.68 0.0" rpy="0.0 0.0 1.57"/>
    <parent link="urdf_offset"/>
    <child link="popcorn_table:p_table:table_origin"/>
  </joint>
  <joint name="popcorn_table:p_table:center_joint" type="fixed">
    <origin xyz="0.275 0.9 0.71" rpy="0.0 0.0 0.0"/>
    <parent link="popcorn_table:p_table:table_origin"/>
    <child link="popcorn_table:p_table:table_center"/>
  </joint>
  <joint name="popcorn_table:p_table:table_front_edge_center_joint" type="fixed">
    <origin xyz="0.0 0.9 0.71" rpy="0.0 0.0 0.0"/>
    <parent link="popcorn_table:p_table:table_origin"/>
    <child link="popcorn_table:p_table:table_front_edge_center"/>
  </joint>
  <link name="shelf:shelf:shelf_origin"/>
  <link name="shelf:shelf:shelf_center"/>
  <link name="shelf:shelf:shelf_base_center"/>
  <joint name="shelf:shelf:shelf_origin_joint" type="fixed">
    <origin xyz="5.11 4.42 0.0" rpy="0.0 0.0 0.0"/>
    <parent link="urdf_offset"/>
    <child link="shelf:shelf:shelf_origin"/>
  </joint>
  <joint name="shelf:shelf:shelf_center_joint" type="fixed">
    <origin xyz="0.17 0.52 0.6775" rpy="0.0 0.0 0.0"/>
    <parent link="shelf:shelf:shelf_origin"/>
    <child link="shelf:shelf:shelf_center"/>
  </joint>
  <joint name="shelf:shelf:shelf_base_center_joint" type="fixed">
    <origin xyz="0.17 0.52 0.0" rpy="0.0 0.0 0.0"/>
    <parent link="shelf:shelf:shelf_origin"/>
    <child link="shelf:shelf:shelf_base_center"/>
  </joint>
  <link name="shelf:shelf:shelf_back">
    <visual>
      <origin xyz="0.0 0.0 0.0" rpy="0.0 0.0 0.0"/>
      <geometry>
        <box size="0.01 1.04 1.355"/>
      </geometry>
      <material name="shelf_blue"/>
    </visual>
    <collision>
      <origin xyz="0.0 0.0 0.0" rpy="0.0 0.0 0.0"/>
      <geometry>
        <box size="0.01 1.04 1.355"/>
      </geometry>
    </collision>
  </link>
  <joint name="shelf:shelf:shelf_back:joint" type="fixed">
    <origin xyz="0.34 0.52 0.6775" rpy="0.0 0.0 0.0"/>
    <parent link="shelf:shelf:shelf_origin"/>
    <child link="shelf:shelf:shelf_back"/>
  </joint>
  <link name="shelf:shelf:shelf_right_side">
    <visual>
      <origin xyz="0.0 0.0 0.0" rpy="0.0 0.0 0.0"/>
      <geometry>
        <box size="0.34 0.01 1.355"/>
      </geometry>
      <material name="shelf_blue"/>
    </visual>
    <collision>
      <origin xyz="0.0 0.0 0.0" rpy="0.0 0.0 0.0"/>
      <geometry>
        <box size="0.34 0.01 1.355"/>
      </geometry>
    </collision>
  </link>
  <joint name="shelf:shelf:shelf_right_side:joint" type="fixed">
    <origin xyz="0.17 0.0 0.6775" rpy="0.0 0.0 0.0"/>
    <parent link="shelf:shelf:shelf_origin"/>
    <child link="shelf:shelf:shelf_right_side"/>
  </joint>
  <link name="shelf:shelf:shelf_left_side">
    <visual>
      <origin xyz="0.0 0.0 0.0" rpy="0.0 0.0 0.0"/>
      <geometry>
        <box size="0.34 0.01 1.355"/>
      </geometry>
      <material name="shelf_blue"/>
    </visual>
    <collision>
      <origin xyz="0.0 0.0 0.0" rpy="0.0 0.0 0.0"/>
      <geometry>
        <box size="0.34 0.01 1.355"/>
      </geometry>
    </collision>
  </link>
  <joint name="shelf:shelf:shelf_left_side:joint" type="fixed">
    <origin xyz="0.17 1.04 0.6775" rpy="0.0 0.0 0.0"/>
    <parent link="shelf:shelf:shelf_origin"/>
    <child link="shelf:shelf:shelf_left_side"/>
  </joint>
  <link name="shelf:shelf:shelf_floor_0">
    <visual>
      <origin xyz="0.0 0.0 -0.02" rpy="0.0 0.0 0.0"/>
      <geometry>
        <box size="0.34 1.04 0.04"/>
      </geometry>
      <material name="shelf_blue"/>
    </visual>
    <collision>
      <origin xyz="0.0 0.0 -0.02" rpy="0.0 0.0 0.0"/>
      <geometry>
        <box size="0.34 1.04 0.04"/>
      </geometry>
    </collision>
  </link>
  <joint name="shelf:shelf:shelf_floor_0:joint" type="fixed">
    <origin xyz="0.0 0.0 0.077" rpy="0.0 0.0 0.0"/>
    <parent link="shelf:shelf:shelf_base_center"/>
    <child link="shelf:shelf:shelf_floor_0"/>
  </joint>
  <link name="shelf:shelf:shelf_floor_1">
    <visual>
      <origin xyz="0.0 0.0 -0.02" rpy="0.0 0.0 0.0"/>
      <geometry>
        <box size="0.34 1.04 0.04"/>
      </geometry>
      <material name="shelf_blue"/>
    </visual>
    <collision>
      <origin xyz="0.0 0.0 -0.02" rpy="0.0 0.0 0.0"/>
      <geometry>
        <box size="0.34 1.04 0.04"/>
      </geometry>
    </collision>
  </link>
  <joint name="shelf:shelf:shelf_floor_1:joint" type="fixed">
    <origin xyz="0.0 0.0 0.371" rpy="0.0 0.0 0.0"/>
    <parent link="shelf:shelf:shelf_base_center"/>
    <child link="shelf:shelf:shelf_floor_1"/>
  </joint>
  <link name="shelf:shelf:shelf_floor_2">
    <visual>
      <origin xyz="0.0 0.0 -0.02" rpy="0.0 0.0 0.0"/>
      <geometry>
        <box size="0.34 1.04 0.04"/>
      </geometry>
      <material name="shelf_blue"/>
    </visual>
    <collision>
      <origin xyz="0.0 0.0 -0.02" rpy="0.0 0.0 0.0"/>
      <geometry>
        <box size="0.34 1.04 0.04"/>
      </geometry>
    </collision>
  </link>
  <joint name="shelf:shelf:shelf_floor_2:joint" type="fixed">
    <origin xyz="0.0 0.0 0.716" rpy="0.0 0.0 0.0"/>
    <parent link="shelf:shelf:shelf_base_center"/>
    <child link="shelf:shelf:shelf_floor_2"/>
  </joint>
  <link name="kitchen_main">
    <inertial>
      <origin xyz="0.0 0.0 0.0" rpy="0.0 0.0 0.0"/>
      <mass value="1.0"/>
      <inertia ixx="1.0" ixy="0.0" ixz="0.0" iyy="1.0" iyz="0.0" izz="1.0"/>
    </inertial>
  </link>
  <joint name="kitchen_main" type="fixed">
    <origin xyz="2.45 -0.67 0.0" rpy="0.0 0.0 -1.57"/>
    <parent link="urdf_offset"/>
    <child link="kitchen_main"/>
  </joint>
  <link name="sink_area_footprint">
    <inertial>
      <origin xyz="0.0 0.0 0.0" rpy="0.0 0.0 0.0"/>
      <mass value="1.0"/>
      <inertia ixx="1.0" ixy="0.0" ixz="0.0" iyy="1.0" iyz="0.0" izz="1.0"/>
    </inertial>
  </link>
  <link name="sink_area">
    <inertial>
      <origin xyz="0.0 0.0 0.0" rpy="0.0 0.0 0.0"/>
      <mass value="1.0"/>
      <inertia ixx="1.0" ixy="0.0" ixz="0.0" iyy="1.0" iyz="0.0" izz="1.0"/>
    </inertial>
    <visual>
      <origin xyz="0.0 0.0 0.0" rpy="0.0 0.0 0.0"/>
      <geometry>
        <mesh filename="package://iai_kitchen/meshes/racks/SinkArea.obj"/>
      </geometry>
    </visual>
    <collision>
      <origin xyz="0.0 0.0 0.0" rpy="0.0 0.0 0.0"/>
      <geometry>
        <mesh filename="package://iai_kitchen/meshes/racks/SinkArea.obj"/>
      </geometry>
    </collision>
  </link>
  <joint name="sink_area_footprint_joint" type="fixed">
    <origin xyz="1.825 1.32 0.0" rpy="0.0 0.0 3.14159265359"/>
    <parent link="kitchen_main"/>
    <child link="sink_area_footprint"/>
  </joint>
  <joint name="sink_area_main_joint" type="fixed">
    <origin xyz="0.29 1.03 0.41" rpy="0.0 0.0 0.0"/>
    <parent link="sink_area_footprint"/>
    <child link="sink_area"/>
  </joint>
  <link name="sink_area_surface">
    <inertial>
      <origin xyz="0.0 0.0 0.0" rpy="0.0 0.0 0.0"/>
      <mass value="1.0"/>
      <inertia ixx="1.0" ixy="0.0" ixz="0.0" iyy="1.0" iyz="0.0" izz="1.0"/>
    </inertial>
    <collision>
      <origin xyz="0.0 -0.225 0.0" rpy="0.0 0.0 0.0"/>
      <geometry>
        <box size="0.575 1.6 0.02"/>
      </geometry>
    </collision>
  </link>
  <joint name="sink_area_surface_joint" type="fixed">
    <origin xyz="0.0 0.0 0.43" rpy="0.0 0.0 0.0"/>
    <parent link="sink_area"/>
    <child link="sink_area_surface"/>
  </joint>
  <link name="sink_area_sink">
    <inertial>
      <origin xyz="0.0 0.0 0.0" rpy="0.0 0.0 0.0"/>
      <mass value="1.0"/>
      <inertia ixx="1.0" ixy="0.0" ixz="0.0" iyy="1.0" iyz="0.0" izz="1.0"/>
    </inertial>
    <visual>
      <origin xyz="0.0 0.0 0.0" rpy="0.0 0.0 0.0"/>
      <geometry>
        <mesh filename="package://iai_kitchen/meshes/misc/Sink.obj"/>
      </geometry>
    </visual>
    <collision>
      <origin xyz="0.0 0.0 0.0" rpy="0.0 0.0 0.0"/>
      <geometry>
        <mesh filename="package://iai_kitchen/meshes/misc/Sink.obj"/>
      </geometry>
    </collision>
  </link>
  <joint name="sink_area_sink_joint" type="fixed">
    <origin xyz="0.005 0.47 0.4414" rpy="0.0 0.0 0.0"/>
    <parent link="sink_area"/>
    <child link="sink_area_sink"/>
  </joint>
  <link name="sink_area_right_panel">
    <inertial>
      <origin xyz="0.0 0.0 0.0" rpy="0.0 0.0 0.0"/>
      <mass value="1.0"/>
      <inertia ixx="1.0" ixy="0.0" ixz="0.0" iyy="1.0" iyz="0.0" izz="1.0"/>
    </inertial>
    <visual>
      <origin xyz="0.0 0.0 0.0" rpy="0.0 0.0 0.0"/>
      <geometry>
        <mesh filename="package://iai_kitchen/meshes/drawers/Panel_60.obj"/>
      </geometry>
    </visual>
    <collision>
      <origin xyz="0.0 0.0 0.0" rpy="0.0 0.0 0.0"/>
      <geometry>
        <mesh filename="package://iai_kitchen/meshes/drawers/Panel_60.obj"/>
      </geometry>
    </collision>
  </link>
  <joint name="sink_area_right_panel_joint" type="fixed">
    <origin xyz="0.28 0.7 0.355" rpy="0.0 0.0 0.0"/>
    <parent link="sink_area"/>
    <child link="sink_area_right_panel"/>
  </joint>
  <link name="sink_area_trash_drawer_main">
    <inertial>
      <origin xyz="0.0 0.0 0.0" rpy="0.0 0.0 0.0"/>
      <mass value="1.0"/>
      <inertia ixx="1.0" ixy="0.0" ixz="0.0" iyy="1.0" iyz="0.0" izz="1.0"/>
    </inertial>
    <visual>
      <origin xyz="0.0 0.0 0.0" rpy="0.0 0.0 0.0"/>
      <geometry>
        <mesh filename="package://iai_kitchen/meshes/drawers/Drawer_60_58.obj"/>
      </geometry>
    </visual>
    <collision>
      <origin xyz="0.0 0.0 0.0" rpy="0.0 0.0 0.0"/>
      <geometry>
        <mesh filename="package://iai_kitchen/meshes/drawers/Drawer_60_58.obj"/>
      </geometry>
    </collision>
  </link>
  <link name="sink_area_trash_drawer_handle">
    <inertial>
      <origin xyz="0.0 0.0 0.0" rpy="0.0 0.0 0.0"/>
      <mass value="1.0"/>
      <inertia ixx="1.0" ixy="0.0" ixz="0.0" iyy="1.0" iyz="0.0" izz="1.0"/>
    </inertial>
    <visual>
      <origin xyz="0.0 0.0 0.0" rpy="0.0 0.0 0.0"/>
      <geometry>
        <mesh filename="package://iai_kitchen/meshes/handles/Handle60.obj"/>
      </geometry>
    </visual>
    <collision>
      <origin xyz="0.0 0.0 0.0" rpy="0.0 0.0 0.0"/>
      <geometry>
        <mesh filename="package://iai_kitchen/meshes/handles/Handle60.obj"/>
      </geometry>
    </collision>
  </link>
  <joint name="sink_area_trash_drawer_main_joint" type="prismatic">
    <origin xyz="0.01 0.7 -0.015" rpy="0.0 0.0 0.0"/>
    <axis xyz="1.0 0.0 0.0"/>
    <parent link="sink_area"/>
    <child link="sink_area_trash_drawer_main"/>
    <limit effort="300.0" lower="0.0" upper="0.48" velocity="10.0"/>
  </joint>
  <joint name="sink_area_trash_drawer_handle_joint" type="fixed">
    <origin xyz="0.3325 0.0 0.2375" rpy="0.0 0.0 0.0"/>
    <axis xyz="0.0 0.0 1.0"/>
    <parent link="sink_area_trash_drawer_main"/>
    <child link="sink_area_trash_drawer_handle"/>
    <limit effort="300.0" lower="0.0" upper="1.57079632679" velocity="10.0"/>
  </joint>
  <link name="sink_area_left_upper_drawer_main">
    <inertial>
      <origin xyz="0.0 0.0 0.0" rpy="0.0 0.0 0.0"/>
      <mass value="1.0"/>
      <inertia ixx="1.0" ixy="0.0" ixz="0.0" iyy="1.0" iyz="0.0" izz="1.0"/>
    </inertial>
    <visual>
      <origin xyz="0.0 0.0 0.0" rpy="0.0 0.0 0.0"/>
      <geometry>
        <mesh filename="package://iai_kitchen/meshes/drawers/Drawer_80_14.obj"/>
      </geometry>
    </visual>
    <collision>
      <origin xyz="0.0 0.0 0.0" rpy="0.0 0.0 0.0"/>
      <geometry>
        <mesh filename="package://iai_kitchen/meshes/drawers/Drawer_80_14.obj"/>
      </geometry>
    </collision>
  </link>
  <link name="sink_area_left_upper_drawer_handle">
    <inertial>
      <origin xyz="0.0 0.0 0.0" rpy="0.0 0.0 0.0"/>
      <mass value="1.0"/>
      <inertia ixx="1.0" ixy="0.0" ixz="0.0" iyy="1.0" iyz="0.0" izz="1.0"/>
    </inertial>
    <visual>
      <origin xyz="0.0 0.0 0.0" rpy="0.0 0.0 0.0"/>
      <geometry>
        <mesh filename="package://iai_kitchen/meshes/handles/Handle80.obj"/>
      </geometry>
    </visual>
    <collision>
      <origin xyz="0.0 0.0 0.0" rpy="0.0 0.0 0.0"/>
      <geometry>
        <mesh filename="package://iai_kitchen/meshes/handles/Handle80.obj"/>
      </geometry>
    </collision>
  </link>
  <joint name="sink_area_left_upper_drawer_main_joint" type="prismatic">
    <origin xyz="0.01 -0.6 0.345" rpy="0.0 0.0 0.0"/>
    <axis xyz="1.0 0.0 0.0"/>
    <parent link="sink_area"/>
    <child link="sink_area_left_upper_drawer_main"/>
    <limit effort="300.0" lower="0.0" upper="0.48" velocity="10.0"/>
  </joint>
  <joint name="sink_area_left_upper_drawer_handle_joint" type="fixed">
    <origin xyz="0.3325 0.0 0.0175" rpy="0.0 0.0 0.0"/>
    <axis xyz="0.0 0.0 1.0"/>
    <parent link="sink_area_left_upper_drawer_main"/>
    <child link="sink_area_left_upper_drawer_handle"/>
    <limit effort="300.0" lower="0.0" upper="1.57079632679" velocity="10.0"/>
  </joint>
  <link name="sink_area_left_middle_drawer_main">
    <inertial>
      <origin xyz="0.0 0.0 0.0" rpy="0.0 0.0 0.0"/>
      <mass value="1.0"/>
      <inertia ixx="1.0" ixy="0.0" ixz="0.0" iyy="1.0" iyz="0.0" izz="1.0"/>
    </inertial>
    <visual>
      <origin xyz="0.0 0.0 0.0" rpy="0.0 0.0 0.0"/>
      <geometry>
        <mesh filename="package://iai_kitchen/meshes/drawers/Drawer_80_29.obj"/>
      </geometry>
    </visual>
    <collision>
      <origin xyz="0.0 0.0 0.0" rpy="0.0 0.0 0.0"/>
      <geometry>
        <mesh filename="package://iai_kitchen/meshes/drawers/Drawer_80_29.obj"/>
      </geometry>
    </collision>
  </link>
  <link name="sink_area_left_middle_drawer_handle">
    <inertial>
      <origin xyz="0.0 0.0 0.0" rpy="0.0 0.0 0.0"/>
      <mass value="1.0"/>
      <inertia ixx="1.0" ixy="0.0" ixz="0.0" iyy="1.0" iyz="0.0" izz="1.0"/>
    </inertial>
    <visual>
      <origin xyz="0.0 0.0 0.0" rpy="0.0 0.0 0.0"/>
      <geometry>
        <mesh filename="package://iai_kitchen/meshes/handles/Handle80.obj"/>
      </geometry>
    </visual>
    <collision>
      <origin xyz="0.0 0.0 0.0" rpy="0.0 0.0 0.0"/>
      <geometry>
        <mesh filename="package://iai_kitchen/meshes/handles/Handle80.obj"/>
      </geometry>
    </collision>
  </link>
  <joint name="sink_area_left_middle_drawer_main_joint" type="prismatic">
    <origin xyz="0.01 -0.6 0.12" rpy="0.0 0.0 0.0"/>
    <axis xyz="1.0 0.0 0.0"/>
    <parent link="sink_area"/>
    <child link="sink_area_left_middle_drawer_main"/>
    <limit effort="300.0" lower="0.0" upper="0.48" velocity="10.0"/>
  </joint>
  <joint name="sink_area_left_middle_drawer_handle_joint" type="fixed">
    <origin xyz="0.3325 0.0 0.11" rpy="0.0 0.0 0.0"/>
    <axis xyz="0.0 0.0 1.0"/>
    <parent link="sink_area_left_middle_drawer_main"/>
    <child link="sink_area_left_middle_drawer_handle"/>
    <limit effort="300.0" lower="0.0" upper="1.57079632679" velocity="10.0"/>
  </joint>
  <link name="sink_area_left_bottom_drawer_main">
    <inertial>
      <origin xyz="0.0 0.0 0.0" rpy="0.0 0.0 0.0"/>
      <mass value="1.0"/>
      <inertia ixx="1.0" ixy="0.0" ixz="0.0" iyy="1.0" iyz="0.0" izz="1.0"/>
    </inertial>
    <visual>
      <origin xyz="0.0 0.0 0.0" rpy="0.0 0.0 0.0"/>
      <geometry>
        <mesh filename="package://iai_kitchen/meshes/drawers/Drawer_80_29.obj"/>
      </geometry>
    </visual>
    <collision>
      <origin xyz="0.0 0.0 0.0" rpy="0.0 0.0 0.0"/>
      <geometry>
        <mesh filename="package://iai_kitchen/meshes/drawers/Drawer_80_29.obj"/>
      </geometry>
    </collision>
  </link>
  <link name="sink_area_left_bottom_drawer_handle">
    <inertial>
      <origin xyz="0.0 0.0 0.0" rpy="0.0 0.0 0.0"/>
      <mass value="1.0"/>
      <inertia ixx="1.0" ixy="0.0" ixz="0.0" iyy="1.0" iyz="0.0" izz="1.0"/>
    </inertial>
    <visual>
      <origin xyz="0.0 0.0 0.0" rpy="0.0 0.0 0.0"/>
      <geometry>
        <mesh filename="package://iai_kitchen/meshes/handles/Handle80.obj"/>
      </geometry>
    </visual>
    <collision>
      <origin xyz="0.0 0.0 0.0" rpy="0.0 0.0 0.0"/>
      <geometry>
        <mesh filename="package://iai_kitchen/meshes/handles/Handle80.obj"/>
      </geometry>
    </collision>
  </link>
  <joint name="sink_area_left_bottom_drawer_main_joint" type="prismatic">
    <origin xyz="0.01 -0.6 -0.18" rpy="0.0 0.0 0.0"/>
    <axis xyz="1.0 0.0 0.0"/>
    <parent link="sink_area"/>
    <child link="sink_area_left_bottom_drawer_main"/>
    <limit effort="300.0" lower="0.0" upper="0.48" velocity="10.0"/>
  </joint>
  <joint name="sink_area_left_bottom_drawer_handle_joint" type="fixed">
    <origin xyz="0.3325 0.0 0.11" rpy="0.0 0.0 0.0"/>
    <axis xyz="0.0 0.0 1.0"/>
    <parent link="sink_area_left_bottom_drawer_main"/>
    <child link="sink_area_left_bottom_drawer_handle"/>
    <limit effort="300.0" lower="0.0" upper="1.57079632679" velocity="10.0"/>
  </joint>
  <link name="sink_area_dish_washer_main">
    <inertial>
      <origin xyz="0.0 0.0 0.0" rpy="0.0 0.0 0.0"/>
      <mass value="1.0"/>
      <inertia ixx="1.0" ixy="0.0" ixz="0.0" iyy="1.0" iyz="0.0" izz="1.0"/>
    </inertial>
    <visual>
      <origin xyz="0.0 0.0 0.0" rpy="0.0 0.0 0.0"/>
      <geometry>
        <mesh filename="package://iai_kitchen/meshes/misc/DishWasher.obj"/>
      </geometry>
    </visual>
    <collision>
      <origin xyz="0.0 0.0 0.0" rpy="0.0 0.0 0.0"/>
      <geometry>
        <mesh filename="package://iai_kitchen/meshes/misc/DishWasher.obj"/>
      </geometry>
    </collision>
  </link>
  <link name="sink_area_dish_washer_door">
    <inertial>
      <origin xyz="0.0 0.0 0.0" rpy="0.0 0.0 0.0"/>
      <mass value="1.0"/>
      <inertia ixx="1.0" ixy="0.0" ixz="0.0" iyy="1.0" iyz="0.0" izz="1.0"/>
    </inertial>
    <visual>
      <origin xyz="0.0 0.0 0.0" rpy="1.57079632679 0.0 0.0"/>
      <geometry>
        <mesh filename="package://iai_kitchen/meshes/misc/DishWasherDoor.obj"/>
      </geometry>
    </visual>
    <collision>
      <origin xyz="0.0 0.0 0.0" rpy="1.57079632679 0.0 0.0"/>
      <geometry>
        <mesh filename="package://iai_kitchen/meshes/misc/DishWasherDoor.obj"/>
      </geometry>
    </collision>
  </link>
  <link name="sink_area_dish_washer_door_handle">
    <inertial>
      <origin xyz="0.0 0.0 0.0" rpy="0.0 0.0 0.0"/>
      <mass value="1.0"/>
      <inertia ixx="1.0" ixy="0.0" ixz="0.0" iyy="1.0" iyz="0.0" izz="1.0"/>
    </inertial>
    <visual>
      <origin xyz="0.0 0.0 0.0" rpy="0.0 0.0 0.0"/>
      <geometry>
        <mesh filename="package://iai_kitchen/meshes/handles/Handle60.obj"/>
      </geometry>
    </visual>
    <collision>
      <origin xyz="0.0 0.0 0.0" rpy="0.0 0.0 0.0"/>
      <geometry>
        <mesh filename="package://iai_kitchen/meshes/handles/Handle60.obj"/>
      </geometry>
    </collision>
  </link>
  <joint name="sink_area_dish_washer_main_joint" type="fixed">
    <origin xyz="0.01 0.1 0.044" rpy="0.0 0.0 0.0"/>
    <axis xyz="1.0 0.0 0.0"/>
    <parent link="sink_area"/>
    <child link="sink_area_dish_washer_main"/>
  </joint>
  <joint name="sink_area_dish_washer_door_joint" type="revolute">
    <origin xyz="0.27 0.0 -0.325" rpy="-1.57079632679 0.03 0.0"/>
    <axis xyz="0.0 0.0 1.0"/>
    <parent link="sink_area_dish_washer_main"/>
    <child link="sink_area_dish_washer_door"/>
    <limit effort="300.0" lower="0.0" upper="1.57079632679" velocity="10.0"/>
  </joint>
  <joint name="sink_area_dish_washer_door_handle_joint" type="fixed">
    <origin xyz="0.0625 -0.6325 0.0" rpy="-1.57079632679 0.0 0.0"/>
    <parent link="sink_area_dish_washer_door"/>
    <child link="sink_area_dish_washer_door_handle"/>
  </joint>
  <link name="oven_area_area_footprint">
    <inertial>
      <origin xyz="0.0 0.0 0.0" rpy="0.0 0.0 0.0"/>
      <mass value="1.0"/>
      <inertia ixx="1.0" ixy="0.0" ixz="0.0" iyy="1.0" iyz="0.0" izz="1.0"/>
    </inertial>
  </link>
  <link name="oven_area_area">
    <inertial>
      <origin xyz="0.0 0.0 0.0" rpy="0.0 0.0 0.0"/>
      <mass value="1.0"/>
      <inertia ixx="1.0" ixy="0.0" ixz="0.0" iyy="1.0" iyz="0.0" izz="1.0"/>
    </inertial>
    <visual>
      <origin xyz="0.0 0.0 0.0" rpy="0.0 0.0 0.0"/>
      <geometry>
        <mesh filename="package://iai_kitchen/meshes/racks/OvenArea.obj"/>
      </geometry>
    </visual>
    <collision>
      <origin xyz="0.0 0.0 0.0" rpy="0.0 0.0 0.0"/>
      <geometry>
        <mesh filename="package://iai_kitchen/meshes/racks/OvenArea.obj"/>
      </geometry>
    </collision>
  </link>
  <joint name="oven_area_footprint_joint" type="fixed">
    <origin xyz="1.805 2.52 0.0" rpy="0.0 0.0 3.14159265359"/>
    <parent link="kitchen_main"/>
    <child link="oven_area_area_footprint"/>
  </joint>
  <joint name="oven_area_main_joint" type="fixed">
    <origin xyz="0.29 0.6 0.755" rpy="0.0 0.0 0.0"/>
    <parent link="oven_area_area_footprint"/>
    <child link="oven_area_area"/>
  </joint>
  <link name="oven_area_oven_main">
    <inertial>
      <origin xyz="0.0 0.0 0.0" rpy="0.0 0.0 0.0"/>
      <mass value="1.0"/>
      <inertia ixx="1.0" ixy="0.0" ixz="0.0" iyy="1.0" iyz="0.0" izz="1.0"/>
    </inertial>
    <visual>
      <origin xyz="0.0 0.0 0.0" rpy="0.0 0.0 0.0"/>
      <geometry>
        <mesh filename="package://iai_kitchen/meshes/oven/OvenMain.obj"/>
      </geometry>
    </visual>
    <collision>
      <origin xyz="0.0 0.0 0.0" rpy="0.0 0.0 0.0"/>
      <geometry>
        <mesh filename="package://iai_kitchen/meshes/oven/OvenMain.obj"/>
      </geometry>
    </collision>
  </link>
  <link name="oven_area_oven_door">
    <inertial>
      <origin xyz="0.0 0.0 0.0" rpy="0.0 0.0 0.0"/>
      <mass value="1.0"/>
      <inertia ixx="1.0" ixy="0.0" ixz="0.0" iyy="1.0" iyz="0.0" izz="1.0"/>
    </inertial>
    <visual>
      <origin xyz="0.0 0.0 0.0" rpy="1.57079632679 0.0 0.0"/>
      <geometry>
        <mesh filename="package://iai_kitchen/meshes/oven/OvenDoor.obj"/>
      </geometry>
    </visual>
    <collision>
      <origin xyz="0.0 0.0 0.0" rpy="1.57079632679 0.0 0.0"/>
      <geometry>
        <mesh filename="package://iai_kitchen/meshes/oven/OvenDoor.obj"/>
      </geometry>
    </collision>
  </link>
  <link name="oven_area_oven_door_handle">
    <inertial>
      <origin xyz="0.0 0.0 0.0" rpy="0.0 0.0 0.0"/>
      <mass value="1.0"/>
      <inertia ixx="1.0" ixy="0.0" ixz="0.0" iyy="1.0" iyz="0.0" izz="1.0"/>
    </inertial>
    <visual>
      <origin xyz="0.0 0.0 0.0" rpy="0.0 0.0 0.0"/>
      <geometry>
        <mesh filename="package://iai_kitchen/meshes/handles/Handle60.obj"/>
      </geometry>
    </visual>
    <collision>
      <origin xyz="0.0 0.0 0.0" rpy="0.0 0.0 0.0"/>
      <geometry>
        <mesh filename="package://iai_kitchen/meshes/handles/Handle60.obj"/>
      </geometry>
    </collision>
  </link>
  <link name="oven_area_oven_panel">
    <inertial>
      <origin xyz="0.0 0.0 0.0" rpy="0.0 0.0 0.0"/>
      <mass value="1.0"/>
      <inertia ixx="1.0" ixy="0.0" ixz="0.0" iyy="1.0" iyz="0.0" izz="1.0"/>
    </inertial>
    <visual>
      <origin xyz="0.0 0.0 0.0" rpy="0.0 0.0 0.0"/>
      <geometry>
        <mesh filename="package://iai_kitchen/meshes/oven/OvenPanel.obj"/>
      </geometry>
    </visual>
    <collision>
      <origin xyz="0.0 0.0 0.0" rpy="0.0 0.0 0.0"/>
      <geometry>
        <mesh filename="package://iai_kitchen/meshes/oven/OvenPanel.obj"/>
      </geometry>
    </collision>
  </link>
  <joint name="oven_area_oven_main_joint" type="fixed">
    <origin xyz="0.0 0.0 0.415" rpy="0.0 0.0 0.0"/>
    <parent link="oven_area_area"/>
    <child link="oven_area_oven_main"/>
  </joint>
  <joint name="oven_area_oven_door_joint" type="revolute">
    <origin xyz="0.2737 0.0 -0.2614" rpy="-1.57079632679 0.0 0.0"/>
    <axis xyz="0.0 0.0 1.0"/>
    <parent link="oven_area_oven_main"/>
    <child link="oven_area_oven_door"/>
    <limit effort="0.03" lower="0.0" upper="0.0" velocity="10.0"/>
    <dynamics damping="100.1"/>
  </joint>
  <gazebo reference="oven_area_oven_door_joint">
    <kp>1000000000</kp>
    <kd>1000000000</kd>
  </gazebo>
  <joint name="oven_area_oven_door_handle_joint" type="fixed">
    <origin xyz="0.05876 -0.39803 0.0" rpy="-1.57079632679 0.0 0.0"/>
    <axis xyz="0.0 0.0 1.0"/>
    <parent link="oven_area_oven_door"/>
    <child link="oven_area_oven_door_handle"/>
    <limit effort="300.0" lower="0.0" upper="1.57079632679" velocity="10.0"/>
  </joint>
  <joint name="oven_area_oven_panel_joint" type="fixed">
    <origin xyz="0.27 0.0 0.2449" rpy="0.0 0.0 0.0"/>
    <parent link="oven_area_oven_main"/>
    <child link="oven_area_oven_panel"/>
  </joint>
  <link name="oven_area_oven_knob_stove_1">
    <inertial>
      <origin xyz="0.0 0.0 0.0" rpy="0.0 0.0 0.0"/>
      <mass value="1.0"/>
      <inertia ixx="1.0" ixy="0.0" ixz="0.0" iyy="1.0" iyz="0.0" izz="1.0"/>
    </inertial>
    <visual>
      <origin xyz="0.0 0.0 0.0" rpy="0.0 1.57079632679 0.0"/>
      <geometry>
        <mesh filename="package://iai_kitchen/meshes/oven/Knob.obj"/>
      </geometry>
    </visual>
    <collision>
      <origin xyz="0.0 0.0 0.0" rpy="0.0 1.57079632679 0.0"/>
      <geometry>
        <mesh filename="package://iai_kitchen/meshes/oven/Knob.obj"/>
      </geometry>
    </collision>
  </link>
  <joint name="oven_area_oven_knob_stove_1_joint" type="revolute">
    <origin xyz="0.0 -0.21 0.0" rpy="0.0 -1.57079632679 0.0"/>
    <axis xyz="0.0 0.0 1.0"/>
    <parent link="oven_area_oven_panel"/>
    <child link="oven_area_oven_knob_stove_1"/>
    <limit effort="300.0" lower="0.0" upper="3.14159265359" velocity="10.0"/>
  </joint>
  <link name="oven_area_oven_knob_stove_2">
    <inertial>
      <origin xyz="0.0 0.0 0.0" rpy="0.0 0.0 0.0"/>
      <mass value="1.0"/>
      <inertia ixx="1.0" ixy="0.0" ixz="0.0" iyy="1.0" iyz="0.0" izz="1.0"/>
    </inertial>
    <visual>
      <origin xyz="0.0 0.0 0.0" rpy="0.0 1.57079632679 0.0"/>
      <geometry>
        <mesh filename="package://iai_kitchen/meshes/oven/Knob.obj"/>
      </geometry>
    </visual>
    <collision>
      <origin xyz="0.0 0.0 0.0" rpy="0.0 1.57079632679 0.0"/>
      <geometry>
        <mesh filename="package://iai_kitchen/meshes/oven/Knob.obj"/>
      </geometry>
    </collision>
  </link>
  <joint name="oven_area_oven_knob_stove_2_joint" type="revolute">
    <origin xyz="0.0 -0.14 0.0" rpy="0.0 -1.57079632679 0.0"/>
    <axis xyz="0.0 0.0 1.0"/>
    <parent link="oven_area_oven_panel"/>
    <child link="oven_area_oven_knob_stove_2"/>
    <limit effort="300.0" lower="0.0" upper="3.14159265359" velocity="10.0"/>
  </joint>
  <link name="oven_area_oven_knob_stove_3">
    <inertial>
      <origin xyz="0.0 0.0 0.0" rpy="0.0 0.0 0.0"/>
      <mass value="1.0"/>
      <inertia ixx="1.0" ixy="0.0" ixz="0.0" iyy="1.0" iyz="0.0" izz="1.0"/>
    </inertial>
    <visual>
      <origin xyz="0.0 0.0 0.0" rpy="0.0 1.57079632679 0.0"/>
      <geometry>
        <mesh filename="package://iai_kitchen/meshes/oven/Knob.obj"/>
      </geometry>
    </visual>
    <collision>
      <origin xyz="0.0 0.0 0.0" rpy="0.0 1.57079632679 0.0"/>
      <geometry>
        <mesh filename="package://iai_kitchen/meshes/oven/Knob.obj"/>
      </geometry>
    </collision>
  </link>
  <joint name="oven_area_oven_knob_stove_3_joint" type="revolute">
    <origin xyz="0.0 -0.07 0.0" rpy="0.0 -1.57079632679 0.0"/>
    <axis xyz="0.0 0.0 1.0"/>
    <parent link="oven_area_oven_panel"/>
    <child link="oven_area_oven_knob_stove_3"/>
    <limit effort="300.0" lower="0.0" upper="3.14159265359" velocity="10.0"/>
  </joint>
  <link name="oven_area_oven_knob_stove_4">
    <inertial>
      <origin xyz="0.0 0.0 0.0" rpy="0.0 0.0 0.0"/>
      <mass value="1.0"/>
      <inertia ixx="1.0" ixy="0.0" ixz="0.0" iyy="1.0" iyz="0.0" izz="1.0"/>
    </inertial>
    <visual>
      <origin xyz="0.0 0.0 0.0" rpy="0.0 1.57079632679 0.0"/>
      <geometry>
        <mesh filename="package://iai_kitchen/meshes/oven/Knob.obj"/>
      </geometry>
    </visual>
    <collision>
      <origin xyz="0.0 0.0 0.0" rpy="0.0 1.57079632679 0.0"/>
      <geometry>
        <mesh filename="package://iai_kitchen/meshes/oven/Knob.obj"/>
      </geometry>
    </collision>
  </link>
  <joint name="oven_area_oven_knob_stove_4_joint" type="revolute">
    <origin xyz="0.0 -0.0 0.0" rpy="0.0 -1.57079632679 0.0"/>
    <axis xyz="0.0 0.0 1.0"/>
    <parent link="oven_area_oven_panel"/>
    <child link="oven_area_oven_knob_stove_4"/>
    <limit effort="300.0" lower="0.0" upper="3.14159265359" velocity="10.0"/>
  </joint>
  <link name="oven_area_oven_knob_oven">
    <inertial>
      <origin xyz="0.0 0.0 0.0" rpy="0.0 0.0 0.0"/>
      <mass value="1.0"/>
      <inertia ixx="1.0" ixy="0.0" ixz="0.0" iyy="1.0" iyz="0.0" izz="1.0"/>
    </inertial>
    <visual>
      <origin xyz="0.0 0.0 0.0" rpy="0.0 1.57079632679 0.0"/>
      <geometry>
        <mesh filename="package://iai_kitchen/meshes/oven/Knob.obj"/>
      </geometry>
    </visual>
    <collision>
      <origin xyz="0.0 0.0 0.0" rpy="0.0 1.57079632679 0.0"/>
      <geometry>
        <mesh filename="package://iai_kitchen/meshes/oven/Knob.obj"/>
      </geometry>
    </collision>
  </link>
  <joint name="oven_area_oven_knob_oven_joint" type="revolute">
    <origin xyz="0.0 0.16 0.0" rpy="0.0 -1.57079632679 0.0"/>
    <axis xyz="0.0 0.0 1.0"/>
    <parent link="oven_area_oven_panel"/>
    <child link="oven_area_oven_knob_oven"/>
    <limit effort="300.0" lower="0.0" upper="3.14159265359" velocity="10.0"/>
  </joint>
  <link name="oven_area_area_middle_upper_drawer_main">
    <inertial>
      <origin xyz="0.0 0.0 0.0" rpy="0.0 0.0 0.0"/>
      <mass value="1.0"/>
      <inertia ixx="1.0" ixy="0.0" ixz="0.0" iyy="1.0" iyz="0.0" izz="1.0"/>
    </inertial>
    <visual>
      <origin xyz="0.0 0.0 0.0" rpy="0.0 0.0 0.0"/>
      <geometry>
        <mesh filename="package://iai_kitchen/meshes/drawers/Drawer_60_14.obj"/>
      </geometry>
    </visual>
    <collision>
      <origin xyz="0.0 0.0 0.0" rpy="0.0 0.0 0.0"/>
      <geometry>
        <mesh filename="package://iai_kitchen/meshes/drawers/Drawer_60_14.obj"/>
      </geometry>
    </collision>
  </link>
  <link name="oven_area_area_middle_upper_drawer_handle">
    <inertial>
      <origin xyz="0.0 0.0 0.0" rpy="0.0 0.0 0.0"/>
      <mass value="1.0"/>
      <inertia ixx="1.0" ixy="0.0" ixz="0.0" iyy="1.0" iyz="0.0" izz="1.0"/>
    </inertial>
    <visual>
      <origin xyz="0.0 0.0 0.0" rpy="0.0 0.0 0.0"/>
      <geometry>
        <mesh filename="package://iai_kitchen/meshes/handles/Handle60.obj"/>
      </geometry>
    </visual>
    <collision>
      <origin xyz="0.0 0.0 0.0" rpy="0.0 0.0 0.0"/>
      <geometry>
        <mesh filename="package://iai_kitchen/meshes/handles/Handle60.obj"/>
      </geometry>
    </collision>
  </link>
  <joint name="oven_area_area_middle_upper_drawer_main_joint" type="prismatic">
    <origin xyz="0.0 -0.0 0.045" rpy="0.0 0.0 0.0"/>
    <axis xyz="1.0 0.0 0.0"/>
    <parent link="oven_area_area"/>
    <child link="oven_area_area_middle_upper_drawer_main"/>
    <limit effort="300.0" lower="0.0" upper="0.48" velocity="10.0"/>
  </joint>
  <joint name="oven_area_area_middle_upper_drawer_handle_joint" type="fixed">
    <origin xyz="0.3325 0.0 0.0175" rpy="0.0 0.0 0.0"/>
    <axis xyz="0.0 0.0 1.0"/>
    <parent link="oven_area_area_middle_upper_drawer_main"/>
    <child link="oven_area_area_middle_upper_drawer_handle"/>
    <limit effort="300.0" lower="0.0" upper="1.57079632679" velocity="10.0"/>
  </joint>
  <link name="oven_area_area_middle_lower_drawer_main">
    <inertial>
      <origin xyz="0.0 0.0 0.0" rpy="0.0 0.0 0.0"/>
      <mass value="1.0"/>
      <inertia ixx="1.0" ixy="0.0" ixz="0.0" iyy="1.0" iyz="0.0" izz="1.0"/>
    </inertial>
    <visual>
      <origin xyz="0.0 0.0 0.0" rpy="0.0 0.0 0.0"/>
      <geometry>
        <mesh filename="package://iai_kitchen/meshes/drawers/Drawer_60_58.obj"/>
      </geometry>
    </visual>
    <collision>
      <origin xyz="0.0 0.0 0.0" rpy="0.0 0.0 0.0"/>
      <geometry>
        <mesh filename="package://iai_kitchen/meshes/drawers/Drawer_60_58.obj"/>
      </geometry>
    </collision>
  </link>
  <link name="oven_area_area_middle_lower_drawer_handle">
    <inertial>
      <origin xyz="0.0 0.0 0.0" rpy="0.0 0.0 0.0"/>
      <mass value="1.0"/>
      <inertia ixx="1.0" ixy="0.0" ixz="0.0" iyy="1.0" iyz="0.0" izz="1.0"/>
    </inertial>
    <visual>
      <origin xyz="0.0 0.0 0.0" rpy="0.0 0.0 0.0"/>
      <geometry>
        <mesh filename="package://iai_kitchen/meshes/handles/Handle60.obj"/>
      </geometry>
    </visual>
    <collision>
      <origin xyz="0.0 0.0 0.0" rpy="0.0 0.0 0.0"/>
      <geometry>
        <mesh filename="package://iai_kitchen/meshes/handles/Handle60.obj"/>
      </geometry>
    </collision>
  </link>
  <joint name="oven_area_area_middle_lower_drawer_main_joint" type="prismatic">
    <origin xyz="0.0 -0.0 -0.315" rpy="0.0 0.0 0.0"/>
    <axis xyz="1.0 0.0 0.0"/>
    <parent link="oven_area_area"/>
    <child link="oven_area_area_middle_lower_drawer_main"/>
    <limit effort="300.0" lower="0.0" upper="0.48" velocity="10.0"/>
  </joint>
  <joint name="oven_area_area_middle_lower_drawer_handle_joint" type="fixed">
    <origin xyz="0.3325 0.0 0.2375" rpy="0.0 0.0 0.0"/>
    <axis xyz="0.0 0.0 1.0"/>
    <parent link="oven_area_area_middle_lower_drawer_main"/>
    <child link="oven_area_area_middle_lower_drawer_handle"/>
    <limit effort="300.0" lower="0.0" upper="1.57079632679" velocity="10.0"/>
  </joint>
  <link name="oven_area_area_left_drawer_main">
    <inertial>
      <origin xyz="0.0 0.0 0.0" rpy="0.0 0.0 0.0"/>
      <mass value="1.0"/>
      <inertia ixx="1.0" ixy="0.0" ixz="0.0" iyy="1.0" iyz="0.0" izz="1.0"/>
    </inertial>
    <visual>
      <origin xyz="0.0 0.0 0.0" rpy="0.0 0.0 0.0"/>
      <geometry>
        <mesh filename="package://iai_kitchen/meshes/drawers/VDrawer.obj"/>
      </geometry>
    </visual>
    <collision>
      <origin xyz="0.0 0.0 0.0" rpy="0.0 0.0 0.0"/>
      <geometry>
        <mesh filename="package://iai_kitchen/meshes/drawers/VDrawer.obj"/>
      </geometry>
    </collision>
  </link>
  <link name="oven_area_area_left_drawer_handle">
    <inertial>
      <origin xyz="0.0 0.0 0.0" rpy="0.0 0.0 0.0"/>
      <mass value="1.0"/>
      <inertia ixx="1.0" ixy="0.0" ixz="0.0" iyy="1.0" iyz="0.0" izz="1.0"/>
    </inertial>
    <visual>
      <origin xyz="0.0 0.0 0.0" rpy="0.0 0.0 0.0"/>
      <geometry>
        <mesh filename="package://iai_kitchen/meshes/handles/VHandle130.obj"/>
      </geometry>
    </visual>
    <collision>
      <origin xyz="0.0 0.0 0.0" rpy="0.0 0.0 0.0"/>
      <geometry>
        <mesh filename="package://iai_kitchen/meshes/handles/VHandle130.obj"/>
      </geometry>
    </collision>
  </link>
  <joint name="oven_area_area_left_drawer_main_joint" type="prismatic">
    <origin xyz="0.0 -0.45 0.06" rpy="0.0 0.0 0.0"/>
    <axis xyz="1.0 0.0 0.0"/>
    <parent link="oven_area_area"/>
    <child link="oven_area_area_left_drawer_main"/>
    <limit effort="300.0" lower="0.0" upper="0.48" velocity="10.0"/>
  </joint>
  <joint name="oven_area_area_left_drawer_handle_joint" type="fixed">
    <origin xyz="0.3525 0.0 0.0" rpy="0.0 0.0 0.0"/>
    <axis xyz="0.0 0.0 1.0"/>
    <parent link="oven_area_area_left_drawer_main"/>
    <child link="oven_area_area_left_drawer_handle"/>
    <limit effort="300.0" lower="0.0" upper="1.57079632679" velocity="10.0"/>
  </joint>
  <joint name="oven_area_area_right_drawer_joint" type="prismatic">
    <origin xyz="0.02 0.44 0.05" rpy="0.0 0.0 0.0"/>
    <axis xyz="0.999 0.0 0.044"/>
    <parent link="oven_area_area"/>
    <child link="oven_area_area_right_drawer_main"/>
    <limit effort="300.0" lower="0.0" upper="0.48" velocity="10.0"/>
  </joint>
  <link name="oven_area_area_right_drawer_main">
    <inertial>
      <mass value="0.1"/>
      <inertia ixx="4e-08" ixy="0.0" ixz="0.0" iyy="4e-08" iyz="0.0" izz="4e-08"/>
    </inertial>
  </link>
  <joint name="drawer_oven_right_front_joint" type="fixed">
    <origin xyz="0.25 0.0 0.0" rpy="0.0 0.0 0.0"/>
    <parent link="oven_area_area_right_drawer_main"/>
    <child link="drawer_oven_right_front_link"/>
  </joint>
  <link name="drawer_oven_right_front_link">
    <inertial>
      <mass value="1.0"/>
      <inertia ixx="0.153554166667" ixy="0.0" ixz="0.0" iyy="0.0348041666667" iyz="0.0" izz="0.173854166667"/>
    </inertial>
    <visual>
      <origin xyz="0.0 0.0 0.0" rpy="0.0 0.0 0.0"/>
      <geometry>
        <box size="0.025 0.295 1.325"/>
      </geometry>
    </visual>
    <collision>
      <origin xyz="0.0 0.0 0.0" rpy="0.0 0.0 0.0"/>
      <geometry>
        <box size="0.025 0.3 1.33"/>
      </geometry>
    </collision>
  </link>
  <link name="drawer_oven_right_board0_link">
    <inertial>
      <mass value="1.0"/>
      <inertia ixx="0.153554166667" ixy="0.0" ixz="0.0" iyy="0.0348041666667" iyz="0.0" izz="0.173854166667"/>
    </inertial>
    <visual>
      <origin xyz="0.0 0.0 0.0" rpy="0.0 0.0 0.0"/>
      <geometry>
        <box size="0.49 0.27 0.025"/>
      </geometry>
    </visual>
    <collision>
      <origin xyz="0.0 0.0 0.0" rpy="0.0 0.0 0.0"/>
      <geometry>
        <box size="0.49 0.27 0.025"/>
      </geometry>
    </collision>
  </link>
  <joint name="drawer_oven_right_board0_joint" type="fixed">
    <origin xyz="0.0 0.0 -0.655" rpy="0 0 0"/>
    <parent link="oven_area_area_right_drawer_main"/>
    <child link="drawer_oven_right_board0_link"/>
  </joint>
  <link name="drawer_oven_right_board0_barrier_right_link">
    <inertial>
      <mass value="1.0"/>
      <inertia ixx="0.153554166667" ixy="0.0" ixz="0.0" iyy="0.0348041666667" iyz="0.0" izz="0.173854166667"/>
    </inertial>
    <visual>
      <origin xyz="0.0 0.0 0.0" rpy="0.0 0.0 0.0"/>
      <geometry>
        <box size="0.49 0.02 0.05"/>
      </geometry>
    </visual>
    <collision>
      <origin xyz="0.0 0.0 0.0" rpy="0.0 0.0 0.0"/>
      <geometry>
        <box size="0.49 0.02 0.05"/>
      </geometry>
    </collision>
  </link>
  <joint name="drawer_oven_right_board0_barrier_right_joint" type="fixed">
    <origin xyz="0.0 -0.135 -0.62" rpy="0 0 0"/>
    <parent link="oven_area_area_right_drawer_main"/>
    <child link="drawer_oven_right_board0_barrier_right_link"/>
  </joint>
  <link name="drawer_oven_right_board0_barrier_left_link">
    <inertial>
      <mass value="1.0"/>
      <inertia ixx="0.153554166667" ixy="0.0" ixz="0.0" iyy="0.0348041666667" iyz="0.0" izz="0.173854166667"/>
    </inertial>
    <visual>
      <origin xyz="0.0 0.0 0.0" rpy="0.0 0.0 0.0"/>
      <geometry>
        <box size="0.49 0.02 0.05"/>
      </geometry>
    </visual>
    <collision>
      <origin xyz="0.0 0.0 0.0" rpy="0.0 0.0 0.0"/>
      <geometry>
        <box size="0.49 0.02 0.05"/>
      </geometry>
    </collision>
  </link>
  <joint name="drawer_oven_right_board0_barrier_left_joint" type="fixed">
    <origin xyz="0.0 0.135 -0.62" rpy="0 0 0"/>
    <parent link="oven_area_area_right_drawer_main"/>
    <child link="drawer_oven_right_board0_barrier_left_link"/>
  </joint>
  <link name="drawer_oven_right_board1_link">
    <inertial>
      <mass value="1.0"/>
      <inertia ixx="0.153554166667" ixy="0.0" ixz="0.0" iyy="0.0348041666667" iyz="0.0" izz="0.173854166667"/>
    </inertial>
    <visual>
      <origin xyz="0.0 0.0 0.0" rpy="0.0 0.0 0.0"/>
      <geometry>
        <box size="0.49 0.27 0.025"/>
      </geometry>
    </visual>
    <collision>
      <origin xyz="0.0 0.0 0.0" rpy="0.0 0.0 0.0"/>
      <geometry>
        <box size="0.49 0.27 0.025"/>
      </geometry>
    </collision>
  </link>
  <joint name="drawer_oven_right_board1_joint" type="fixed">
    <origin xyz="0.0 0.0 -0.33" rpy="0 0 0"/>
    <parent link="oven_area_area_right_drawer_main"/>
    <child link="drawer_oven_right_board1_link"/>
  </joint>
  <link name="drawer_oven_right_board1_barrier_right_link">
    <inertial>
      <mass value="1.0"/>
      <inertia ixx="0.153554166667" ixy="0.0" ixz="0.0" iyy="0.0348041666667" iyz="0.0" izz="0.173854166667"/>
    </inertial>
    <visual>
      <origin xyz="0.0 0.0 0.0" rpy="0.0 0.0 0.0"/>
      <geometry>
        <box size="0.49 0.02 0.05"/>
      </geometry>
    </visual>
    <collision>
      <origin xyz="0.0 0.0 0.0" rpy="0.0 0.0 0.0"/>
      <geometry>
        <box size="0.49 0.02 0.05"/>
      </geometry>
    </collision>
  </link>
  <joint name="drawer_oven_right_board1_barrier_right_joint" type="fixed">
    <origin xyz="0.0 -0.135 -0.295" rpy="0 0 0"/>
    <parent link="oven_area_area_right_drawer_main"/>
    <child link="drawer_oven_right_board1_barrier_right_link"/>
  </joint>
  <link name="drawer_oven_right_board1_barrier_left_link">
    <inertial>
      <mass value="1.0"/>
      <inertia ixx="0.153554166667" ixy="0.0" ixz="0.0" iyy="0.0348041666667" iyz="0.0" izz="0.173854166667"/>
    </inertial>
    <visual>
      <origin xyz="0.0 0.0 0.0" rpy="0.0 0.0 0.0"/>
      <geometry>
        <box size="0.49 0.02 0.05"/>
      </geometry>
    </visual>
    <collision>
      <origin xyz="0.0 0.0 0.0" rpy="0.0 0.0 0.0"/>
      <geometry>
        <box size="0.49 0.02 0.05"/>
      </geometry>
    </collision>
  </link>
  <joint name="drawer_oven_right_board1_barrier_left_joint" type="fixed">
    <origin xyz="0.0 0.135 -0.295" rpy="0 0 0"/>
    <parent link="oven_area_area_right_drawer_main"/>
    <child link="drawer_oven_right_board1_barrier_left_link"/>
  </joint>
  <link name="drawer_oven_right_board2_link">
    <inertial>
      <mass value="1.0"/>
      <inertia ixx="0.153554166667" ixy="0.0" ixz="0.0" iyy="0.0348041666667" iyz="0.0" izz="0.173854166667"/>
    </inertial>
    <visual>
      <origin xyz="0.0 0.0 0.0" rpy="0.0 0.0 0.0"/>
      <geometry>
        <box size="0.49 0.27 0.025"/>
      </geometry>
    </visual>
    <collision>
      <origin xyz="0.0 0.0 0.0" rpy="0.0 0.0 0.0"/>
      <geometry>
        <box size="0.49 0.27 0.025"/>
      </geometry>
    </collision>
  </link>
  <joint name="drawer_oven_right_board2_joint" type="fixed">
    <origin xyz="0.0 0.0 0.0" rpy="0 0 0"/>
    <parent link="oven_area_area_right_drawer_main"/>
    <child link="drawer_oven_right_board2_link"/>
  </joint>
  <link name="drawer_oven_right_board2_barrier_right_link">
    <inertial>
      <mass value="1.0"/>
      <inertia ixx="0.153554166667" ixy="0.0" ixz="0.0" iyy="0.0348041666667" iyz="0.0" izz="0.173854166667"/>
    </inertial>
    <visual>
      <origin xyz="0.0 0.0 0.0" rpy="0.0 0.0 0.0"/>
      <geometry>
        <box size="0.49 0.02 0.05"/>
      </geometry>
    </visual>
    <collision>
      <origin xyz="0.0 0.0 0.0" rpy="0.0 0.0 0.0"/>
      <geometry>
        <box size="0.49 0.02 0.05"/>
      </geometry>
    </collision>
  </link>
  <joint name="drawer_oven_right_board2_barrier_right_joint" type="fixed">
    <origin xyz="0.0 -0.135 0.035" rpy="0 0 0"/>
    <parent link="oven_area_area_right_drawer_main"/>
    <child link="drawer_oven_right_board2_barrier_right_link"/>
  </joint>
  <link name="drawer_oven_right_board2_barrier_left_link">
    <inertial>
      <mass value="1.0"/>
      <inertia ixx="0.153554166667" ixy="0.0" ixz="0.0" iyy="0.0348041666667" iyz="0.0" izz="0.173854166667"/>
    </inertial>
    <visual>
      <origin xyz="0.0 0.0 0.0" rpy="0.0 0.0 0.0"/>
      <geometry>
        <box size="0.49 0.02 0.05"/>
      </geometry>
    </visual>
    <collision>
      <origin xyz="0.0 0.0 0.0" rpy="0.0 0.0 0.0"/>
      <geometry>
        <box size="0.49 0.02 0.05"/>
      </geometry>
    </collision>
  </link>
  <joint name="drawer_oven_right_board2_barrier_left_joint" type="fixed">
    <origin xyz="0.0 0.135 0.035" rpy="0 0 0"/>
    <parent link="oven_area_area_right_drawer_main"/>
    <child link="drawer_oven_right_board2_barrier_left_link"/>
  </joint>
  <link name="drawer_oven_right_board3_link">
    <inertial>
      <mass value="1.0"/>
      <inertia ixx="0.153554166667" ixy="0.0" ixz="0.0" iyy="0.0348041666667" iyz="0.0" izz="0.173854166667"/>
    </inertial>
    <visual>
      <origin xyz="0.0 0.0 0.0" rpy="0.0 0.0 0.0"/>
      <geometry>
        <box size="0.49 0.27 0.025"/>
      </geometry>
    </visual>
    <collision>
      <origin xyz="0.0 0.0 0.0" rpy="0.0 0.0 0.0"/>
      <geometry>
        <box size="0.49 0.27 0.025"/>
      </geometry>
    </collision>
  </link>
  <joint name="drawer_oven_right_board3_joint" type="fixed">
    <origin xyz="0.0 0.0 0.33" rpy="0 0 0"/>
    <parent link="oven_area_area_right_drawer_main"/>
    <child link="drawer_oven_right_board3_link"/>
  </joint>
  <link name="drawer_oven_right_board3_barrier_right_link">
    <inertial>
      <mass value="1.0"/>
      <inertia ixx="0.153554166667" ixy="0.0" ixz="0.0" iyy="0.0348041666667" iyz="0.0" izz="0.173854166667"/>
    </inertial>
    <visual>
      <origin xyz="0.0 0.0 0.0" rpy="0.0 0.0 0.0"/>
      <geometry>
        <box size="0.49 0.02 0.05"/>
      </geometry>
    </visual>
    <collision>
      <origin xyz="0.0 0.0 0.0" rpy="0.0 0.0 0.0"/>
      <geometry>
        <box size="0.49 0.02 0.05"/>
      </geometry>
    </collision>
  </link>
  <joint name="drawer_oven_right_board3_barrier_right_joint" type="fixed">
    <origin xyz="0.0 -0.135 0.365" rpy="0 0 0"/>
    <parent link="oven_area_area_right_drawer_main"/>
    <child link="drawer_oven_right_board3_barrier_right_link"/>
  </joint>
  <link name="drawer_oven_right_board3_barrier_left_link">
    <inertial>
      <mass value="1.0"/>
      <inertia ixx="0.153554166667" ixy="0.0" ixz="0.0" iyy="0.0348041666667" iyz="0.0" izz="0.173854166667"/>
    </inertial>
    <visual>
      <origin xyz="0.0 0.0 0.0" rpy="0.0 0.0 0.0"/>
      <geometry>
        <box size="0.49 0.02 0.05"/>
      </geometry>
    </visual>
    <collision>
      <origin xyz="0.0 0.0 0.0" rpy="0.0 0.0 0.0"/>
      <geometry>
        <box size="0.49 0.02 0.05"/>
      </geometry>
    </collision>
  </link>
  <joint name="drawer_oven_right_board3_barrier_left_joint" type="fixed">
    <origin xyz="0.0 0.135 0.365" rpy="0 0 0"/>
    <parent link="oven_area_area_right_drawer_main"/>
    <child link="drawer_oven_right_board3_barrier_left_link"/>
  </joint>
  <joint name="oven_area_area_right_drawer_handle_joint" type="fixed">
    <origin xyz="0.05 0.0 0.0" rpy="0.0 0.0 0.0"/>
    <parent link="drawer_oven_right_front_link"/>
    <child link="oven_area_area_right_drawer_handle"/>
  </joint>
  <link name="oven_area_area_right_drawer_handle">
    <inertial>
      <mass value="0.1"/>
      <inertia ixx="0.0127110416667" ixy="0.0" ixz="0.0" iyy="1.66666666667e-06" iyz="0.0" izz="0.0127110416667"/>
    </inertial>
    <visual>
      <origin xyz="0.0 0.0 0.0" rpy="0.0 0.0 0.0"/>
      <geometry>
        <box size="0.01 0.01 1.235"/>
      </geometry>
    </visual>
    <collision>
      <origin xyz="0.0 0.0 0.0" rpy="0.0 0.0 0.0"/>
      <geometry>
        <box size="0.015 0.015 1.24"/>
      </geometry>
    </collision>
  </link>
  <link name="kitchen_island_footprint">
    <inertial>
      <origin xyz="0.0 0.0 0.0" rpy="0.0 0.0 0.0"/>
      <mass value="1.0"/>
      <inertia ixx="1.0" ixy="0.0" ixz="0.0" iyy="1.0" iyz="0.0" izz="1.0"/>
    </inertial>
  </link>
  <link name="kitchen_island">
    <inertial>
      <origin xyz="0.0 0.0 0.0" rpy="0.0 0.0 0.0"/>
      <mass value="1.0"/>
      <inertia ixx="1.0" ixy="0.0" ixz="0.0" iyy="1.0" iyz="0.0" izz="1.0"/>
    </inertial>
    <visual>
      <origin xyz="0.0 0.0 0.0" rpy="0.0 0.0 0.0"/>
      <geometry>
        <mesh filename="package://iai_kitchen/meshes/racks/IslandArea.obj"/>
      </geometry>
    </visual>
    <collision>
      <origin xyz="0.0 0.0 0.0" rpy="0.0 0.0 0.0"/>
      <geometry>
        <mesh filename="package://iai_kitchen/meshes/racks/IslandArea.obj"/>
      </geometry>
    </collision>
  </link>
  <joint name="kitchen_island_footprint_joint" type="fixed">
    <origin xyz="-1.365 0.64 0.0" rpy="0.0 0.0 0.0"/>
    <parent link="kitchen_main"/>
    <child link="kitchen_island_footprint"/>
  </joint>
  <joint name="kitchen_island_joint" type="fixed">
    <origin xyz="0.2975 1.05 0.421" rpy="0.0 0.0 0.0"/>
    <parent link="kitchen_island_footprint"/>
    <child link="kitchen_island"/>
  </joint>
  <link name="kitchen_island_surface">
    <inertial>
      <origin xyz="0.0 0.0 0.0" rpy="0.0 0.0 0.0"/>
      <mass value="1.0"/>
      <inertia ixx="1.0" ixy="0.0" ixz="0.0" iyy="1.0" iyz="0.0" izz="1.0"/>
    </inertial>
    <collision>
      <origin xyz="0.0 0.0 0.0" rpy="0.0 0.0 0.0"/>
      <geometry>
        <box size="0.8 2.45 0.02"/>
      </geometry>
    </collision>
  </link>
  <joint name="kitchen_island_surface_joint" type="fixed">
    <origin xyz="0.0 0.0 0.42" rpy="0.0 0.0 0.0"/>
    <parent link="kitchen_island"/>
    <child link="kitchen_island_surface"/>
  </joint>
  <link name="kitchen_island_stove">
    <inertial>
      <origin xyz="0.0 0.0 0.0" rpy="0.0 0.0 0.0"/>
      <mass value="1.0"/>
      <inertia ixx="1.0" ixy="0.0" ixz="0.0" iyy="1.0" iyz="0.0" izz="1.0"/>
    </inertial>
    <visual>
      <origin xyz="0.0 0.0 0.0" rpy="0.0 0.0 0.0"/>
      <geometry>
        <mesh filename="package://iai_kitchen/meshes/misc/Stove.obj"/>
      </geometry>
    </visual>
    <collision>
      <origin xyz="0.0 0.0 0.0" rpy="0.0 0.0 0.0"/>
      <geometry>
        <mesh filename="package://iai_kitchen/meshes/misc/Stove.obj"/>
      </geometry>
    </collision>
  </link>
  <joint name="kitchen_island_stove_joint" type="fixed">
    <origin xyz="0.0 0.7658 0.4315" rpy="0.0 0.0 0.0"/>
    <parent link="kitchen_island"/>
    <child link="kitchen_island_stove"/>
  </joint>
  <link name="kitchen_island_left_panel">
    <inertial>
      <origin xyz="0.0 0.0 0.0" rpy="0.0 0.0 0.0"/>
      <mass value="1.0"/>
      <inertia ixx="1.0" ixy="0.0" ixz="0.0" iyy="1.0" iyz="0.0" izz="1.0"/>
    </inertial>
    <visual>
      <origin xyz="0.0 0.0 0.0" rpy="0.0 0.0 0.0"/>
      <geometry>
        <mesh filename="package://iai_kitchen/meshes/drawers/Panel_60.obj"/>
      </geometry>
    </visual>
    <collision>
      <origin xyz="0.0 0.0 0.0" rpy="0.0 0.0 0.0"/>
      <geometry>
        <mesh filename="package://iai_kitchen/meshes/drawers/Panel_60.obj"/>
      </geometry>
    </collision>
  </link>
  <joint name="kitchen_island_left_panel_joint" type="fixed">
    <origin xyz="0.2725 -0.8 0.329" rpy="0.0 0.0 0.0"/>
    <parent link="kitchen_island"/>
    <child link="kitchen_island_left_panel"/>
  </joint>
  <link name="kitchen_island_left_upper_drawer_main">
    <inertial>
      <origin xyz="0.0 0.0 0.0" rpy="0.0 0.0 0.0"/>
      <mass value="1.0"/>
      <inertia ixx="1.0" ixy="0.0" ixz="0.0" iyy="1.0" iyz="0.0" izz="1.0"/>
    </inertial>
    <visual>
      <origin xyz="0.0 0.0 0.0" rpy="0.0 0.0 0.0"/>
      <geometry>
        <mesh filename="package://iai_kitchen/meshes/drawers/Drawer_60_29.obj"/>
      </geometry>
    </visual>
    <collision>
      <origin xyz="0.0 0.0 0.0" rpy="0.0 0.0 0.0"/>
      <geometry>
        <mesh filename="package://iai_kitchen/meshes/drawers/Drawer_60_29.obj"/>
      </geometry>
    </collision>
  </link>
  <link name="kitchen_island_left_upper_drawer_handle">
    <inertial>
      <origin xyz="0.0 0.0 0.0" rpy="0.0 0.0 0.0"/>
      <mass value="1.0"/>
      <inertia ixx="1.0" ixy="0.0" ixz="0.0" iyy="1.0" iyz="0.0" izz="1.0"/>
    </inertial>
    <visual>
      <origin xyz="0.0 0.0 0.0" rpy="0.0 0.0 0.0"/>
      <geometry>
        <mesh filename="package://iai_kitchen/meshes/handles/Handle60.obj"/>
      </geometry>
    </visual>
    <collision>
      <origin xyz="0.0 0.0 0.0" rpy="0.0 0.0 0.0"/>
      <geometry>
        <mesh filename="package://iai_kitchen/meshes/handles/Handle60.obj"/>
      </geometry>
    </collision>
  </link>
  <joint name="kitchen_island_left_upper_drawer_main_joint" type="prismatic">
    <origin xyz="0.0025 -0.8 0.114" rpy="0.0 0.0 0.0"/>
    <axis xyz="1.0 0.0 0.0"/>
    <parent link="kitchen_island"/>
    <child link="kitchen_island_left_upper_drawer_main"/>
    <limit effort="300.0" lower="0.0" upper="0.48" velocity="10.0"/>
  </joint>
  <joint name="kitchen_island_left_upper_drawer_handle_joint" type="fixed">
    <origin xyz="0.3325 0.0 0.11" rpy="0.0 0.0 0.0"/>
    <axis xyz="0.0 0.0 1.0"/>
    <parent link="kitchen_island_left_upper_drawer_main"/>
    <child link="kitchen_island_left_upper_drawer_handle"/>
    <limit effort="300.0" lower="0.0" upper="1.57079632679" velocity="10.0"/>
  </joint>
  <link name="kitchen_island_left_lower_drawer_main">
    <inertial>
      <origin xyz="0.0 0.0 0.0" rpy="0.0 0.0 0.0"/>
      <mass value="1.0"/>
      <inertia ixx="1.0" ixy="0.0" ixz="0.0" iyy="1.0" iyz="0.0" izz="1.0"/>
    </inertial>
    <visual>
      <origin xyz="0.0 0.0 0.0" rpy="0.0 0.0 0.0"/>
      <geometry>
        <mesh filename="package://iai_kitchen/meshes/drawers/Drawer_60_29.obj"/>
      </geometry>
    </visual>
    <collision>
      <origin xyz="0.0 0.0 0.0" rpy="0.0 0.0 0.0"/>
      <geometry>
        <mesh filename="package://iai_kitchen/meshes/drawers/Drawer_60_29.obj"/>
      </geometry>
    </collision>
  </link>
  <link name="kitchen_island_left_lower_drawer_handle">
    <inertial>
      <origin xyz="0.0 0.0 0.0" rpy="0.0 0.0 0.0"/>
      <mass value="1.0"/>
      <inertia ixx="1.0" ixy="0.0" ixz="0.0" iyy="1.0" iyz="0.0" izz="1.0"/>
    </inertial>
    <visual>
      <origin xyz="0.0 0.0 0.0" rpy="0.0 0.0 0.0"/>
      <geometry>
        <mesh filename="package://iai_kitchen/meshes/handles/Handle60.obj"/>
      </geometry>
    </visual>
    <collision>
      <origin xyz="0.0 0.0 0.0" rpy="0.0 0.0 0.0"/>
      <geometry>
        <mesh filename="package://iai_kitchen/meshes/handles/Handle60.obj"/>
      </geometry>
    </collision>
  </link>
  <joint name="kitchen_island_left_lower_drawer_main_joint" type="prismatic">
    <origin xyz="0.0025 -0.8 -0.176" rpy="0.0 0.0 0.0"/>
    <axis xyz="1.0 0.0 0.0"/>
    <parent link="kitchen_island"/>
    <child link="kitchen_island_left_lower_drawer_main"/>
    <limit effort="300.0" lower="0.0" upper="0.48" velocity="10.0"/>
  </joint>
  <joint name="kitchen_island_left_lower_drawer_handle_joint" type="fixed">
    <origin xyz="0.3325 0.0 0.11" rpy="0.0 0.0 0.0"/>
    <axis xyz="0.0 0.0 1.0"/>
    <parent link="kitchen_island_left_lower_drawer_main"/>
    <child link="kitchen_island_left_lower_drawer_handle"/>
    <limit effort="300.0" lower="0.0" upper="1.57079632679" velocity="10.0"/>
  </joint>
  <link name="kitchen_island_middle_panel">
    <inertial>
      <origin xyz="0.0 0.0 0.0" rpy="0.0 0.0 0.0"/>
      <mass value="1.0"/>
      <inertia ixx="1.0" ixy="0.0" ixz="0.0" iyy="1.0" iyz="0.0" izz="1.0"/>
    </inertial>
    <visual>
      <origin xyz="0.0 0.0 0.0" rpy="0.0 0.0 0.0"/>
      <geometry>
        <mesh filename="package://iai_kitchen/meshes/drawers/Panel_100.obj"/>
      </geometry>
    </visual>
    <collision>
      <origin xyz="0.0 0.0 0.0" rpy="0.0 0.0 0.0"/>
      <geometry>
        <mesh filename="package://iai_kitchen/meshes/drawers/Panel_100.obj"/>
      </geometry>
    </collision>
  </link>
  <joint name="kitchen_island_middle_panel_joint" type="fixed">
    <origin xyz="0.2725 0.0 0.329" rpy="0.0 0.0 0.0"/>
    <parent link="kitchen_island"/>
    <child link="kitchen_island_middle_panel"/>
  </joint>
  <link name="kitchen_island_middle_upper_drawer_main">
    <inertial>
      <origin xyz="0.0 0.0 0.0" rpy="0.0 0.0 0.0"/>
      <mass value="1.0"/>
      <inertia ixx="1.0" ixy="0.0" ixz="0.0" iyy="1.0" iyz="0.0" izz="1.0"/>
    </inertial>
    <visual>
      <origin xyz="0.0 0.0 0.0" rpy="0.0 0.0 0.0"/>
      <geometry>
        <mesh filename="package://iai_kitchen/meshes/drawers/Drawer_100_29.obj"/>
      </geometry>
    </visual>
    <collision>
      <origin xyz="0.0 0.0 0.0" rpy="0.0 0.0 0.0"/>
      <geometry>
        <mesh filename="package://iai_kitchen/meshes/drawers/Drawer_100_29.obj"/>
      </geometry>
    </collision>
  </link>
  <link name="kitchen_island_middle_upper_drawer_handle">
    <inertial>
      <origin xyz="0.0 0.0 0.0" rpy="0.0 0.0 0.0"/>
      <mass value="1.0"/>
      <inertia ixx="1.0" ixy="0.0" ixz="0.0" iyy="1.0" iyz="0.0" izz="1.0"/>
    </inertial>
    <visual>
      <origin xyz="0.0 0.0 0.0" rpy="0.0 0.0 0.0"/>
      <geometry>
        <mesh filename="package://iai_kitchen/meshes/handles/Handle100.obj"/>
      </geometry>
    </visual>
    <collision>
      <origin xyz="0.0 0.0 0.0" rpy="0.0 0.0 0.0"/>
      <geometry>
        <mesh filename="package://iai_kitchen/meshes/handles/Handle100.obj"/>
      </geometry>
    </collision>
  </link>
  <joint name="kitchen_island_middle_upper_drawer_main_joint" type="prismatic">
    <origin xyz="0.0025 0.0 0.114" rpy="0.0 0.0 0.0"/>
    <axis xyz="1.0 0.0 0.0"/>
    <parent link="kitchen_island"/>
    <child link="kitchen_island_middle_upper_drawer_main"/>
    <limit effort="300.0" lower="0.0" upper="0.48" velocity="10.0"/>
  </joint>
  <joint name="kitchen_island_middle_upper_drawer_handle_joint" type="fixed">
    <origin xyz="0.3325 0.0 0.11" rpy="0.0 0.0 0.0"/>
    <axis xyz="0.0 0.0 1.0"/>
    <parent link="kitchen_island_middle_upper_drawer_main"/>
    <child link="kitchen_island_middle_upper_drawer_handle"/>
    <limit effort="300.0" lower="0.0" upper="1.57079632679" velocity="10.0"/>
  </joint>
  <link name="kitchen_island_middle_lower_drawer_main">
    <inertial>
      <origin xyz="0.0 0.0 0.0" rpy="0.0 0.0 0.0"/>
      <mass value="1.0"/>
      <inertia ixx="1.0" ixy="0.0" ixz="0.0" iyy="1.0" iyz="0.0" izz="1.0"/>
    </inertial>
    <visual>
      <origin xyz="0.0 0.0 0.0" rpy="0.0 0.0 0.0"/>
      <geometry>
        <mesh filename="package://iai_kitchen/meshes/drawers/Drawer_100_29.obj"/>
      </geometry>
    </visual>
    <collision>
      <origin xyz="0.0 0.0 0.0" rpy="0.0 0.0 0.0"/>
      <geometry>
        <mesh filename="package://iai_kitchen/meshes/drawers/Drawer_100_29.obj"/>
      </geometry>
    </collision>
  </link>
  <link name="kitchen_island_middle_lower_drawer_handle">
    <inertial>
      <origin xyz="0.0 0.0 0.0" rpy="0.0 0.0 0.0"/>
      <mass value="1.0"/>
      <inertia ixx="1.0" ixy="0.0" ixz="0.0" iyy="1.0" iyz="0.0" izz="1.0"/>
    </inertial>
    <visual>
      <origin xyz="0.0 0.0 0.0" rpy="0.0 0.0 0.0"/>
      <geometry>
        <mesh filename="package://iai_kitchen/meshes/handles/Handle100.obj"/>
      </geometry>
    </visual>
    <collision>
      <origin xyz="0.0 0.0 0.0" rpy="0.0 0.0 0.0"/>
      <geometry>
        <mesh filename="package://iai_kitchen/meshes/handles/Handle100.obj"/>
      </geometry>
    </collision>
  </link>
  <joint name="kitchen_island_middle_lower_drawer_main_joint" type="prismatic">
    <origin xyz="0.0025 0.0 -0.176" rpy="0.0 0.0 0.0"/>
    <axis xyz="1.0 0.0 0.0"/>
    <parent link="kitchen_island"/>
    <child link="kitchen_island_middle_lower_drawer_main"/>
    <limit effort="300.0" lower="0.0" upper="0.48" velocity="10.0"/>
  </joint>
  <joint name="kitchen_island_middle_lower_drawer_handle_joint" type="fixed">
    <origin xyz="0.3325 0.0 0.11" rpy="0.0 0.0 0.0"/>
    <axis xyz="0.0 0.0 1.0"/>
    <parent link="kitchen_island_middle_lower_drawer_main"/>
    <child link="kitchen_island_middle_lower_drawer_handle"/>
    <limit effort="300.0" lower="0.0" upper="1.57079632679" velocity="10.0"/>
  </joint>
  <link name="kitchen_island_right_panel">
    <inertial>
      <origin xyz="0.0 0.0 0.0" rpy="0.0 0.0 0.0"/>
      <mass value="1.0"/>
      <inertia ixx="1.0" ixy="0.0" ixz="0.0" iyy="1.0" iyz="0.0" izz="1.0"/>
    </inertial>
    <visual>
      <origin xyz="0.0 0.0 0.0" rpy="0.0 0.0 0.0"/>
      <geometry>
        <mesh filename="package://iai_kitchen/meshes/drawers/Panel_60.obj"/>
      </geometry>
    </visual>
    <collision>
      <origin xyz="0.0 0.0 0.0" rpy="0.0 0.0 0.0"/>
      <geometry>
        <mesh filename="package://iai_kitchen/meshes/drawers/Panel_60.obj"/>
      </geometry>
    </collision>
  </link>
  <joint name="kitchen_island_right_panel_joint" type="fixed">
    <origin xyz="0.2725 0.8 0.329" rpy="0.0 0.0 0.0"/>
    <parent link="kitchen_island"/>
    <child link="kitchen_island_right_panel"/>
  </joint>
  <link name="kitchen_island_right_upper_drawer_main">
    <inertial>
      <origin xyz="0.0 0.0 0.0" rpy="0.0 0.0 0.0"/>
      <mass value="1.0"/>
      <inertia ixx="1.0" ixy="0.0" ixz="0.0" iyy="1.0" iyz="0.0" izz="1.0"/>
    </inertial>
    <visual>
      <origin xyz="0.0 0.0 0.0" rpy="0.0 0.0 0.0"/>
      <geometry>
        <mesh filename="package://iai_kitchen/meshes/drawers/Drawer_60_29.obj"/>
      </geometry>
    </visual>
    <collision>
      <origin xyz="0.0 0.0 0.0" rpy="0.0 0.0 0.0"/>
      <geometry>
        <mesh filename="package://iai_kitchen/meshes/drawers/Drawer_60_29.obj"/>
      </geometry>
    </collision>
  </link>
  <link name="kitchen_island_right_upper_drawer_handle">
    <inertial>
      <origin xyz="0.0 0.0 0.0" rpy="0.0 0.0 0.0"/>
      <mass value="1.0"/>
      <inertia ixx="1.0" ixy="0.0" ixz="0.0" iyy="1.0" iyz="0.0" izz="1.0"/>
    </inertial>
    <visual>
      <origin xyz="0.0 0.0 0.0" rpy="0.0 0.0 0.0"/>
      <geometry>
        <mesh filename="package://iai_kitchen/meshes/handles/Handle60.obj"/>
      </geometry>
    </visual>
    <collision>
      <origin xyz="0.0 0.0 0.0" rpy="0.0 0.0 0.0"/>
      <geometry>
        <mesh filename="package://iai_kitchen/meshes/handles/Handle60.obj"/>
      </geometry>
    </collision>
  </link>
  <joint name="kitchen_island_right_upper_drawer_main_joint" type="prismatic">
    <origin xyz="0.0025 0.8 0.114" rpy="0.0 0.0 0.0"/>
    <axis xyz="1.0 0.0 0.0"/>
    <parent link="kitchen_island"/>
    <child link="kitchen_island_right_upper_drawer_main"/>
    <limit effort="300.0" lower="0.0" upper="0.48" velocity="10.0"/>
  </joint>
  <joint name="kitchen_island_right_upper_drawer_handle_joint" type="fixed">
    <origin xyz="0.3325 0.0 0.11" rpy="0.0 0.0 0.0"/>
    <axis xyz="0.0 0.0 1.0"/>
    <parent link="kitchen_island_right_upper_drawer_main"/>
    <child link="kitchen_island_right_upper_drawer_handle"/>
    <limit effort="300.0" lower="0.0" upper="1.57079632679" velocity="10.0"/>
  </joint>
  <link name="kitchen_island_right_lower_drawer_main">
    <inertial>
      <origin xyz="0.0 0.0 0.0" rpy="0.0 0.0 0.0"/>
      <mass value="1.0"/>
      <inertia ixx="1.0" ixy="0.0" ixz="0.0" iyy="1.0" iyz="0.0" izz="1.0"/>
    </inertial>
    <visual>
      <origin xyz="0.0 0.0 0.0" rpy="0.0 0.0 0.0"/>
      <geometry>
        <mesh filename="package://iai_kitchen/meshes/drawers/Drawer_60_29.obj"/>
      </geometry>
    </visual>
    <collision>
      <origin xyz="0.0 0.0 0.0" rpy="0.0 0.0 0.0"/>
      <geometry>
        <mesh filename="package://iai_kitchen/meshes/drawers/Drawer_60_29.obj"/>
      </geometry>
    </collision>
  </link>
  <link name="kitchen_island_right_lower_drawer_handle">
    <inertial>
      <origin xyz="0.0 0.0 0.0" rpy="0.0 0.0 0.0"/>
      <mass value="1.0"/>
      <inertia ixx="1.0" ixy="0.0" ixz="0.0" iyy="1.0" iyz="0.0" izz="1.0"/>
    </inertial>
    <visual>
      <origin xyz="0.0 0.0 0.0" rpy="0.0 0.0 0.0"/>
      <geometry>
        <mesh filename="package://iai_kitchen/meshes/handles/Handle60.obj"/>
      </geometry>
    </visual>
    <collision>
      <origin xyz="0.0 0.0 0.0" rpy="0.0 0.0 0.0"/>
      <geometry>
        <mesh filename="package://iai_kitchen/meshes/handles/Handle60.obj"/>
      </geometry>
    </collision>
  </link>
  <joint name="kitchen_island_right_lower_drawer_main_joint" type="prismatic">
    <origin xyz="0.0025 0.8 -0.176" rpy="0.0 0.0 0.0"/>
    <axis xyz="1.0 0.0 0.0"/>
    <parent link="kitchen_island"/>
    <child link="kitchen_island_right_lower_drawer_main"/>
    <limit effort="300.0" lower="0.0" upper="0.48" velocity="10.0"/>
  </joint>
  <joint name="kitchen_island_right_lower_drawer_handle_joint" type="fixed">
    <origin xyz="0.3325 0.0 0.11" rpy="0.0 0.0 0.0"/>
    <axis xyz="0.0 0.0 1.0"/>
    <parent link="kitchen_island_right_lower_drawer_main"/>
    <child link="kitchen_island_right_lower_drawer_handle"/>
    <limit effort="300.0" lower="0.0" upper="1.57079632679" velocity="10.0"/>
  </joint>
  <link name="fridge_area_footprint">
    <inertial>
      <origin xyz="0.0 0.0 0.0" rpy="0.0 0.0 0.0"/>
      <mass value="1.0"/>
      <inertia ixx="1.0" ixy="0.0" ixz="0.0" iyy="1.0" iyz="0.0" izz="1.0"/>
    </inertial>
  </link>
  <link name="fridge_area">
    <inertial>
      <origin xyz="0.0 0.0 0.0" rpy="0.0 0.0 0.0"/>
      <mass value="1.0"/>
      <inertia ixx="1.0" ixy="0.0" ixz="0.0" iyy="1.0" iyz="0.0" izz="1.0"/>
    </inertial>
    <visual>
      <origin xyz="0.0 0.0 0.01" rpy="0.0 0.0 0.0"/>
      <geometry>
        <mesh filename="package://iai_kitchen/meshes/racks/FridgeArea.obj"/>
      </geometry>
    </visual>
    <collision>
      <origin xyz="0.0 0.0 0.01" rpy="0.0 0.0 0.0"/>
      <geometry>
        <mesh filename="package://iai_kitchen/meshes/racks/FridgeArea.obj"/>
      </geometry>
    </collision>
  </link>
  <joint name="fridge_area_footprint_joint" type="fixed">
    <origin xyz="1.825 -0.74 0.0" rpy="0.0 0.0 3.14159265359"/>
    <parent link="kitchen_main"/>
    <child link="fridge_area_footprint"/>
  </joint>
  <joint name="fridge_area_main_joint" type="fixed">
    <origin xyz="0.29 0.3 0.74" rpy="0.0 0.0 0.0"/>
    <parent link="fridge_area_footprint"/>
    <child link="fridge_area"/>
  </joint>
  <link name="fridge_area_lower_drawer_main">
    <inertial>
      <origin xyz="0.0 0.0 0.0" rpy="0.0 0.0 0.0"/>
      <mass value="1.0"/>
      <inertia ixx="1.0" ixy="0.0" ixz="0.0" iyy="1.0" iyz="0.0" izz="1.0"/>
    </inertial>
    <visual>
      <origin xyz="0.0 0.0 0.0" rpy="0.0 0.0 0.0"/>
      <geometry>
        <mesh filename="package://iai_kitchen/meshes/drawers/Drawer_60_29.obj"/>
      </geometry>
    </visual>
    <collision>
      <origin xyz="0.0 0.0 0.0" rpy="0.0 0.0 0.0"/>
      <geometry>
        <mesh filename="package://iai_kitchen/meshes/drawers/Drawer_60_29.obj"/>
      </geometry>
    </collision>
  </link>
  <link name="fridge_area_lower_drawer_handle">
    <inertial>
      <origin xyz="0.0 0.0 0.0" rpy="0.0 0.0 0.0"/>
      <mass value="1.0"/>
      <inertia ixx="1.0" ixy="0.0" ixz="0.0" iyy="1.0" iyz="0.0" izz="1.0"/>
    </inertial>
    <visual>
      <origin xyz="0.0 0.0 0.0" rpy="0.0 0.0 0.0"/>
      <geometry>
        <mesh filename="package://iai_kitchen/meshes/handles/Handle60.obj"/>
      </geometry>
    </visual>
    <collision>
      <origin xyz="0.0 0.0 0.0" rpy="0.0 0.0 0.0"/>
      <geometry>
        <mesh filename="package://iai_kitchen/meshes/handles/Handle60.obj"/>
      </geometry>
    </collision>
  </link>
  <joint name="fridge_area_lower_drawer_main_joint" type="prismatic">
    <origin xyz="0.0 -0.0 -0.4175" rpy="0.0 0.0 0.0"/>
    <axis xyz="1.0 0.0 0.0"/>
    <parent link="fridge_area"/>
    <child link="fridge_area_lower_drawer_main"/>
    <limit effort="300.0" lower="0.0" upper="0.48" velocity="10.0"/>
  </joint>
  <joint name="fridge_area_lower_drawer_handle_joint" type="fixed">
    <origin xyz="0.3325 0.0 0.11" rpy="0.0 0.0 0.0"/>
    <axis xyz="0.0 0.0 1.0"/>
    <parent link="fridge_area_lower_drawer_main"/>
    <child link="fridge_area_lower_drawer_handle"/>
    <limit effort="300.0" lower="0.0" upper="1.57079632679" velocity="10.0"/>
  </joint>
  <link name="iai_fridge_main">
    <inertial>
      <origin xyz="0.0 0.0 0.0" rpy="0.0 0.0 0.0"/>
      <mass value="1.0"/>
      <inertia ixx="1.0" ixy="0.0" ixz="0.0" iyy="1.0" iyz="0.0" izz="1.0"/>
    </inertial>
    <visual>
      <origin xyz="0.0 0.0 0.0" rpy="0.0 0.0 0.0"/>
      <geometry>
        <mesh filename="package://iai_kitchen/meshes/misc/Fridge.obj"/>
      </geometry>
    </visual>
    <collision>
      <origin xyz="0.0 0.0 0.0" rpy="0.0 0.0 0.0"/>
      <geometry>
        <mesh filename="package://iai_kitchen/meshes/misc/Fridge.obj"/>
      </geometry>
    </collision>
  </link>
  <link name="iai_fridge_door">
    <inertial>
      <origin xyz="0.0 0.0 0.0" rpy="0.0 0.0 0.0"/>
      <mass value="1.0"/>
      <inertia ixx="1.0" ixy="0.0" ixz="0.0" iyy="1.0" iyz="0.0" izz="1.0"/>
    </inertial>
    <visual>
      <origin xyz="0.0 0.0 0.0" rpy="0.0 0.0 0.0"/>
      <geometry>
        <mesh filename="package://iai_kitchen/meshes/misc/FridgeDoor.obj"/>
      </geometry>
    </visual>
    <collision>
      <origin xyz="0.0 0.0 0.0" rpy="0.0 0.0 0.0"/>
      <geometry>
        <mesh filename="package://iai_kitchen/meshes/misc/FridgeDoor.obj"/>
      </geometry>
    </collision>
  </link>
  <link name="iai_fridge_door_handle">
    <inertial>
      <origin xyz="0.0 0.0 0.0" rpy="0.0 0.0 0.0"/>
      <mass value="1.0"/>
      <inertia ixx="1.0" ixy="0.0" ixz="0.0" iyy="1.0" iyz="0.0" izz="1.0"/>
    </inertial>
    <visual>
      <origin xyz="0.0 0.0 0.0" rpy="0.0 0.0 0.0"/>
      <geometry>
        <mesh filename="package://iai_kitchen/meshes/handles/VHandle90.obj"/>
      </geometry>
    </visual>
    <collision>
      <origin xyz="0.0 0.0 0.0" rpy="0.0 0.0 0.0"/>
      <geometry>
        <mesh filename="package://iai_kitchen/meshes/handles/VHandle90.obj"/>
      </geometry>
    </collision>
  </link>
  <joint name="iai_fridge_main_joint" type="fixed">
    <origin xyz="0.0 0.0 0.0" rpy="0.0 0.0 0.0"/>
    <parent link="fridge_area"/>
    <child link="iai_fridge_main"/>
  </joint>
  <joint name="iai_fridge_door_joint" type="revolute">
    <origin xyz="0.29 0.3 0.245" rpy="0.0 0.0 0.0"/>
    <axis xyz="0.0 0.0 1.0"/>
    <parent link="iai_fridge_main"/>
    <child link="iai_fridge_door"/>
    <limit effort="300.0" lower="0.0" upper="1.57079632679" velocity="10.0"/>
  </joint>
  <joint name="iai_fridge_door_handle_joint" type="fixed">
    <origin xyz="0.06 -0.57 0.0" rpy="0.0 0.0 0.0"/>
    <parent link="iai_fridge_door"/>
    <child link="iai_fridge_door_handle"/>
  </joint>
  <link name="kitchen_wall_1">
    <inertial>
      <origin xyz="0.0 0.0 0.0" rpy="0.0 0.0 0.0"/>
      <mass value="1.0"/>
      <inertia ixx="1.0" ixy="0.0" ixz="0.0" iyy="1.0" iyz="0.0" izz="1.0"/>
    </inertial>
    <visual>
      <origin xyz="0.0 0.0 1.25" rpy="0.0 0.0 0.0"/>
      <geometry>
        <box size="4.9 0.15 2.5"/>
      </geometry>
    </visual>
    <collision>
      <origin xyz="0.0 0.0 1.25" rpy="0.0 0.0 0.0"/>
      <geometry>
        <box size="4.9 0.15 2.5"/>
      </geometry>
    </collision>
  </link>
  <link name="kitchen_wall_2">
    <inertial>
      <origin xyz="0.0 0.0 0.0" rpy="0.0 0.0 0.0"/>
      <mass value="1.0"/>
      <inertia ixx="1.0" ixy="0.0" ixz="0.0" iyy="1.0" iyz="0.0" izz="1.0"/>
    </inertial>
    <visual>
      <origin xyz="0.0 0.0 1.25" rpy="0.0 0.0 0.0"/>
      <geometry>
        <box size="5.901 0.15 2.5"/>
      </geometry>
    </visual>
    <collision>
      <origin xyz="0.0 0.0 1.25" rpy="0.0 0.0 0.0"/>
      <geometry>
        <box size="5.901 0.15 2.5"/>
      </geometry>
    </collision>
  </link>
  <link name="kitchen_walls"/>
  <joint name="walls_main_joint" type="fixed">
    <origin xyz="-1.0 0.562175 0.0" rpy="0.0 0.0 0.0"/>
    <parent link="kitchen_main"/>
    <child link="kitchen_walls"/>
  </joint>
  <joint name="wall_1_joint" type="fixed">
    <origin xyz="2.87551 0.0 0.0" rpy="0.0 -0.0 1.5708"/>
    <parent link="kitchen_walls"/>
    <child link="kitchen_wall_1"/>
  </joint>
  <joint name="wall_2_joint" type="fixed">
    <origin xyz="0.0 2.516 0.0" rpy="0.0 -0.0 3.14159"/>
    <parent link="kitchen_walls"/>
    <child link="kitchen_wall_2"/>
  </joint>
  <link name="urdf_main"/>
  <joint name="map_urdf_joint" type="fixed">
    <origin xyz="0.0 0.0 0.0" rpy="0.0 0.0 0.0"/>
    <parent link="urdf_main"/>
    <child link="urdf_offset"/>
  </joint>
  <link name="urdf_offset"/>
</robot>