<?xml version="1.0" ?>
<robot name="iai-kitchen" version="1.0">
  <material name="table_grey">
    <color rgba="0.255 0.62 0.223 1.0"/>
  </material>
  <material name="round_table_grey">
    <color rgba="0.8 0.8 0.8 1.0"/>
  </material>
  <material name="wall_pink">
    <color rgba="0.95 0.43 0.96 1.0"/>
  </material>
  <material name="shelf_blue">
    <color rgba="0.59 0.88 0.9 1.0"/>
  </material>
  <material name="shelf_door_green">
    <color rgba="0.64 0.87 0.82 1.0"/>
  </material>
  <material name="shelf_openable_handle_red">
    <color rgba="0.74 0.25 0.25 1.0"/>
  </material>
  <material name="shelf_hohc_handle_red">
    <color rgba="0.74 0.25 0.25 1.0"/>
  </material>
  <material name="door_green">
    <color rgba="0.0 0.31 0.22 1.0"/>
  </material>
  <material name="hinge_red">
    <color rgba="0.74 0.25 0.25 1.0"/>
  </material>
  <material name="handle_blue">
    <color rgba="0.3 0.5 0.78 1.0"/>
  </material>
  <material name="bucket_grey">
    <color rgba="0.8 0.8 0.8 1.0"/>
  </material>
  <material name="white">
    <color rgba="1.0 1.0 1.0 1.0"/>
  </material>
  <material name="orange">
    <color rgba="1.0 0.7 0.0 1.0"/>
  </material>
  <material name="handle_white">
    <color rgba="1.0 1.0 1.0 1.0"/>
  </material>
  <material name="bottom_white">
    <color rgba="1.0 1.0 1.0 1.0"/>
  </material>
  <material name="frame_wood">
    <color rgba="0.68 0.63 0.47 1.0"/>
  </material>
  <material name="handle_grey">
    <color rgba="0.7 0.7 0.7 1.0"/>
  </material>
  <material name="dishwasher_table_color">
    <color rgba="0.255 0.62 0.223 1.0"/>
  </material>
  <material name="color_grey">
    <color rgba="0.8 0.8 0.8 1.0"/>
  </material>
  <material name="color_red">
    <color rgba="1.0 0.0 0.0 1.0"/>
  </material>
  <material name="color_blue">
    <color rgba="0.0 0.0 1.0 1.0"/>
  </material>
  <material name="simple_couch_color_grey">
    <color rgba="0.8 0.8 0.8 1.0"/>
  </material>
  <material name="simple_couch_color_red">
    <color rgba="1.0 0.0 0.0 1.0"/>
  </material>
  <material name="simple_couch_color_blue">
    <color rgba="0.0 0.0 1.0 1.0"/>
  </material>
  <material name="chair_color">
    <color rgba="0.0 0.0 0.5 1.0"/>
  </material>
  <link name="long_table:l_table:table_center">
    <visual>
      <origin xyz="0.0 0.0 -0.3675" rpy="0.0 0.0 0.0"/>
      <geometry>
        <box size="0.73 1.17 0.735"/>
      </geometry>
      <material name="table_grey"/>
    </visual>
    <collision>
      <origin xyz="0.0 0.0 -0.3675" rpy="0.0 0.0 0.0"/>
      <geometry>
        <box size="0.73 1.17 0.735"/>
      </geometry>
    </collision>
  </link>
  <link name="long_table:l_table:table_origin"/>
  <link name="long_table:l_table:table_front_edge_center"/>
  <joint name="long_table:l_table:table_origin_joint" type="fixed">
    <origin xyz="1.01 2.13 0.0" rpy="0.0 0.0 3.15"/>
    <parent link="urdf_offset"/>
    <child link="long_table:l_table:table_origin"/>
  </joint>
  <joint name="long_table:l_table:center_joint" type="fixed">
    <origin xyz="0.365 0.585 0.735" rpy="0.0 0.0 0.0"/>
    <parent link="long_table:l_table:table_origin"/>
    <child link="long_table:l_table:table_center"/>
  </joint>
  <joint name="long_table:l_table:table_front_edge_center_joint" type="fixed">
    <origin xyz="0.0 0.585 0.735" rpy="0.0 0.0 0.0"/>
    <parent link="long_table:l_table:table_origin"/>
    <child link="long_table:l_table:table_front_edge_center"/>
  </joint>
  <link name="couch_table:couch_table:table_center">
    <visual>
      <origin xyz="0.0 0.0 -0.2165" rpy="0.0 0.0 0.0"/>
      <geometry>
        <box size="0.37 0.909 0.433"/>
      </geometry>
      <material name="table_grey"/>
    </visual>
    <collision>
      <origin xyz="0.0 0.0 -0.2165" rpy="0.0 0.0 0.0"/>
      <geometry>
        <box size="0.37 0.909 0.433"/>
      </geometry>
    </collision>
  </link>
  <link name="couch_table:couch_table:table_origin"/>
  <link name="couch_table:couch_table:table_front_edge_center"/>
  <joint name="couch_table:couch_table:table_origin_joint" type="fixed">
    <origin xyz="4.83 1.99 0.0" rpy="0.0 0.0 0.0"/>
    <parent link="urdf_offset"/>
    <child link="couch_table:couch_table:table_origin"/>
  </joint>
  <joint name="couch_table:couch_table:center_joint" type="fixed">
    <origin xyz="0.185 0.4545 0.433" rpy="0.0 0.0 0.0"/>
    <parent link="couch_table:couch_table:table_origin"/>
    <child link="couch_table:couch_table:table_center"/>
  </joint>
  <joint name="couch_table:couch_table:table_front_edge_center_joint" type="fixed">
    <origin xyz="0.0 0.4545 0.433" rpy="0.0 0.0 0.0"/>
    <parent link="couch_table:couch_table:table_origin"/>
    <child link="couch_table:couch_table:table_front_edge_center"/>
  </joint>
  <link name="kitchen_island:kitchen_island:table_center">
    <visual>
      <origin xyz="0.0 0.0 -0.4265" rpy="0.0 0.0 0.0"/>
      <geometry>
        <box size="0.796 -2.47 0.853"/>
      </geometry>
      <material name="table_grey"/>
    </visual>
    <collision>
      <origin xyz="0.0 0.0 -0.4265" rpy="0.0 0.0 0.0"/>
      <geometry>
        <box size="0.796 -2.47 0.853"/>
      </geometry>
    </collision>
  </link>
  <link name="kitchen_island:kitchen_island:table_origin"/>
  <link name="kitchen_island:kitchen_island:table_front_edge_center"/>
  <joint name="kitchen_island:kitchen_island:table_origin_joint" type="fixed">
    <origin xyz="3.0 0.134 0.0" rpy="0.0 0.0 1.57"/>
    <parent link="urdf_offset"/>
    <child link="kitchen_island:kitchen_island:table_origin"/>
  </joint>
  <joint name="kitchen_island:kitchen_island:center_joint" type="fixed">
    <origin xyz="0.398 -1.235 0.853" rpy="0.0 0.0 0.0"/>
    <parent link="kitchen_island:kitchen_island:table_origin"/>
    <child link="kitchen_island:kitchen_island:table_center"/>
  </joint>
  <joint name="kitchen_island:kitchen_island:table_front_edge_center_joint" type="fixed">
    <origin xyz="0.0 -1.235 0.853" rpy="0.0 0.0 0.0"/>
    <parent link="kitchen_island:kitchen_island:table_origin"/>
    <child link="kitchen_island:kitchen_island:table_front_edge_center"/>
  </joint>
  <link name="oven_area:oven_area:table_center">
    <visual>
      <origin xyz="0.0 0.0 -0.755" rpy="0.0 0.0 0.0"/>
      <geometry>
        <box size="0.68 1.2 1.51"/>
      </geometry>
      <material name="table_grey"/>
    </visual>
    <collision>
      <origin xyz="0.0 0.0 -0.755" rpy="0.0 0.0 0.0"/>
      <geometry>
        <box size="0.68 1.2 1.51"/>
      </geometry>
    </collision>
  </link>
  <link name="oven_area:oven_area:table_origin"/>
  <link name="oven_area:oven_area:table_front_edge_center"/>
  <joint name="oven_area:oven_area:table_origin_joint" type="fixed">
    <origin xyz="3.77 -1.8 0.0" rpy="0.0 0.0 4.72"/>
    <parent link="urdf_offset"/>
    <child link="oven_area:oven_area:table_origin"/>
  </joint>
  <joint name="oven_area:oven_area:center_joint" type="fixed">
    <origin xyz="0.34 0.6 1.51" rpy="0.0 0.0 0.0"/>
    <parent link="oven_area:oven_area:table_origin"/>
    <child link="oven_area:oven_area:table_center"/>
  </joint>
  <joint name="oven_area:oven_area:table_front_edge_center_joint" type="fixed">
    <origin xyz="0.0 0.6 1.51" rpy="0.0 0.0 0.0"/>
    <parent link="oven_area:oven_area:table_origin"/>
    <child link="oven_area:oven_area:table_front_edge_center"/>
  </joint>
  <link name="work_surface_left:work_surface_left:table_center">
    <visual>
      <origin xyz="0.0 0.0 -0.42" rpy="0.0 0.0 0.0"/>
      <geometry>
        <box size="0.68 0.82 0.84"/>
      </geometry>
      <material name="table_grey"/>
    </visual>
    <collision>
      <origin xyz="0.0 0.0 -0.42" rpy="0.0 0.0 0.0"/>
      <geometry>
        <box size="0.68 0.82 0.84"/>
      </geometry>
    </collision>
  </link>
  <link name="work_surface_left:work_surface_left:table_origin"/>
  <link name="work_surface_left:work_surface_left:table_front_edge_center"/>
  <joint name="work_surface_left:work_surface_left:table_origin_joint" type="fixed">
    <origin xyz="2.94 -1.84 0.0" rpy="0.0 0.0 4.72"/>
    <parent link="urdf_offset"/>
    <child link="work_surface_left:work_surface_left:table_origin"/>
  </joint>
  <joint name="work_surface_left:work_surface_left:center_joint" type="fixed">
    <origin xyz="0.34 0.41 0.84" rpy="0.0 0.0 0.0"/>
    <parent link="work_surface_left:work_surface_left:table_origin"/>
    <child link="work_surface_left:work_surface_left:table_center"/>
  </joint>
  <joint name="work_surface_left:work_surface_left:table_front_edge_center_joint" type="fixed">
    <origin xyz="0.0 0.41 0.84" rpy="0.0 0.0 0.0"/>
    <parent link="work_surface_left:work_surface_left:table_origin"/>
    <child link="work_surface_left:work_surface_left:table_front_edge_center"/>
  </joint>
  <link name="work_surface_right:work_surface_right:table_center">
    <visual>
      <origin xyz="0.0 0.0 -0.42" rpy="0.0 0.0 0.0"/>
      <geometry>
        <box size="0.68 0.64 0.84"/>
      </geometry>
      <material name="table_grey"/>
    </visual>
    <collision>
      <origin xyz="0.0 0.0 -0.42" rpy="0.0 0.0 0.0"/>
      <geometry>
        <box size="0.68 0.64 0.84"/>
      </geometry>
    </collision>
  </link>
  <link name="work_surface_right:work_surface_right:table_origin"/>
  <link name="work_surface_right:work_surface_right:table_front_edge_center"/>
  <joint name="work_surface_right:work_surface_right:table_origin_joint" type="fixed">
    <origin xyz="1.705 -1.84 0.0" rpy="0.0 0.0 4.72"/>
    <parent link="urdf_offset"/>
    <child link="work_surface_right:work_surface_right:table_origin"/>
  </joint>
  <joint name="work_surface_right:work_surface_right:center_joint" type="fixed">
    <origin xyz="0.34 0.32 0.84" rpy="0.0 0.0 0.0"/>
    <parent link="work_surface_right:work_surface_right:table_origin"/>
    <child link="work_surface_right:work_surface_right:table_center"/>
  </joint>
  <joint name="work_surface_right:work_surface_right:table_front_edge_center_joint" type="fixed">
    <origin xyz="0.0 0.32 0.84" rpy="0.0 0.0 0.0"/>
    <parent link="work_surface_right:work_surface_right:table_origin"/>
    <child link="work_surface_right:work_surface_right:table_front_edge_center"/>
  </joint>
  <link name="refrigerator:refrigerator:table_center">
    <visual>
      <origin xyz="0.0 0.0 -0.755" rpy="0.0 0.0 0.0"/>
      <geometry>
        <box size="0.68 0.595 1.51"/>
      </geometry>
      <material name="table_grey"/>
    </visual>
    <collision>
      <origin xyz="0.0 0.0 -0.755" rpy="0.0 0.0 0.0"/>
      <geometry>
        <box size="0.68 0.595 1.51"/>
      </geometry>
    </collision>
  </link>
  <link name="refrigerator:refrigerator:table_origin"/>
  <link name="refrigerator:refrigerator:table_front_edge_center"/>
  <joint name="refrigerator:refrigerator:table_origin_joint" type="fixed">
    <origin xyz="1.11 -1.84 0.0" rpy="0.0 0.0 4.72"/>
    <parent link="urdf_offset"/>
    <child link="refrigerator:refrigerator:table_origin"/>
  </joint>
  <joint name="refrigerator:refrigerator:center_joint" type="fixed">
    <origin xyz="0.34 0.2975 1.51" rpy="0.0 0.0 0.0"/>
    <parent link="refrigerator:refrigerator:table_origin"/>
    <child link="refrigerator:refrigerator:table_center"/>
  </joint>
  <joint name="refrigerator:refrigerator:table_front_edge_center_joint" type="fixed">
    <origin xyz="0.0 0.2975 1.51" rpy="0.0 0.0 0.0"/>
    <parent link="refrigerator:refrigerator:table_origin"/>
    <child link="refrigerator:refrigerator:table_front_edge_center"/>
  </joint>
  <link name="suturo_couch:couch:place1">
    <visual>
      <origin xyz="0.0 0.0 0.15" rpy="0.0 0.0 0.0"/>
      <geometry>
        <box size="1.0 1.7 0.3"/>
      </geometry>
      <material name="color_grey"/>
    </visual>
    <collision>
      <origin xyz="0.0 0.0 0.0" rpy="0.0 0.0 0.0"/>
      <geometry>
        <box size="1.0 1.7 0.3"/>
      </geometry>
    </collision>
  </link>
  <link name="suturo_couch:couch:place2">
    <visual>
      <origin xyz="0.0 -0.425 0.15" rpy="0.0 0.0 0.0"/>
      <geometry>
        <box size="1.0 0.85 0.3"/>
      </geometry>
      <material name="color_red"/>
    </visual>
    <collision>
      <origin xyz="0.0 0.0 0.0" rpy="0.0 0.0 0.0"/>
      <geometry>
        <box size="1.0 1.7 0.3"/>
      </geometry>
    </collision>
  </link>
  <link name="suturo_couch:couch:place3">
    <visual>
      <origin xyz="0.0 0.425 0.15" rpy="0.0 0.0 0.0"/>
      <geometry>
        <box size="1.0 0.85 0.3"/>
      </geometry>
      <material name="color_blue"/>
    </visual>
    <collision>
      <origin xyz="0.0 0.0 -0.15" rpy="0.0 0.0 0.0"/>
      <geometry>
        <box size="1.0 1.7 0.3"/>
      </geometry>
    </collision>
  </link>
  <joint name="suturo_couch:couch:couch_origin_joint" type="fixed">
    <origin xyz="4.2 1.19 0.0" rpy="0.0 0.0 1.57"/>
    <parent link="urdf_offset"/>
    <child link="suturo_couch:couch:place1"/>
  </joint>
  <joint name="suturo_couch:couch:couch_left_joint" type="fixed">
    <origin xyz="0.0 0.0 0.0" rpy="0.0 0.0 0.0"/>
    <parent link="suturo_couch:couch:place1"/>
    <child link="suturo_couch:couch:place2"/>
  </joint>
  <joint name="suturo_couch:couch:couch_right_joint" type="fixed">
    <origin xyz="0.0 0.0 0.0" rpy="0.0 0.0 0.0"/>
    <parent link="suturo_couch:couch:place1"/>
    <child link="suturo_couch:couch:place3"/>
  </joint>
  <link name="shelf:shelf:shelf_origin"/>
  <link name="shelf:shelf:shelf_center"/>
  <link name="shelf:shelf:shelf_base_center"/>
  <joint name="shelf:shelf:shelf_origin_joint" type="fixed">
    <origin xyz="5.11 4.42 0.0" rpy="0.0 0.0 0.0"/>
    <parent link="urdf_offset"/>
    <child link="shelf:shelf:shelf_origin"/>
  </joint>
  <joint name="shelf:shelf:shelf_center_joint" type="fixed">
    <origin xyz="0.17 0.52 0.6775" rpy="0.0 0.0 0.0"/>
    <parent link="shelf:shelf:shelf_origin"/>
    <child link="shelf:shelf:shelf_center"/>
  </joint>
  <joint name="shelf:shelf:shelf_base_center_joint" type="fixed">
    <origin xyz="0.17 0.52 0.0" rpy="0.0 0.0 0.0"/>
    <parent link="shelf:shelf:shelf_origin"/>
    <child link="shelf:shelf:shelf_base_center"/>
  </joint>
  <link name="shelf:shelf:shelf_back">
    <visual>
      <origin xyz="0.0 0.0 0.0" rpy="0.0 0.0 0.0"/>
      <geometry>
        <box size="0.01 1.04 1.355"/>
      </geometry>
      <material name="shelf_blue"/>
    </visual>
    <collision>
      <origin xyz="0.0 0.0 0.0" rpy="0.0 0.0 0.0"/>
      <geometry>
        <box size="0.01 1.04 1.355"/>
      </geometry>
    </collision>
  </link>
  <joint name="shelf:shelf:shelf_back:joint" type="fixed">
    <origin xyz="0.34 0.52 0.6775" rpy="0.0 0.0 0.0"/>
    <parent link="shelf:shelf:shelf_origin"/>
    <child link="shelf:shelf:shelf_back"/>
  </joint>
  <link name="shelf:shelf:shelf_right_side">
    <visual>
      <origin xyz="0.0 0.0 0.0" rpy="0.0 0.0 0.0"/>
      <geometry>
        <box size="0.34 0.01 1.355"/>
      </geometry>
      <material name="shelf_blue"/>
    </visual>
    <collision>
      <origin xyz="0.0 0.0 0.0" rpy="0.0 0.0 0.0"/>
      <geometry>
        <box size="0.34 0.01 1.355"/>
      </geometry>
    </collision>
  </link>
  <joint name="shelf:shelf:shelf_right_side:joint" type="fixed">
    <origin xyz="0.17 0.0 0.6775" rpy="0.0 0.0 0.0"/>
    <parent link="shelf:shelf:shelf_origin"/>
    <child link="shelf:shelf:shelf_right_side"/>
  </joint>
  <link name="shelf:shelf:shelf_left_side">
    <visual>
      <origin xyz="0.0 0.0 0.0" rpy="0.0 0.0 0.0"/>
      <geometry>
        <box size="0.34 0.01 1.355"/>
      </geometry>
      <material name="shelf_blue"/>
    </visual>
    <collision>
      <origin xyz="0.0 0.0 0.0" rpy="0.0 0.0 0.0"/>
      <geometry>
        <box size="0.34 0.01 1.355"/>
      </geometry>
    </collision>
  </link>
  <joint name="shelf:shelf:shelf_left_side:joint" type="fixed">
    <origin xyz="0.17 1.04 0.6775" rpy="0.0 0.0 0.0"/>
    <parent link="shelf:shelf:shelf_origin"/>
    <child link="shelf:shelf:shelf_left_side"/>
  </joint>
  <link name="shelf:shelf:shelf_floor_0">
    <visual>
      <origin xyz="0.0 0.0 -0.02" rpy="0.0 0.0 0.0"/>
      <geometry>
        <box size="0.34 1.04 0.04"/>
      </geometry>
      <material name="shelf_blue"/>
    </visual>
    <collision>
      <origin xyz="0.0 0.0 -0.02" rpy="0.0 0.0 0.0"/>
      <geometry>
        <box size="0.34 1.04 0.04"/>
      </geometry>
    </collision>
  </link>
  <joint name="shelf:shelf:shelf_floor_0:joint" type="fixed">
    <origin xyz="0.0 0.0 0.077" rpy="0.0 0.0 0.0"/>
    <parent link="shelf:shelf:shelf_base_center"/>
    <child link="shelf:shelf:shelf_floor_0"/>
  </joint>
  <link name="shelf:shelf:shelf_floor_1">
    <visual>
      <origin xyz="0.0 0.0 -0.02" rpy="0.0 0.0 0.0"/>
      <geometry>
        <box size="0.34 1.04 0.04"/>
      </geometry>
      <material name="shelf_blue"/>
    </visual>
    <collision>
      <origin xyz="0.0 0.0 -0.02" rpy="0.0 0.0 0.0"/>
      <geometry>
        <box size="0.34 1.04 0.04"/>
      </geometry>
    </collision>
  </link>
  <joint name="shelf:shelf:shelf_floor_1:joint" type="fixed">
    <origin xyz="0.0 0.0 0.371" rpy="0.0 0.0 0.0"/>
    <parent link="shelf:shelf:shelf_base_center"/>
    <child link="shelf:shelf:shelf_floor_1"/>
  </joint>
  <link name="shelf:shelf:shelf_floor_2">
    <visual>
      <origin xyz="0.0 0.0 -0.02" rpy="0.0 0.0 0.0"/>
      <geometry>
        <box size="0.34 1.04 0.04"/>
      </geometry>
      <material name="shelf_blue"/>
    </visual>
    <collision>
      <origin xyz="0.0 0.0 -0.02" rpy="0.0 0.0 0.0"/>
      <geometry>
        <box size="0.34 1.04 0.04"/>
      </geometry>
    </collision>
  </link>
  <joint name="shelf:shelf:shelf_floor_2:joint" type="fixed">
    <origin xyz="0.0 0.0 0.716" rpy="0.0 0.0 0.0"/>
    <parent link="shelf:shelf:shelf_base_center"/>
    <child link="shelf:shelf:shelf_floor_2"/>
  </joint>
  <joint name="world_iai_kitchen:kitchen:room_joint" type="fixed">
    <origin xyz="2.825 -1.0 -0.05" rpy="0.0 0.0 0.0"/>
    <parent link="urdf_offset"/>
    <child link="iai_kitchen:kitchen:room_center_link"/>
  </joint>
  <link name="iai_kitchen:kitchen:room_center_link">
    <visual>
      <geometry>
        <box size="5.25 3.0 0.01"/>
      </geometry>
      <material name="iai_kitchen:kitchen:color">
        <color rgba="0.0 0.0 1.0 0.1"/>
      </material>
    </visual>
    <collision>
      <geometry>
        <box size="5.25 3.0 0.01"/>
      </geometry>
    </collision>
  </link>
  <joint name="room_kitchen_entry_exit:entry_exit:connection_joint" type="fixed">
    <origin xyz="-2.225 1.09 0.0" rpy="0.0 0.0 0.0"/>
    <parent link="iai_kitchen:kitchen:room_center_link"/>
    <child link="kitchen_entry_exit:entry_exit:link"/>
  </joint>
  <link name="kitchen_entry_exit:entry_exit:link"/>
  <joint name="world_arena:arena:room_joint" type="fixed">
    <origin xyz="3.0 2.05 -0.05" rpy="0.0 0.0 0.0"/>
    <parent link="urdf_offset"/>
    <child link="arena:arena:room_center_link"/>
  </joint>
  <link name="arena:arena:room_center_link">
    <visual>
      <geometry>
        <box size="5.2 9.1 0.01"/>
      </geometry>
      <material name="arena:arena:color">
        <color rgba="1.0 0.0 0.0 0.0"/>
      </material>
    </visual>
    <collision>
      <geometry>
        <box size="5.2 9.1 0.01"/>
      </geometry>
    </collision>
  </link>
  <joint name="room_arena_entry:entry:connection_joint" type="fixed">
    <origin xyz="-2.33 -2.05 0.0" rpy="0.0 0.0 0.0"/>
    <parent link="arena:arena:room_center_link"/>
    <child link="arena_entry:entry:link"/>
  </joint>
  <link name="arena_entry:entry:link"/>
  <joint name="room_arena_exit:exit:connection_joint" type="fixed">
    <origin xyz="-2.33 1.75 0.0" rpy="0.0 0.0 0.0"/>
    <parent link="arena:arena:room_center_link"/>
    <child link="arena_exit:exit:link"/>
  </joint>
  <link name="arena_exit:exit:link"/>
  <joint name="world_living_room:living_room:room_joint" type="fixed">
    <origin xyz="2.825 2.2 -0.05" rpy="0.0 0.0 0.0"/>
    <parent link="urdf_offset"/>
    <child link="living_room:living_room:room_center_link"/>
  </joint>
  <link name="living_room:living_room:room_center_link">
    <visual>
      <geometry>
        <box size="5.25 3.4 0.01"/>
      </geometry>
      <material name="living_room:living_room:color">
        <color rgba="0.0 1.0 0.0 0.1"/>
      </material>
    </visual>
    <collision>
      <geometry>
        <box size="5.25 3.4 0.01"/>
      </geometry>
    </collision>
  </link>
  <joint name="room_living_room_entry_exit:entry_exit:connection_joint" type="fixed">
    <origin xyz="-2.5650000000000004 1.6099999999999999 0.0" rpy="0.0 0.0 0.0"/>
    <parent link="living_room:living_room:room_center_link"/>
    <child link="living_room_entry_exit:entry_exit:link"/>
  </joint>
  <link name="living_room_entry_exit:entry_exit:link"/>
  <joint name="world_dining_room:dining_room:room_joint" type="fixed">
    <origin xyz="2.825 5.25 -0.05" rpy="0.0 0.0 0.0"/>
    <parent link="urdf_offset"/>
    <child link="dining_room:dining_room:room_center_link"/>
  </joint>
  <link name="dining_room:dining_room:room_center_link">
    <visual>
      <geometry>
        <box size="5.25 2.7 0.01"/>
      </geometry>
      <material name="dining_room:dining_room:color">
        <color rgba="1.0 0.0 0.0 0.1"/>
      </material>
    </visual>
    <collision>
      <geometry>
        <box size="5.25 2.7 0.01"/>
      </geometry>
    </collision>
  </link>
  <joint name="room_dining_room_entry_exit:entry_exit:connection_joint" type="fixed">
    <origin xyz="-0.7250000000000001 -1.35 0.0" rpy="0.0 0.0 0.0"/>
    <parent link="dining_room:dining_room:room_center_link"/>
    <child link="dining_room_entry_exit:entry_exit:link"/>
  </joint>
  <link name="dining_room_entry_exit:entry_exit:link"/>
  <link name="iai_kitchen:arena:door_center">
    <visual>
      <origin xyz="0.4275 0.0 0.0" rpy="0.0 0.0 0.0"/>
      <geometry>
        <box size="0.855 0.04 2.0"/>
      </geometry>
      <material name="door_green"/>
    </visual>
    <collision>
      <origin xyz="0.4275 0.0 0.0" rpy="0.0 0.0 0.0"/>
      <geometry>
        <box size="0.855 0.04 2.0"/>
      </geometry>
    </collision>
  </link>
  <link name="iai_kitchen:arena:door_hinge">
    <visual>
      <origin xyz="0.0 0.0 0.0" rpy="0.0 0.0 0.0"/>
      <geometry>
        <box size="0.05 0.05 2.0"/>
      </geometry>
      <material name="hinge_red"/>
    </visual>
    <collision>
      <origin xyz="0.0 0.0 0.0" rpy="0.0 0.0 0.0"/>
      <geometry>
        <box size="0.05 0.05 2.0"/>
      </geometry>
    </collision>
  </link>
  <link name="iai_kitchen:arena:door_handle_link">
    <visual>
      <origin xyz="0.0 0.0 0.0" rpy="0.0 0.0 0.0"/>
      <geometry>
        <cylinder radius="0.013" length="0.1"/>
      </geometry>
    </visual>
    <collision>
      <origin xyz="0.0 0.0 0.0" rpy="0.0 0.0 0.0"/>
      <geometry>
        <cylinder radius="0.013" length="0.1"/>
      </geometry>
    </collision>
  </link>
  <link name="iai_kitchen:arena:door_handle_outside">
    <visual>
      <origin xyz="0.0 0.0 0.0" rpy="0.0 0.0 0.0"/>
      <geometry>
        <box size="0.015 0.15 0.01"/>
      </geometry>
      <material name="handle_blue"/>
    </visual>
    <collision>
      <origin xyz="0.0 0.0 0.0" rpy="0.0 0.0 0.0"/>
      <geometry>
        <box size="0.015 0.15 0.01"/>
      </geometry>
    </collision>
  </link>
  <link name="iai_kitchen:arena:door_handle_inside">
    <visual>
      <origin xyz="0.0 0.0 0.0" rpy="0.0 0.0 0.0"/>
      <geometry>
        <box size="0.015 0.15 0.01"/>
      </geometry>
      <material name="handle_blue"/>
    </visual>
    <collision>
      <origin xyz="0.0 0.0 0.0" rpy="0.0 0.0 0.0"/>
      <geometry>
        <box size="0.015 0.15 0.01"/>
      </geometry>
    </collision>
  </link>
  <joint name="iai_kitchen:arena:door_origin_revolute_joint" type="revolute">
    <origin xyz="0.0 0.0 0.0" rpy="0.0 0.0 1.57"/>
    <axis xyz="0.0 0.0 1.0"/>
    <parent link="iai_kitchen:arena:door_hinge"/>
    <child link="iai_kitchen:arena:door_center"/>
    <limit effort="100.0" lower="-1.4" upper="0.0" velocity="10.0"/>
  </joint>
  <joint name="iai_kitchen:arena:door_hinge_joint" type="fixed">
    <origin xyz="0.58 -0.44 1.04" rpy="0.0 0.0 0.0"/>
    <axis xyz="0.0 0.0 0.0"/>
    <parent link="urdf_offset"/>
    <child link="iai_kitchen:arena:door_hinge"/>
    <limit effort="1.0" lower="0.0" upper="1.5708" velocity="1.0"/>
  </joint>
  <joint name="iai_kitchen:arena:door_handle_joint" type="revolute">
    <origin xyz="0.82 0.0 0.02" rpy="1.5707963267948966 0.0 0.0"/>
    <axis xyz="0.0 0.0 1.0"/>
    <parent link="iai_kitchen:arena:door_center"/>
    <child link="iai_kitchen:arena:door_handle_link"/>
    <limit effort="1.0" lower="0.0" upper="0.6283185307179586" velocity="1.0"/>
  </joint>
  <joint name="iai_kitchen:arena:door_handle_inside_joint" type="fixed">
    <origin xyz="-0.02 0.0 0.055" rpy="0.0 0.0 1.5707963267948966"/>
    <parent link="iai_kitchen:arena:door_handle_link"/>
    <child link="iai_kitchen:arena:door_handle_inside"/>
  </joint>
  <joint name="iai_kitchen:arena:door_handle_outside_joint" type="fixed">
    <origin xyz="-0.075 0.0 -0.05" rpy="0.0 0.0 -1.5707963267948966"/>
    <parent link="iai_kitchen:arena:door_handle_link"/>
    <child link="iai_kitchen:arena:door_handle_outside"/>
  </joint>
  <link name="living_room:arena:door_center">
    <visual>
      <origin xyz="0.4275 0.0 0.0" rpy="0.0 0.0 0.0"/>
      <geometry>
        <box size="0.855 0.04 2.0"/>
      </geometry>
      <material name="door_green"/>
    </visual>
    <collision>
      <origin xyz="0.4275 0.0 0.0" rpy="0.0 0.0 0.0"/>
      <geometry>
        <box size="0.855 0.04 2.0"/>
      </geometry>
    </collision>
  </link>
  <link name="living_room:arena:door_hinge">
    <visual>
      <origin xyz="0.0 0.0 0.0" rpy="0.0 0.0 0.0"/>
      <geometry>
        <box size="0.05 0.05 2.0"/>
      </geometry>
      <material name="hinge_red"/>
    </visual>
    <collision>
      <origin xyz="0.0 0.0 0.0" rpy="0.0 0.0 0.0"/>
      <geometry>
        <box size="0.05 0.05 2.0"/>
      </geometry>
    </collision>
  </link>
  <link name="living_room:arena:door_handle_link">
    <visual>
      <origin xyz="0.0 0.0 0.0" rpy="0.0 0.0 0.0"/>
      <geometry>
        <cylinder radius="0.013" length="0.1"/>
      </geometry>
    </visual>
    <collision>
      <origin xyz="0.0 0.0 0.0" rpy="0.0 0.0 0.0"/>
      <geometry>
        <cylinder radius="0.013" length="0.1"/>
      </geometry>
    </collision>
  </link>
  <link name="living_room:arena:door_handle_outside">
    <visual>
      <origin xyz="0.0 0.0 0.0" rpy="0.0 0.0 0.0"/>
      <geometry>
        <box size="0.015 0.15 0.01"/>
      </geometry>
      <material name="handle_blue"/>
    </visual>
    <collision>
      <origin xyz="0.0 0.0 0.0" rpy="0.0 0.0 0.0"/>
      <geometry>
        <box size="0.015 0.15 0.01"/>
      </geometry>
    </collision>
  </link>
  <link name="living_room:arena:door_handle_inside">
    <visual>
      <origin xyz="0.0 0.0 0.0" rpy="0.0 0.0 0.0"/>
      <geometry>
        <box size="0.015 0.15 0.01"/>
      </geometry>
      <material name="handle_blue"/>
    </visual>
    <collision>
      <origin xyz="0.0 0.0 0.0" rpy="0.0 0.0 0.0"/>
      <geometry>
        <box size="0.015 0.15 0.01"/>
      </geometry>
    </collision>
  </link>
  <joint name="living_room:arena:door_origin_revolute_joint" type="revolute">
    <origin xyz="0.0 0.0 0.0" rpy="0.0 0.0 1.57"/>
    <axis xyz="0.0 0.0 1.0"/>
    <parent link="living_room:arena:door_hinge"/>
    <child link="living_room:arena:door_center"/>
    <limit effort="100.0" lower="-1.4" upper="0.0" velocity="10.0"/>
  </joint>
  <joint name="living_room:arena:door_hinge_joint" type="fixed">
    <origin xyz="0.28 3.37 1.04" rpy="0.0 0.0 0.0"/>
    <axis xyz="0.0 0.0 0.0"/>
    <parent link="urdf_offset"/>
    <child link="living_room:arena:door_hinge"/>
    <limit effort="1.0" lower="0.0" upper="1.5708" velocity="1.0"/>
  </joint>
  <joint name="living_room:arena:door_handle_joint" type="revolute">
    <origin xyz="0.79 0.0 0.02" rpy="1.5707963267948966 0.0 0.0"/>
    <axis xyz="0.0 0.0 1.0"/>
    <parent link="living_room:arena:door_center"/>
    <child link="living_room:arena:door_handle_link"/>
    <limit effort="1.0" lower="0.0" upper="0.6283185307179586" velocity="1.0"/>
  </joint>
  <joint name="living_room:arena:door_handle_inside_joint" type="fixed">
    <origin xyz="-0.02 0.0 0.055" rpy="0.0 0.0 1.5707963267948966"/>
    <parent link="living_room:arena:door_handle_link"/>
    <child link="living_room:arena:door_handle_inside"/>
  </joint>
  <joint name="living_room:arena:door_handle_outside_joint" type="fixed">
    <origin xyz="-0.075 0.0 -0.05" rpy="0.0 0.0 -1.5707963267948966"/>
    <parent link="living_room:arena:door_handle_link"/>
    <child link="living_room:arena:door_handle_outside"/>
  </joint>
  <link name="dishwasher_main">
    <inertial>
      <origin xyz="0.0 0.0 0.0" rpy="0.0 0.0 0.0"/>
      <mass value="1.0"/>
      <inertia ixx="1.0" ixy="0.0" ixz="0.0" iyy="1.0" iyz="0.0" izz="1.0"/>
    </inertial>
  </link>
  <joint name="dishwasher_main" type="fixed">
    <origin xyz="1.86 -2.2 0.0" rpy="0.0 0.0 1.57"/>
    <parent link="urdf_offset"/>
    <child link="dishwasher_main"/>
  </joint>
  <joint name="dishwasher_main_joint" type="fixed">
    <origin xyz="1.86 -2.2 0.0" rpy="0.0 0.0 1.57"/>
    <parent link="dishwasher_main"/>
    <child link="sink_area_dish_washer_main"/>
  </joint>
  <link name="sink_area_dish_washer_main">
    <inertial>
      <origin xyz="0.0 0.0 0.0" rpy="0.0 0.0 0.0"/>
      <mass value="1.0"/>
      <inertia ixx="1.0" ixy="0.0" ixz="0.0" iyy="1.0" iyz="0.0" izz="1.0"/>
    </inertial>
    <visual>
      <origin xyz="0.0 0.0 0.0" rpy="0.0 0.0 0.0"/>
      <geometry>
        <mesh filename="package://iai_kitchen/meshes/misc/DishWasher.obj"/>
      </geometry>
    </visual>
    <collision>
      <origin xyz="0.0 0.0 0.0" rpy="0.0 0.0 0.0"/>
      <geometry>
        <mesh filename="package://iai_kitchen/meshes/misc/DishWasher.obj"/>
      </geometry>
    </collision>
  </link>
  <link name="sink_area_dish_washer_door">
    <inertial>
      <origin xyz="0.0 0.0 0.0" rpy="0.0 0.0 0.0"/>
      <mass value="1.0"/>
      <inertia ixx="1.0" ixy="0.0" ixz="0.0" iyy="1.0" iyz="0.0" izz="1.0"/>
    </inertial>
    <visual>
      <origin xyz="0.0 0.0 0.0" rpy="1.57079632679 0.0 0.0"/>
      <geometry>
        <mesh filename="package://iai_kitchen/meshes/misc/DishWasherDoor.obj"/>
      </geometry>
    </visual>
    <collision>
      <origin xyz="0.0 0.0 0.0" rpy="1.57079632679 0.0 0.0"/>
      <geometry>
        <mesh filename="package://iai_kitchen/meshes/misc/DishWasherDoor.obj"/>
      </geometry>
    </collision>
  </link>
  <link name="sink_area_dish_washer_door_handle">
    <inertial>
      <origin xyz="0.0 0.0 0.0" rpy="0.0 0.0 0.0"/>
      <mass value="1.0"/>
      <inertia ixx="1.0" ixy="0.0" ixz="0.0" iyy="1.0" iyz="0.0" izz="1.0"/>
    </inertial>
    <visual>
      <origin xyz="0.0 0.0 0.0" rpy="0.0 0.0 0.0"/>
      <geometry>
        <mesh filename="package://iai_kitchen/meshes/handles/Handle60.obj"/>
      </geometry>
    </visual>
    <collision>
      <origin xyz="0.0 0.0 0.0" rpy="0.0 0.0 0.0"/>
      <geometry>
        <mesh filename="package://iai_kitchen/meshes/handles/Handle60.obj"/>
      </geometry>
    </collision>
  </link>
  <link name="dishwasher_tab"/>
  <link name="dishwasher_table:d_table:table_origin"/>
  <link name="dishwasher_table:d_table:table_front_edge_center"/>
  <link name="dishwasher_table:d_table:table_center">
    <visual>
      <origin xyz="0.0 0.0 0.0" rpy="0.0 0.0 0.0"/>
      <geometry>
        <box size="0.6 0.6 0.02"/>
      </geometry>
      <material name="dishwasher_table_color"/>
    </visual>
    <collision>
      <origin xyz="0.0 0.0 0.0" rpy="0.0 0.0 0.0"/>
      <geometry>
        <box size="0.6 0.6 0.02"/>
      </geometry>
    </collision>
  </link>
  <joint name="dishwasher_tab_joint" type="fixed">
    <origin xyz="-0.1 0.1 0.15" rpy="0.0 0.0 0.0"/>
    <parent link="sink_area_dish_washer_door_handle"/>
    <child link="dishwasher_tab"/>
  </joint>
  <joint name="sink_area_dish_washer_main_joint" type="fixed">
    <origin xyz="0.08 -0.78 0.44" rpy="0.0 0.0 0.0"/>
    <axis xyz="1.0 0.0 0.0"/>
    <parent link="dishwasher_main"/>
    <child link="sink_area_dish_washer_main"/>
  </joint>
  <joint name="sink_area_dish_washer_door_joint" type="revolute">
    <origin xyz="0.27 0.0 -0.325" rpy="-1.57079632679 0.03 0.0"/>
    <axis xyz="0.0 0.0 1.0"/>
    <parent link="sink_area_dish_washer_main"/>
    <child link="sink_area_dish_washer_door"/>
    <limit effort="300.0" lower="0.0" upper="1.57079632679" velocity="10.0"/>
  </joint>
  <joint name="sink_area_dish_washer_door_handle_joint" type="fixed">
    <origin xyz="0.0625 -0.6325 0.0" rpy="-1.57079632679 0.0 0.0"/>
    <parent link="sink_area_dish_washer_door"/>
    <child link="sink_area_dish_washer_door_handle"/>
  </joint>
  <joint name="dish_washer_table_main_joint" type="fixed">
    <origin xyz="0.0 0.0 0.39" rpy="0.0 0.0 0.0"/>
    <parent link="sink_area_dish_washer_main"/>
    <child link="dishwasher_table:d_table:table_origin"/>
  </joint>
  <joint name="dish_washer_table_center_joint" type="fixed">
    <origin xyz="0.3 0.0 0.0" rpy="0.0 0.0 0.0"/>
    <parent link="dishwasher_table:d_table:table_origin"/>
    <child link="dishwasher_table:d_table:table_front_edge_center"/>
  </joint>
  <joint name="dish_washer_table_edge_joint" type="fixed">
    <origin xyz="0.0 0.0 0.0" rpy="0.0 0.0 0.0"/>
    <parent link="dishwasher_table:d_table:table_origin"/>
    <child link="dishwasher_table:d_table:table_center"/>
  </joint>
  <link name="chair:chair:chair_center">
    <visual>
      <origin xyz="0.0 0.0 0.0" rpy="0.0 0.0 0.0"/>
      <geometry>
        <box size="0.3 0.3 0.5"/>
      </geometry>
      <material name="chair_color"/>
    </visual>
    <collision>
      <origin xyz="0.0 0.0 0.0" rpy="0.0 0.0 0.0"/>
      <geometry>
        <box size="0.3 0.3 0.5"/>
      </geometry>
    </collision>
  </link>
  <link name="chair:chair:chair_backrest">
    <visual>
      <origin xyz="0.0 0.0 0.0" rpy="0.0 0.0 0.0"/>
      <geometry>
        <box size="0.3 0.05 0.5"/>
      </geometry>
      <material name="chair_color"/>
    </visual>
    <collision>
      <origin xyz="0.0 0.0 0.0" rpy="0.0 0.0 0.0"/>
      <geometry>
        <box size="0.3 0.05 0.5"/>
      </geometry>
    </collision>
  </link>
  <link name="chair:chair:chair_origin"/>
  <link name="chair:chair:chair_front_edge_center"/>
  <joint name="chair:chair:chair_origin_joint" type="fixed">
    <origin xyz="2.8 1.3 0.0" rpy="0.0 0.0 0.0"/>
    <parent link="urdf_offset"/>
    <child link="chair:chair:chair_origin"/>
  </joint>
  <joint name="chair:chair:center_joint" type="fixed">
    <origin xyz="0.0 0.0 0.25" rpy="0.0 0.0 0.0"/>
    <parent link="chair:chair:chair_origin"/>
    <child link="chair:chair:chair_center"/>
  </joint>
  <joint name="chair:chair:chair_front_edge_center_joint" type="fixed">
    <origin xyz="0.0 0.15 0.5" rpy="0.0 0.0 0.0"/>
    <parent link="chair:chair:chair_origin"/>
    <child link="chair:chair:chair_front_edge_center"/>
  </joint>
  <joint name="chair:chair:chair_backrest_joint" type="fixed">
    <origin xyz="0.0 -0.12 0.25" rpy="0.0 0.0 0.0"/>
    <parent link="chair:chair:chair_center"/>
    <child link="chair:chair:chair_backrest"/>
  </joint>
  <link name="shelf_hohc:shelf_hohc:shelf_origin"/>
  <link name="shelf_hohc:shelf_hohc:shelf_center"/>
  <link name="shelf_hohc:shelf_hohc:shelf_base_center"/>
  <joint name="shelf_hohc:shelf_hohc:shelf_origin_joint" type="fixed">
    <origin xyz="3.4 3.4 0.0" rpy="0.0 0.0 1.57"/>
    <parent link="urdf_offset"/>
    <child link="shelf_hohc:shelf_hohc:shelf_origin"/>
  </joint>
  <joint name="shelf_hohc:shelf_hohc:shelf_center_joint" type="fixed">
    <origin xyz="0.2 0.4 1.01" rpy="0.0 0.0 0.0"/>
    <parent link="shelf_hohc:shelf_hohc:shelf_origin"/>
    <child link="shelf_hohc:shelf_hohc:shelf_center"/>
  </joint>
  <joint name="shelf_hohc:shelf_hohc:shelf_base_center_joint" type="fixed">
    <origin xyz="0.2 0.4 0.0" rpy="0.0 0.0 0.0"/>
    <parent link="shelf_hohc:shelf_hohc:shelf_origin"/>
    <child link="shelf_hohc:shelf_hohc:shelf_base_center"/>
  </joint>
  <link name="shelf_hohc:shelf_hohc:shelf_back">
    <visual>
      <origin xyz="0.0 0.0 0.0" rpy="0.0 0.0 0.0"/>
      <geometry>
        <box size="0.02 0.8 2.02"/>
      </geometry>
      <material name="shelf_blue"/>
    </visual>
    <collision>
      <origin xyz="0.0 0.0 0.0" rpy="0.0 0.0 0.0"/>
      <geometry>
        <box size="0.02 0.8 2.02"/>
      </geometry>
    </collision>
  </link>
  <joint name="shelf_hohc:shelf_hohc:shelf_back:joint" type="fixed">
    <origin xyz="0.4 0.4 1.01" rpy="0.0 0.0 0.0"/>
    <parent link="shelf_hohc:shelf_hohc:shelf_origin"/>
    <child link="shelf_hohc:shelf_hohc:shelf_back"/>
  </joint>
  <link name="shelf_hohc:shelf_hohc:shelf_right_side">
    <visual>
      <origin xyz="0.0 0.0 0.0" rpy="0.0 0.0 0.0"/>
      <geometry>
        <box size="0.4 0.02 2.02"/>
      </geometry>
      <material name="shelf_blue"/>
    </visual>
    <collision>
      <origin xyz="0.0 0.0 0.0" rpy="0.0 0.0 0.0"/>
      <geometry>
        <box size="0.4 0.02 2.02"/>
      </geometry>
    </collision>
  </link>
  <joint name="shelf_hohc:shelf_hohc:shelf_right_side:joint" type="fixed">
    <origin xyz="0.2 0.01 1.01" rpy="0.0 0.0 0.0"/>
    <parent link="shelf_hohc:shelf_hohc:shelf_origin"/>
    <child link="shelf_hohc:shelf_hohc:shelf_right_side"/>
  </joint>
  <link name="shelf_hohc:shelf_hohc:shelf_left_side">
    <visual>
      <origin xyz="0.0 0.0 0.0" rpy="0.0 0.0 0.0"/>
      <geometry>
        <box size="0.4 0.02 2.02"/>
      </geometry>
      <material name="shelf_blue"/>
    </visual>
    <collision>
      <origin xyz="0.0 0.0 0.0" rpy="0.0 0.0 0.0"/>
      <geometry>
        <box size="0.4 0.02 2.02"/>
      </geometry>
    </collision>
  </link>
  <joint name="shelf_hohc:shelf_hohc:shelf_left_side:joint" type="fixed">
    <origin xyz="0.2 0.79 1.01" rpy="0.0 0.0 0.0"/>
    <parent link="shelf_hohc:shelf_hohc:shelf_origin"/>
    <child link="shelf_hohc:shelf_hohc:shelf_left_side"/>
  </joint>
  <link name="shelf_hohc:shelf_hohc:shelf_floor_0">
    <visual>
      <origin xyz="0.0 0.0 -0.02" rpy="0.0 0.0 0.0"/>
      <geometry>
        <box size="0.4 0.8 0.04"/>
      </geometry>
      <material name="shelf_blue"/>
    </visual>
    <collision>
      <origin xyz="0.0 0.0 -0.02" rpy="0.0 0.0 0.0"/>
      <geometry>
        <box size="0.4 0.8 0.04"/>
      </geometry>
    </collision>
  </link>
  <joint name="shelf_hohc:shelf_hohc:shelf_floor_0:joint" type="fixed">
    <origin xyz="0.0 0.0 0.1" rpy="0.0 0.0 0.0"/>
    <parent link="shelf_hohc:shelf_hohc:shelf_base_center"/>
    <child link="shelf_hohc:shelf_hohc:shelf_floor_0"/>
  </joint>
  <link name="shelf_hohc:shelf_hohc:shelf_floor_1">
    <visual>
      <origin xyz="0.0 0.0 -0.02" rpy="0.0 0.0 0.0"/>
      <geometry>
        <box size="0.4 0.8 0.04"/>
      </geometry>
      <material name="shelf_blue"/>
    </visual>
    <collision>
      <origin xyz="0.0 0.0 -0.02" rpy="0.0 0.0 0.0"/>
      <geometry>
        <box size="0.4 0.8 0.04"/>
      </geometry>
    </collision>
  </link>
  <joint name="shelf_hohc:shelf_hohc:shelf_floor_1:joint" type="fixed">
    <origin xyz="0.0 0.0 0.54" rpy="0.0 0.0 0.0"/>
    <parent link="shelf_hohc:shelf_hohc:shelf_base_center"/>
    <child link="shelf_hohc:shelf_hohc:shelf_floor_1"/>
  </joint>
  <link name="shelf_hohc:shelf_hohc:shelf_floor_2">
    <visual>
      <origin xyz="0.0 0.0 -0.02" rpy="0.0 0.0 0.0"/>
      <geometry>
        <box size="0.4 0.8 0.04"/>
      </geometry>
      <material name="shelf_blue"/>
    </visual>
    <collision>
      <origin xyz="0.0 0.0 -0.02" rpy="0.0 0.0 0.0"/>
      <geometry>
        <box size="0.4 0.8 0.04"/>
      </geometry>
    </collision>
  </link>
  <joint name="shelf_hohc:shelf_hohc:shelf_floor_2:joint" type="fixed">
    <origin xyz="0.0 0.0 1.055" rpy="0.0 0.0 0.0"/>
    <parent link="shelf_hohc:shelf_hohc:shelf_base_center"/>
    <child link="shelf_hohc:shelf_hohc:shelf_floor_2"/>
  </joint>
  <link name="shelf_hohc:shelf_hohc:shelf_floor_3">
    <visual>
      <origin xyz="0.0 0.0 -0.02" rpy="0.0 0.0 0.0"/>
      <geometry>
        <box size="0.4 0.8 0.04"/>
      </geometry>
      <material name="shelf_blue"/>
    </visual>
    <collision>
      <origin xyz="0.0 0.0 -0.02" rpy="0.0 0.0 0.0"/>
      <geometry>
        <box size="0.4 0.8 0.04"/>
      </geometry>
    </collision>
  </link>
  <joint name="shelf_hohc:shelf_hohc:shelf_floor_3:joint" type="fixed">
    <origin xyz="0.0 0.0 2.02" rpy="0.0 0.0 0.0"/>
    <parent link="shelf_hohc:shelf_hohc:shelf_base_center"/>
    <child link="shelf_hohc:shelf_hohc:shelf_floor_3"/>
  </joint>
  <link name="shelf_hohc:shelf_hohc:shelf_door_right">
    <visual>
      <origin xyz="0.0 0.18 0.0" rpy="0.0 0.0 0.0"/>
      <geometry>
        <box size="0.02 0.38 0.97"/>
      </geometry>
      <material name="shelf_door_green"/>
    </visual>
    <collision>
      <origin xyz="0.0 0.18 0.0" rpy="0.0 0.0 0.0"/>
      <geometry>
        <box size="0.02 0.38 0.97"/>
      </geometry>
    </collision>
  </link>
  <link name="shelf_hohc:shelf_hohc:shelf_door_right:handle">
    <visual>
      <origin xyz="0.0 0.0 0.0" rpy="0.0 0.0 0.0"/>
      <geometry>
        <box size="0.02 0.015 0.015"/>
      </geometry>
      <material name="shelf_hohc_handle_red"/>
    </visual>
    <collision>
      <origin xyz="0.0 0.0 0.0" rpy="0.0 0.0 0.0"/>
      <geometry>
        <box size="0.02 0.015 0.015"/>
      </geometry>
    </collision>
  </link>
  <joint name="shelf_hohc:shelf_hohc:shelf_door_right:handle_joint" type="fixed">
    <origin xyz="-0.03 0.3575 0.09249999999999997" rpy="0.0 0.0 0.0"/>
    <axis xyz="0.0 0.0 1.0"/>
    <parent link="shelf_hohc:shelf_hohc:shelf_door_right"/>
    <child link="shelf_hohc:shelf_hohc:shelf_door_right:handle"/>
  </joint>
  <joint name="shelf_hohc:shelf_hohc:shelf_door_right:joint" type="revolute">
    <origin xyz="-0.19 0.02 -0.48" rpy="0.0 0.0 0.0"/>
    <axis xyz="0.0 0.0 1.0"/>
    <parent link="shelf_hohc:shelf_hohc:shelf_right_side"/>
    <child link="shelf_hohc:shelf_hohc:shelf_door_right"/>
    <limit effort="30.0" lower="0.0" upper="1.7" velocity="1.0"/>
  </joint>
  <link name="shelf_hohc:shelf_hohc:shelf_door_left">
    <visual>
      <origin xyz="0.0 -0.18 0.0" rpy="0.0 0.0 0.0"/>
      <geometry>
        <box size="0.02 0.38 0.97"/>
      </geometry>
      <material name="shelf_door_green"/>
    </visual>
    <collision>
      <origin xyz="0.0 -0.18 0.0" rpy="0.0 0.0 0.0"/>
      <geometry>
        <box size="0.02 0.38 0.97"/>
      </geometry>
    </collision>
  </link>
  <link name="shelf_hohc:shelf_hohc:shelf_door_left:handle">
    <visual>
      <origin xyz="0.0 0.0 0.0" rpy="0.0 0.0 0.0"/>
      <geometry>
        <box size="0.02 0.015 0.015"/>
      </geometry>
      <material name="shelf_hohc_handle_red"/>
    </visual>
    <collision>
      <origin xyz="0.0 0.0 0.0" rpy="0.0 0.0 0.0"/>
      <geometry>
        <box size="0.02 0.015 0.015"/>
      </geometry>
    </collision>
  </link>
  <joint name="shelf_hohc:shelf_hohc:shelf_door_left:handle_joint" type="fixed">
    <origin xyz="-0.03 -0.3575 0.09249999999999997" rpy="0.0 0.0 0.0"/>
    <axis xyz="0.0 0.0 1.0"/>
    <parent link="shelf_hohc:shelf_hohc:shelf_door_left"/>
    <child link="shelf_hohc:shelf_hohc:shelf_door_left:handle"/>
  </joint>
  <joint name="shelf_hohc:shelf_hohc:shelf_door_left:joint" type="revolute">
    <origin xyz="-0.19 -0.02 -0.48" rpy="0.0 0.0 0.0"/>
    <axis xyz="0.0 0.0 1.0"/>
    <parent link="shelf_hohc:shelf_hohc:shelf_left_side"/>
    <child link="shelf_hohc:shelf_hohc:shelf_door_left"/>
    <limit effort="30.0" lower="-1.7" upper="0.0" velocity="1.0"/>
  </joint>
  <link name="urdf_main"/>
  <joint name="map_urdf_joint" type="fixed">
    <origin xyz="0.0 0.0 0.0" rpy="0.0 0.0 0.0"/>
    <parent link="urdf_main"/>
    <child link="urdf_offset"/>
  </joint>
  <link name="urdf_offset"/>
</robot>