<?xml version="1.0" ?>
<robot name="iai-kitchen" version="1.0">
  <material name="table_grey">
    <color rgba="0.255 0.62 0.223 1.0"/>
  </material>
  <material name="color_grey">
    <color rgba="0.8 0.8 0.8 1.0"/>
  </material>
  <material name="color_red">
    <color rgba="1.0 0.0 0.0 1.0"/>
  </material>
  <material name="color_blue">
    <color rgba="0.0 0.0 1.0 1.0"/>
  </material>
  <material name="round_table_grey">
    <color rgba="0.8 0.8 0.8 1.0"/>
  </material>
  <material name="wall_pink">
    <color rgba="0.95 0.43 0.96 1.0"/>
  </material>
  <material name="shelf_blue">
    <color rgba="0.59 0.88 0.9 1.0"/>
  </material>
  <material name="shelf_door_green">
    <color rgba="0.64 0.87 0.82 1.0"/>
  </material>
  <material name="shelf_openable_handle_red">
    <color rgba="0.74 0.25 0.25 1.0"/>
  </material>
  <material name="door_green">
    <color rgba="0.0 0.31 0.22 1.0"/>
  </material>
  <material name="hinge_red">
    <color rgba="0.74 0.25 0.25 1.0"/>
  </material>
  <material name="handle_blue">
    <color rgba="0.3 0.5 0.78 1.0"/>
  </material>
  <material name="bucket_grey">
    <color rgba="0.8 0.8 0.8 1.0"/>
  </material>
  <material name="white">
    <color rgba="1.0 1.0 1.0 1.0"/>
  </material>
  <material name="orange">
    <color rgba="1.0 0.7 0.0 1.0"/>
  </material>
  <material name="handle_white">
    <color rgba="1.0 1.0 1.0 1.0"/>
  </material>
  <material name="bottom_white">
    <color rgba="1.0 1.0 1.0 1.0"/>
  </material>
  <material name="frame_wood">
    <color rgba="0.68 0.63 0.47 1.0"/>
  </material>
  <material name="handle_grey">
    <color rgba="0.7 0.7 0.7 1.0"/>
  </material>
  <link name="long_table:l_table:table_center">
    <visual>
      <origin xyz="0.0 0.0 -0.3675" rpy="0.0 0.0 0.0"/>
      <geometry>
        <box size="0.73 1.17 0.735"/>
      </geometry>
      <material name="table_grey"/>
    </visual>
    <collision>
      <origin xyz="0.0 0.0 -0.3675" rpy="0.0 0.0 0.0"/>
      <geometry>
        <box size="0.73 1.17 0.735"/>
      </geometry>
    </collision>
  </link>
  <link name="long_table:l_table:table_origin"/>
  <link name="long_table:l_table:table_front_edge_center"/>
  <joint name="long_table:l_table:table_origin_joint" type="fixed">
    <origin xyz="1.01 2.13 0.0" rpy="0.0 0.0 3.15"/>
    <parent link="urdf_offset"/>
    <child link="long_table:l_table:table_origin"/>
  </joint>
  <joint name="long_table:l_table:center_joint" type="fixed">
    <origin xyz="0.365 0.585 0.735" rpy="0.0 0.0 0.0"/>
    <parent link="long_table:l_table:table_origin"/>
    <child link="long_table:l_table:table_center"/>
  </joint>
  <joint name="long_table:l_table:table_front_edge_center_joint" type="fixed">
    <origin xyz="0.0 0.585 0.735" rpy="0.0 0.0 0.0"/>
    <parent link="long_table:l_table:table_origin"/>
    <child link="long_table:l_table:table_front_edge_center"/>
  </joint>
  <link name="popcorn_table:p_table:table_center">
    <visual>
      <origin xyz="0.0 0.0 -0.355" rpy="0.0 0.0 0.0"/>
      <geometry>
        <box size="0.55 1.8 0.71"/>
      </geometry>
      <material name="table_grey"/>
    </visual>
    <collision>
      <origin xyz="0.0 0.0 -0.355" rpy="0.0 0.0 0.0"/>
      <geometry>
        <box size="0.55 1.8 0.71"/>
      </geometry>
    </collision>
  </link>
  <link name="popcorn_table:p_table:table_origin"/>
  <link name="popcorn_table:p_table:table_front_edge_center"/>
  <joint name="popcorn_table:p_table:table_origin_joint" type="fixed">
    <origin xyz="3.03 5.68 0.0" rpy="0.0 0.0 1.57"/>
    <parent link="urdf_offset"/>
    <child link="popcorn_table:p_table:table_origin"/>
  </joint>
  <joint name="popcorn_table:p_table:center_joint" type="fixed">
    <origin xyz="0.275 0.9 0.71" rpy="0.0 0.0 0.0"/>
    <parent link="popcorn_table:p_table:table_origin"/>
    <child link="popcorn_table:p_table:table_center"/>
  </joint>
  <joint name="popcorn_table:p_table:table_front_edge_center_joint" type="fixed">
    <origin xyz="0.0 0.9 0.71" rpy="0.0 0.0 0.0"/>
    <parent link="popcorn_table:p_table:table_origin"/>
    <child link="popcorn_table:p_table:table_front_edge_center"/>
  </joint>
  <link name="couch_table:couch_table:table_center">
    <visual>
      <origin xyz="0.0 0.0 -0.2165" rpy="0.0 0.0 0.0"/>
      <geometry>
        <box size="0.37 0.909 0.433"/>
      </geometry>
      <material name="table_grey"/>
    </visual>
    <collision>
      <origin xyz="0.0 0.0 -0.2165" rpy="0.0 0.0 0.0"/>
      <geometry>
        <box size="0.37 0.909 0.433"/>
      </geometry>
    </collision>
  </link>
  <link name="couch_table:couch_table:table_origin"/>
  <link name="couch_table:couch_table:table_front_edge_center"/>
  <joint name="couch_table:couch_table:table_origin_joint" type="fixed">
    <origin xyz="4.83 1.99 0.0" rpy="0.0 0.0 0.0"/>
    <parent link="urdf_offset"/>
    <child link="couch_table:couch_table:table_origin"/>
  </joint>
  <joint name="couch_table:couch_table:center_joint" type="fixed">
    <origin xyz="0.185 0.4545 0.433" rpy="0.0 0.0 0.0"/>
    <parent link="couch_table:couch_table:table_origin"/>
    <child link="couch_table:couch_table:table_center"/>
  </joint>
  <joint name="couch_table:couch_table:table_front_edge_center_joint" type="fixed">
    <origin xyz="0.0 0.4545 0.433" rpy="0.0 0.0 0.0"/>
    <parent link="couch_table:couch_table:table_origin"/>
    <child link="couch_table:couch_table:table_front_edge_center"/>
  </joint>
  <link name="kitchen_island:kitchen_island:table_center">
    <visual>
      <origin xyz="0.0 0.0 -0.4265" rpy="0.0 0.0 0.0"/>
      <geometry>
        <box size="0.796 -2.47 0.853"/>
      </geometry>
      <material name="table_grey"/>
    </visual>
    <collision>
      <origin xyz="0.0 0.0 -0.4265" rpy="0.0 0.0 0.0"/>
      <geometry>
        <box size="0.796 -2.47 0.853"/>
      </geometry>
    </collision>
  </link>
  <link name="kitchen_island:kitchen_island:table_origin"/>
  <link name="kitchen_island:kitchen_island:table_front_edge_center"/>
  <joint name="kitchen_island:kitchen_island:table_origin_joint" type="fixed">
    <origin xyz="3.0 0.134 0.0" rpy="0.0 0.0 1.57"/>
    <parent link="urdf_offset"/>
    <child link="kitchen_island:kitchen_island:table_origin"/>
  </joint>
  <joint name="kitchen_island:kitchen_island:center_joint" type="fixed">
    <origin xyz="0.398 -1.235 0.853" rpy="0.0 0.0 0.0"/>
    <parent link="kitchen_island:kitchen_island:table_origin"/>
    <child link="kitchen_island:kitchen_island:table_center"/>
  </joint>
  <joint name="kitchen_island:kitchen_island:table_front_edge_center_joint" type="fixed">
    <origin xyz="0.0 -1.235 0.853" rpy="0.0 0.0 0.0"/>
    <parent link="kitchen_island:kitchen_island:table_origin"/>
    <child link="kitchen_island:kitchen_island:table_front_edge_center"/>
  </joint>
  <link name="oven_area:oven_area:table_center">
    <visual>
      <origin xyz="0.0 0.0 -0.755" rpy="0.0 0.0 0.0"/>
      <geometry>
        <box size="0.68 1.2 1.51"/>
      </geometry>
      <material name="table_grey"/>
    </visual>
    <collision>
      <origin xyz="0.0 0.0 -0.755" rpy="0.0 0.0 0.0"/>
      <geometry>
        <box size="0.68 1.2 1.51"/>
      </geometry>
    </collision>
  </link>
  <link name="oven_area:oven_area:table_origin"/>
  <link name="oven_area:oven_area:table_front_edge_center"/>
  <joint name="oven_area:oven_area:table_origin_joint" type="fixed">
    <origin xyz="3.77 -1.8 0.0" rpy="0.0 0.0 4.72"/>
    <parent link="urdf_offset"/>
    <child link="oven_area:oven_area:table_origin"/>
  </joint>
  <joint name="oven_area:oven_area:center_joint" type="fixed">
    <origin xyz="0.34 0.6 1.51" rpy="0.0 0.0 0.0"/>
    <parent link="oven_area:oven_area:table_origin"/>
    <child link="oven_area:oven_area:table_center"/>
  </joint>
  <joint name="oven_area:oven_area:table_front_edge_center_joint" type="fixed">
    <origin xyz="0.0 0.6 1.51" rpy="0.0 0.0 0.0"/>
    <parent link="oven_area:oven_area:table_origin"/>
    <child link="oven_area:oven_area:table_front_edge_center"/>
  </joint>
  <link name="work_surface_left:work_surface_left:table_center">
    <visual>
      <origin xyz="0.0 0.0 -0.42" rpy="0.0 0.0 0.0"/>
      <geometry>
        <box size="0.68 0.82 0.84"/>
      </geometry>
      <material name="table_grey"/>
    </visual>
    <collision>
      <origin xyz="0.0 0.0 -0.42" rpy="0.0 0.0 0.0"/>
      <geometry>
        <box size="0.68 0.82 0.84"/>
      </geometry>
    </collision>
  </link>
  <link name="work_surface_left:work_surface_left:table_origin"/>
  <link name="work_surface_left:work_surface_left:table_front_edge_center"/>
  <joint name="work_surface_left:work_surface_left:table_origin_joint" type="fixed">
    <origin xyz="2.94 -1.84 0.0" rpy="0.0 0.0 4.72"/>
    <parent link="urdf_offset"/>
    <child link="work_surface_left:work_surface_left:table_origin"/>
  </joint>
  <joint name="work_surface_left:work_surface_left:center_joint" type="fixed">
    <origin xyz="0.34 0.41 0.84" rpy="0.0 0.0 0.0"/>
    <parent link="work_surface_left:work_surface_left:table_origin"/>
    <child link="work_surface_left:work_surface_left:table_center"/>
  </joint>
  <joint name="work_surface_left:work_surface_left:table_front_edge_center_joint" type="fixed">
    <origin xyz="0.0 0.41 0.84" rpy="0.0 0.0 0.0"/>
    <parent link="work_surface_left:work_surface_left:table_origin"/>
    <child link="work_surface_left:work_surface_left:table_front_edge_center"/>
  </joint>
  <link name="work_surface_right:work_surface_right:table_center">
    <visual>
      <origin xyz="0.0 0.0 -0.42" rpy="0.0 0.0 0.0"/>
      <geometry>
        <box size="0.68 0.64 0.84"/>
      </geometry>
      <material name="table_grey"/>
    </visual>
    <collision>
      <origin xyz="0.0 0.0 -0.42" rpy="0.0 0.0 0.0"/>
      <geometry>
        <box size="0.68 0.64 0.84"/>
      </geometry>
    </collision>
  </link>
  <link name="work_surface_right:work_surface_right:table_origin"/>
  <link name="work_surface_right:work_surface_right:table_front_edge_center"/>
  <joint name="work_surface_right:work_surface_right:table_origin_joint" type="fixed">
    <origin xyz="1.705 -1.84 0.0" rpy="0.0 0.0 4.72"/>
    <parent link="urdf_offset"/>
    <child link="work_surface_right:work_surface_right:table_origin"/>
  </joint>
  <joint name="work_surface_right:work_surface_right:center_joint" type="fixed">
    <origin xyz="0.34 0.32 0.84" rpy="0.0 0.0 0.0"/>
    <parent link="work_surface_right:work_surface_right:table_origin"/>
    <child link="work_surface_right:work_surface_right:table_center"/>
  </joint>
  <joint name="work_surface_right:work_surface_right:table_front_edge_center_joint" type="fixed">
    <origin xyz="0.0 0.32 0.84" rpy="0.0 0.0 0.0"/>
    <parent link="work_surface_right:work_surface_right:table_origin"/>
    <child link="work_surface_right:work_surface_right:table_front_edge_center"/>
  </joint>
  <link name="refrigerator:refrigerator:table_center">
    <visual>
      <origin xyz="0.0 0.0 -0.755" rpy="0.0 0.0 0.0"/>
      <geometry>
        <box size="0.68 0.595 1.51"/>
      </geometry>
      <material name="table_grey"/>
    </visual>
    <collision>
      <origin xyz="0.0 0.0 -0.755" rpy="0.0 0.0 0.0"/>
      <geometry>
        <box size="0.68 0.595 1.51"/>
      </geometry>
    </collision>
  </link>
  <link name="refrigerator:refrigerator:table_origin"/>
  <link name="refrigerator:refrigerator:table_front_edge_center"/>
  <joint name="refrigerator:refrigerator:table_origin_joint" type="fixed">
    <origin xyz="1.11 -1.84 0.0" rpy="0.0 0.0 4.72"/>
    <parent link="urdf_offset"/>
    <child link="refrigerator:refrigerator:table_origin"/>
  </joint>
  <joint name="refrigerator:refrigerator:center_joint" type="fixed">
    <origin xyz="0.34 0.2975 1.51" rpy="0.0 0.0 0.0"/>
    <parent link="refrigerator:refrigerator:table_origin"/>
    <child link="refrigerator:refrigerator:table_center"/>
  </joint>
  <joint name="refrigerator:refrigerator:table_front_edge_center_joint" type="fixed">
    <origin xyz="0.0 0.2975 1.51" rpy="0.0 0.0 0.0"/>
    <parent link="refrigerator:refrigerator:table_origin"/>
    <child link="refrigerator:refrigerator:table_front_edge_center"/>
  </joint>
  <link name="suturo_couch:couch:place1">
    <visual>
      <origin xyz="0.0 0.0 0.15" rpy="0.0 0.0 0.0"/>
      <geometry>
        <box size="1.0 1.7 0.3"/>
      </geometry>
      <material name="color_grey"/>
    </visual>
    <collision>
      <origin xyz="0.0 0.0 0.0" rpy="0.0 0.0 0.0"/>
      <geometry>
        <box size="1.0 1.7 0.3"/>
      </geometry>
    </collision>
  </link>
  <link name="suturo_couch:couch:place2">
    <visual>
      <origin xyz="0.0 -0.425 0.15" rpy="0.0 0.0 0.0"/>
      <geometry>
        <box size="1.0 0.85 0.3"/>
      </geometry>
      <material name="color_red"/>
    </visual>
    <collision>
      <origin xyz="0.0 0.0 0.0" rpy="0.0 0.0 0.0"/>
      <geometry>
        <box size="1.0 1.7 0.3"/>
      </geometry>
    </collision>
  </link>
  <link name="suturo_couch:couch:place3">
    <visual>
      <origin xyz="0.0 0.425 0.15" rpy="0.0 0.0 0.0"/>
      <geometry>
        <box size="1.0 0.85 0.3"/>
      </geometry>
      <material name="color_blue"/>
    </visual>
    <collision>
      <origin xyz="0.0 0.0 -0.15" rpy="0.0 0.0 0.0"/>
      <geometry>
        <box size="1.0 1.7 0.3"/>
      </geometry>
    </collision>
  </link>
  <joint name="suturo_couch:couch:couch_origin_joint" type="fixed">
    <origin xyz="4.2 1.19 0.0" rpy="0.0 0.0 1.57"/>
    <parent link="urdf_offset"/>
    <child link="suturo_couch:couch:place1"/>
  </joint>
  <joint name="suturo_couch:couch:couch_left_joint" type="fixed">
    <origin xyz="0.0 0.0 0.0" rpy="0.0 0.0 0.0"/>
    <parent link="suturo_couch:couch:place1"/>
    <child link="suturo_couch:couch:place2"/>
  </joint>
  <joint name="suturo_couch:couch:couch_right_joint" type="fixed">
    <origin xyz="0.0 0.0 0.0" rpy="0.0 0.0 0.0"/>
    <parent link="suturo_couch:couch:place1"/>
    <child link="suturo_couch:couch:place3"/>
  </joint>
  <link name="corner:corner:table_center">
    <visual>
      <origin xyz="0.0 0.0 -0.3625" rpy="0.0 0.0 0.0"/>
      <geometry>
        <cylinder radius="0.7" length="0.725"/>
      </geometry>
      <material name="round_table_grey"/>
    </visual>
    <collision>
      <origin xyz="0.0 0.0 -0.3625" rpy="0.0 0.0 0.0"/>
      <geometry>
        <cylinder radius="0.7" length="0.725"/>
      </geometry>
    </collision>
  </link>
  <link name="corner:corner:table_origin"/>
  <link name="corner:corner:table_front_edge_center"/>
  <joint name="corner:corner:table_origin_joint" type="fixed">
    <origin xyz="5.47 5.87 0.0" rpy="0.0 0.0 1.5708"/>
    <parent link="urdf_offset"/>
    <child link="corner:corner:table_origin"/>
  </joint>
  <joint name="corner:corner:center_joint" type="fixed">
    <origin xyz="0.7 0.0 0.725" rpy="0.0 0.0 0.0"/>
    <parent link="corner:corner:table_origin"/>
    <child link="corner:corner:table_center"/>
  </joint>
  <joint name="corner:corner:table_front_edge_center_joint" type="fixed">
    <origin xyz="0.0 0.0 0.725" rpy="0.0 0.0 0.0"/>
    <parent link="corner:corner:table_origin"/>
    <child link="corner:corner:table_front_edge_center"/>
  </joint>
  <link name="shelf:shelf:shelf_origin"/>
  <link name="shelf:shelf:shelf_center"/>
  <link name="shelf:shelf:shelf_base_center"/>
  <joint name="shelf:shelf:shelf_origin_joint" type="fixed">
    <origin xyz="5.11 4.42 0.0" rpy="0.0 0.0 0.0"/>
    <parent link="urdf_offset"/>
    <child link="shelf:shelf:shelf_origin"/>
  </joint>
  <joint name="shelf:shelf:shelf_center_joint" type="fixed">
    <origin xyz="0.17 0.52 0.6775" rpy="0.0 0.0 0.0"/>
    <parent link="shelf:shelf:shelf_origin"/>
    <child link="shelf:shelf:shelf_center"/>
  </joint>
  <joint name="shelf:shelf:shelf_base_center_joint" type="fixed">
    <origin xyz="0.17 0.52 0.0" rpy="0.0 0.0 0.0"/>
    <parent link="shelf:shelf:shelf_origin"/>
    <child link="shelf:shelf:shelf_base_center"/>
  </joint>
  <link name="shelf:shelf:shelf_back">
    <visual>
      <origin xyz="0.0 0.0 0.0" rpy="0.0 0.0 0.0"/>
      <geometry>
        <box size="0.01 1.04 1.355"/>
      </geometry>
      <material name="shelf_blue"/>
    </visual>
    <collision>
      <origin xyz="0.0 0.0 0.0" rpy="0.0 0.0 0.0"/>
      <geometry>
        <box size="0.01 1.04 1.355"/>
      </geometry>
    </collision>
  </link>
  <joint name="shelf:shelf:shelf_back:joint" type="fixed">
    <origin xyz="0.34 0.52 0.6775" rpy="0.0 0.0 0.0"/>
    <parent link="shelf:shelf:shelf_origin"/>
    <child link="shelf:shelf:shelf_back"/>
  </joint>
  <link name="shelf:shelf:shelf_right_side">
    <visual>
      <origin xyz="0.0 0.0 0.0" rpy="0.0 0.0 0.0"/>
      <geometry>
        <box size="0.34 0.01 1.355"/>
      </geometry>
      <material name="shelf_blue"/>
    </visual>
    <collision>
      <origin xyz="0.0 0.0 0.0" rpy="0.0 0.0 0.0"/>
      <geometry>
        <box size="0.34 0.01 1.355"/>
      </geometry>
    </collision>
  </link>
  <joint name="shelf:shelf:shelf_right_side:joint" type="fixed">
    <origin xyz="0.17 0.0 0.6775" rpy="0.0 0.0 0.0"/>
    <parent link="shelf:shelf:shelf_origin"/>
    <child link="shelf:shelf:shelf_right_side"/>
  </joint>
  <link name="shelf:shelf:shelf_left_side">
    <visual>
      <origin xyz="0.0 0.0 0.0" rpy="0.0 0.0 0.0"/>
      <geometry>
        <box size="0.34 0.01 1.355"/>
      </geometry>
      <material name="shelf_blue"/>
    </visual>
    <collision>
      <origin xyz="0.0 0.0 0.0" rpy="0.0 0.0 0.0"/>
      <geometry>
        <box size="0.34 0.01 1.355"/>
      </geometry>
    </collision>
  </link>
  <joint name="shelf:shelf:shelf_left_side:joint" type="fixed">
    <origin xyz="0.17 1.04 0.6775" rpy="0.0 0.0 0.0"/>
    <parent link="shelf:shelf:shelf_origin"/>
    <child link="shelf:shelf:shelf_left_side"/>
  </joint>
  <link name="shelf:shelf:shelf_floor_0">
    <visual>
      <origin xyz="0.0 0.0 -0.02" rpy="0.0 0.0 0.0"/>
      <geometry>
        <box size="0.34 1.04 0.04"/>
      </geometry>
      <material name="shelf_blue"/>
    </visual>
    <collision>
      <origin xyz="0.0 0.0 -0.02" rpy="0.0 0.0 0.0"/>
      <geometry>
        <box size="0.34 1.04 0.04"/>
      </geometry>
    </collision>
  </link>
  <joint name="shelf:shelf:shelf_floor_0:joint" type="fixed">
    <origin xyz="0.0 0.0 0.077" rpy="0.0 0.0 0.0"/>
    <parent link="shelf:shelf:shelf_base_center"/>
    <child link="shelf:shelf:shelf_floor_0"/>
  </joint>
  <link name="shelf:shelf:shelf_floor_1">
    <visual>
      <origin xyz="0.0 0.0 -0.02" rpy="0.0 0.0 0.0"/>
      <geometry>
        <box size="0.34 1.04 0.04"/>
      </geometry>
      <material name="shelf_blue"/>
    </visual>
    <collision>
      <origin xyz="0.0 0.0 -0.02" rpy="0.0 0.0 0.0"/>
      <geometry>
        <box size="0.34 1.04 0.04"/>
      </geometry>
    </collision>
  </link>
  <joint name="shelf:shelf:shelf_floor_1:joint" type="fixed">
    <origin xyz="0.0 0.0 0.371" rpy="0.0 0.0 0.0"/>
    <parent link="shelf:shelf:shelf_base_center"/>
    <child link="shelf:shelf:shelf_floor_1"/>
  </joint>
  <link name="shelf:shelf:shelf_floor_2">
    <visual>
      <origin xyz="0.0 0.0 -0.02" rpy="0.0 0.0 0.0"/>
      <geometry>
        <box size="0.34 1.04 0.04"/>
      </geometry>
      <material name="shelf_blue"/>
    </visual>
    <collision>
      <origin xyz="0.0 0.0 -0.02" rpy="0.0 0.0 0.0"/>
      <geometry>
        <box size="0.34 1.04 0.04"/>
      </geometry>
    </collision>
  </link>
  <joint name="shelf:shelf:shelf_floor_2:joint" type="fixed">
    <origin xyz="0.0 0.0 0.716" rpy="0.0 0.0 0.0"/>
    <parent link="shelf:shelf:shelf_base_center"/>
    <child link="shelf:shelf:shelf_floor_2"/>
  </joint>
  <joint name="wall_1_center_joint" type="fixed">
    <origin xyz="0.515 0.5015 0.3" rpy="0 0 0"/>
    <parent link="urdf_offset"/>
    <child link="wall_1_link"/>
  </joint>
  <link name="wall_1_link">
    <visual>
      <origin xyz="0.0 0.0 0.0" rpy="0.0 0.0 1.5707963267948966"/>
      <geometry>
        <box size="0.173 0.06 0.6"/>
      </geometry>
      <material name="wall_pink"/>
    </visual>
    <collision>
      <origin xyz="0.0 0.0 0.0" rpy="0.0 0.0 1.5707963267948966"/>
      <geometry>
        <box size="0.173 0.06 0.6"/>
      </geometry>
    </collision>
  </link>
  <joint name="wall_2_center_joint" type="fixed">
    <origin xyz="0.91 0.53 0.3" rpy="0 0 0"/>
    <parent link="urdf_offset"/>
    <child link="wall_2_link"/>
  </joint>
  <link name="wall_2_link">
    <visual>
      <origin xyz="0.0 0.0 0.0" rpy="0.0 0.0 0.0"/>
      <geometry>
        <box size="1.32 0.06 0.6"/>
      </geometry>
      <material name="wall_pink"/>
    </visual>
    <collision>
      <origin xyz="0.0 0.0 0.0" rpy="0.0 0.0 0.0"/>
      <geometry>
        <box size="1.32 0.06 0.6"/>
      </geometry>
    </collision>
  </link>
  <joint name="wall_3_center_joint" type="fixed">
    <origin xyz="0.25 1.903 0.3" rpy="0 0 0"/>
    <parent link="urdf_offset"/>
    <child link="wall_3_link"/>
  </joint>
  <link name="wall_3_link">
    <visual>
      <origin xyz="0.0 0.0 0.0" rpy="0.0 0.0 1.5707963267948966"/>
      <geometry>
        <box size="2.8739999999999997 0.06 0.6"/>
      </geometry>
      <material name="wall_pink"/>
    </visual>
    <collision>
      <origin xyz="0.0 0.0 0.0" rpy="0.0 0.0 1.5707963267948966"/>
      <geometry>
        <box size="2.8739999999999997 0.06 0.6"/>
      </geometry>
    </collision>
  </link>
  <joint name="wall_4_center_joint" type="fixed">
    <origin xyz="4.13 3.92 0.3" rpy="0 0 0"/>
    <parent link="urdf_offset"/>
    <child link="wall_4_link"/>
  </joint>
  <link name="wall_4_link">
    <visual>
      <origin xyz="0.0 0.0 0.0" rpy="0.0 0.0 0.0"/>
      <geometry>
        <box size="2.6799999999999997 0.06 0.6"/>
      </geometry>
      <material name="wall_pink"/>
    </visual>
    <collision>
      <origin xyz="0.0 0.0 0.0" rpy="0.0 0.0 0.0"/>
      <geometry>
        <box size="2.6799999999999997 0.06 0.6"/>
      </geometry>
    </collision>
  </link>
  <joint name="wall_5_center_joint" type="fixed">
    <origin xyz="0.25 5.445 0.3" rpy="0 0 0"/>
    <parent link="urdf_offset"/>
    <child link="wall_5_link"/>
  </joint>
  <link name="wall_5_link">
    <visual>
      <origin xyz="0.0 0.0 0.0" rpy="0.0 0.0 1.5707963267948966"/>
      <geometry>
        <box size="2.3500000000000005 0.06 0.6"/>
      </geometry>
      <material name="wall_pink"/>
    </visual>
    <collision>
      <origin xyz="0.0 0.0 0.0" rpy="0.0 0.0 1.5707963267948966"/>
      <geometry>
        <box size="2.3500000000000005 0.06 0.6"/>
      </geometry>
    </collision>
  </link>
  <joint name="wall_9_center_joint" type="fixed">
    <origin xyz="0.97 -2.47 0.3" rpy="0 0 0"/>
    <parent link="urdf_offset"/>
    <child link="wall_9_link"/>
  </joint>
  <link name="wall_9_link">
    <visual>
      <origin xyz="0.0 0.0 0.0" rpy="0.0 0.0 0.0"/>
      <geometry>
        <box size="0.68 0.06 0.6"/>
      </geometry>
      <material name="wall_pink"/>
    </visual>
    <collision>
      <origin xyz="0.0 0.0 0.0" rpy="0.0 0.0 0.0"/>
      <geometry>
        <box size="0.68 0.06 0.6"/>
      </geometry>
    </collision>
  </link>
  <joint name="wall_10_center_joint" type="fixed">
    <origin xyz="0.6645000000000001 -2.0 0.3" rpy="0 0 0"/>
    <parent link="urdf_offset"/>
    <child link="wall_10_link"/>
  </joint>
  <link name="wall_10_link">
    <visual>
      <origin xyz="0.0 0.0 0.0" rpy="0.0 0.0 1.560012431117244"/>
      <geometry>
        <box size="1.0200593120010226 0.06 0.6"/>
      </geometry>
      <material name="wall_pink"/>
    </visual>
    <collision>
      <origin xyz="0.0 0.0 0.0" rpy="0.0 0.0 1.560012431117244"/>
      <geometry>
        <box size="1.0200593120010226 0.06 0.6"/>
      </geometry>
    </collision>
  </link>
  <joint name="wall_11_center_joint" type="fixed">
    <origin xyz="0.457 -1.5 0.3" rpy="0 0 0"/>
    <parent link="urdf_offset"/>
    <child link="wall_11_link"/>
  </joint>
  <link name="wall_11_link">
    <visual>
      <origin xyz="0.0 0.0 0.0" rpy="0.0 0.0 0.0"/>
      <geometry>
        <box size="0.404 0.06 0.6"/>
      </geometry>
      <material name="wall_pink"/>
    </visual>
    <collision>
      <origin xyz="0.0 0.0 0.0" rpy="0.0 0.0 0.0"/>
      <geometry>
        <box size="0.404 0.06 0.6"/>
      </geometry>
    </collision>
  </link>
  <joint name="wall_12_center_joint" type="fixed">
    <origin xyz="0.2575 -0.983 0.3" rpy="0 0 0"/>
    <parent link="urdf_offset"/>
    <child link="wall_12_link"/>
  </joint>
  <link name="wall_12_link">
    <visual>
      <origin xyz="0.0 0.0 0.0" rpy="0.0 0.0 1.566225974704932"/>
      <geometry>
        <box size="1.0940114259001137 0.06 0.6"/>
      </geometry>
      <material name="wall_pink"/>
    </visual>
    <collision>
      <origin xyz="0.0 0.0 0.0" rpy="0.0 0.0 1.566225974704932"/>
      <geometry>
        <box size="1.0940114259001137 0.06 0.6"/>
      </geometry>
    </collision>
  </link>
  <joint name="wall_13_center_joint" type="fixed">
    <origin xyz="0.41 -0.464 0.3" rpy="0 0 0"/>
    <parent link="urdf_offset"/>
    <child link="wall_13_link"/>
  </joint>
  <link name="wall_13_link">
    <visual>
      <origin xyz="0.0 0.0 0.0" rpy="0.0 0.0 0.0"/>
      <geometry>
        <box size="0.31999999999999995 0.06 0.6"/>
      </geometry>
      <material name="wall_pink"/>
    </visual>
    <collision>
      <origin xyz="0.0 0.0 0.0" rpy="0.0 0.0 0.0"/>
      <geometry>
        <box size="0.31999999999999995 0.06 0.6"/>
      </geometry>
    </collision>
  </link>
  <joint name="wall_14_center_joint" type="fixed">
    <origin xyz="2.915 6.62 0.3" rpy="0 0 0"/>
    <parent link="urdf_offset"/>
    <child link="wall_14_link"/>
  </joint>
  <link name="wall_14_link">
    <visual>
      <origin xyz="0.0 0.0 0.0" rpy="0.0 0.0 0.0"/>
      <geometry>
        <box size="5.33 0.06 0.6"/>
      </geometry>
      <material name="wall_pink"/>
    </visual>
    <collision>
      <origin xyz="0.0 0.0 0.0" rpy="0.0 0.0 0.0"/>
      <geometry>
        <box size="5.33 0.06 0.6"/>
      </geometry>
    </collision>
  </link>
  <joint name="wall_15_center_joint" type="fixed">
    <origin xyz="5.54 4.96 0.3" rpy="0 0 0"/>
    <parent link="urdf_offset"/>
    <child link="wall_15_link"/>
  </joint>
  <link name="wall_15_link">
    <visual>
      <origin xyz="0.0 0.0 0.0" rpy="0.0 0.0 1.5467046033699754"/>
      <geometry>
        <box size="3.320963715550051 0.06 0.6"/>
      </geometry>
      <material name="wall_pink"/>
    </visual>
    <collision>
      <origin xyz="0.0 0.0 0.0" rpy="0.0 0.0 1.5467046033699754"/>
      <geometry>
        <box size="3.320963715550051 0.06 0.6"/>
      </geometry>
    </collision>
  </link>
  <joint name="wall_16_center_joint" type="fixed">
    <origin xyz="5.5 0.4099999999999999 0.3" rpy="0 0 0"/>
    <parent link="urdf_offset"/>
    <child link="wall_16_link"/>
  </joint>
  <link name="wall_16_link">
    <visual>
      <origin xyz="0.0 0.0 0.0" rpy="0.0 0.0 1.5707963267948966"/>
      <geometry>
        <box size="5.779999999999999 0.06 0.6"/>
      </geometry>
      <material name="wall_pink"/>
    </visual>
    <collision>
      <origin xyz="0.0 0.0 0.0" rpy="0.0 0.0 1.5707963267948966"/>
      <geometry>
        <box size="5.779999999999999 0.06 0.6"/>
      </geometry>
    </collision>
  </link>
  <joint name="world_iai_kitchen:kitchen:room_joint" type="fixed">
    <origin xyz="2.9 0.7 -0.05" rpy="0.0 0.0 0.0"/>
    <parent link="urdf_offset"/>
    <child link="iai_kitchen:kitchen:room_center_link"/>
  </joint>
  <link name="iai_kitchen:kitchen:room_center_link">
    <visual>
      <geometry>
        <box size="5.28 5.3 0.01"/>
      </geometry>
      <material name="iai_kitchen:kitchen:color">
        <color rgba="0.0 0.0 1.0 0.5"/>
      </material>
    </visual>
    <collision>
      <geometry>
        <box size="5.28 5.3 0.01"/>
      </geometry>
    </collision>
  </link>
  <joint name="room_kitchen_entry_exit:entry_exit:connection_joint" type="fixed">
    <origin xyz="-2.3 -0.61 0.0" rpy="0.0 0.0 0.0"/>
    <parent link="iai_kitchen:kitchen:room_center_link"/>
    <child link="kitchen_entry_exit:entry_exit:link"/>
  </joint>
  <link name="kitchen_entry_exit:entry_exit:link"/>
  <joint name="world_arena:arena:room_joint" type="fixed">
    <origin xyz="2.1 0.54 -0.05" rpy="0.0 0.0 0.0"/>
    <parent link="urdf_offset"/>
    <child link="arena:arena:room_center_link"/>
  </joint>
  <link name="arena:arena:room_center_link">
    <visual>
      <geometry>
        <box size="3.0 2.75 0.01"/>
      </geometry>
      <material name="arena:arena:color">
        <color rgba="1.0 0.0 0.0 0.1"/>
      </material>
    </visual>
    <collision>
      <geometry>
        <box size="3.0 2.75 0.01"/>
      </geometry>
    </collision>
  </link>
  <joint name="room_arena_entry_exit:entry_exit:connection_joint" type="fixed">
    <origin xyz="-1.4300000000000002 -0.54 0.0" rpy="0.0 0.0 0.0"/>
    <parent link="arena:arena:room_center_link"/>
    <child link="arena_entry_exit:entry_exit:link"/>
  </joint>
  <link name="arena_entry_exit:entry_exit:link"/>
  <joint name="world_living_room:living_room:room_joint" type="fixed">
    <origin xyz="2.9 4.95 -0.05" rpy="0.0 0.0 0.0"/>
    <parent link="urdf_offset"/>
    <child link="living_room:living_room:room_center_link"/>
  </joint>
  <link name="living_room:living_room:room_center_link">
    <visual>
      <geometry>
        <box size="5.3 3.28 0.01"/>
      </geometry>
      <material name="living_room:living_room:color">
        <color rgba="0.0 0.0 1.0 0.5"/>
      </material>
    </visual>
    <collision>
      <geometry>
        <box size="5.3 3.28 0.01"/>
      </geometry>
    </collision>
  </link>
  <joint name="room_living_room_entry_exit:entry_exit:connection_joint" type="fixed">
    <origin xyz="-2.6399999999999997 -1.1400000000000001 0.0" rpy="0.0 0.0 0.0"/>
    <parent link="living_room:living_room:room_center_link"/>
    <child link="living_room_entry_exit:entry_exit:link"/>
  </joint>
  <link name="living_room_entry_exit:entry_exit:link"/>
  <link name="kitchen_main">
    <inertial>
      <origin xyz="0.0 0.0 0.0" rpy="0.0 0.0 0.0"/>
      <mass value="1.0"/>
      <inertia ixx="1.0" ixy="0.0" ixz="0.0" iyy="1.0" iyz="0.0" izz="1.0"/>
    </inertial>
  </link>
  <joint name="kitchen_main" type="fixed">
    <origin xyz="1.86 -2.2 0.0" rpy="0.0 0.0 1.57"/>
    <parent link="urdf_offset"/>
    <child link="kitchen_main"/>
  </joint>
  <joint name="kitchen_main_joint" type="fixed">
    <origin xyz="1.86 -2.2 0.0" rpy="0.0 0.0 1.57"/>
    <parent link="kitchen_main"/>
    <child link="sink_area_dish_washer_main"/>
  </joint>
  <link name="sink_area_dish_washer_main">
    <inertial>
      <origin xyz="0.0 0.0 0.0" rpy="0.0 0.0 0.0"/>
      <mass value="1.0"/>
      <inertia ixx="1.0" ixy="0.0" ixz="0.0" iyy="1.0" iyz="0.0" izz="1.0"/>
    </inertial>
    <visual>
      <origin xyz="0.0 0.0 0.0" rpy="0.0 0.0 0.0"/>
      <geometry>
        <mesh filename="package://iai_kitchen/meshes/misc/DishWasher.obj"/>
      </geometry>
    </visual>
    <collision>
      <origin xyz="0.0 0.0 0.0" rpy="0.0 0.0 0.0"/>
      <geometry>
        <mesh filename="package://iai_kitchen/meshes/misc/DishWasher.obj"/>
      </geometry>
    </collision>
  </link>
  <link name="sink_area_dish_washer_door">
    <inertial>
      <origin xyz="0.0 0.0 0.0" rpy="0.0 0.0 0.0"/>
      <mass value="1.0"/>
      <inertia ixx="1.0" ixy="0.0" ixz="0.0" iyy="1.0" iyz="0.0" izz="1.0"/>
    </inertial>
    <visual>
      <origin xyz="0.0 0.0 0.0" rpy="1.57079632679 0.0 0.0"/>
      <geometry>
        <mesh filename="package://iai_kitchen/meshes/misc/DishWasherDoor.obj"/>
      </geometry>
    </visual>
    <collision>
      <origin xyz="0.0 0.0 0.0" rpy="1.57079632679 0.0 0.0"/>
      <geometry>
        <mesh filename="package://iai_kitchen/meshes/misc/DishWasherDoor.obj"/>
      </geometry>
    </collision>
  </link>
  <link name="sink_area_dish_washer_door_handle">
    <inertial>
      <origin xyz="0.0 0.0 0.0" rpy="0.0 0.0 0.0"/>
      <mass value="1.0"/>
      <inertia ixx="1.0" ixy="0.0" ixz="0.0" iyy="1.0" iyz="0.0" izz="1.0"/>
    </inertial>
    <visual>
      <origin xyz="0.0 0.0 0.0" rpy="0.0 0.0 0.0"/>
      <geometry>
        <mesh filename="package://iai_kitchen/meshes/handles/Handle60.obj"/>
      </geometry>
    </visual>
    <collision>
      <origin xyz="0.0 0.0 0.0" rpy="0.0 0.0 0.0"/>
      <geometry>
        <mesh filename="package://iai_kitchen/meshes/handles/Handle60.obj"/>
      </geometry>
    </collision>
  </link>
  <link name="dishwasher_tab"/>
  <joint name="dishwasher_tab_joint" type="fixed">
    <origin xyz="-0.1 0.1 0.15" rpy="0.0 0.0 0.0"/>
    <parent link="sink_area_dish_washer_door_handle"/>
    <child link="dishwasher_tab"/>
  </joint>
  <joint name="sink_area_dish_washer_main_joint" type="fixed">
    <origin xyz="0.08 -0.78 0.44" rpy="0.0 0.0 0.0"/>
    <axis xyz="1.0 0.0 0.0"/>
    <parent link="kitchen_main"/>
    <child link="sink_area_dish_washer_main"/>
  </joint>
  <joint name="sink_area_dish_washer_door_joint" type="revolute">
    <origin xyz="0.27 0.0 -0.325" rpy="-1.57079632679 0.03 0.0"/>
    <axis xyz="0.0 0.0 1.0"/>
    <parent link="sink_area_dish_washer_main"/>
    <child link="sink_area_dish_washer_door"/>
    <limit effort="300.0" lower="0.0" upper="1.57079632679" velocity="10.0"/>
  </joint>
  <joint name="sink_area_dish_washer_door_handle_joint" type="fixed">
    <origin xyz="0.0625 -0.6325 0.0" rpy="-1.57079632679 0.0 0.0"/>
    <parent link="sink_area_dish_washer_door"/>
    <child link="sink_area_dish_washer_door_handle"/>
  </joint>
  <link name="iai_kitchen:arena:door_center">
    <visual>
      <origin xyz="0.4275 0.0 0.0" rpy="0.0 0.0 0.0"/>
      <geometry>
        <box size="0.855 0.04 2.0"/>
      </geometry>
      <material name="door_green"/>
    </visual>
    <collision>
      <origin xyz="0.4275 0.0 0.0" rpy="0.0 0.0 0.0"/>
      <geometry>
        <box size="0.855 0.04 2.0"/>
      </geometry>
    </collision>
  </link>
  <link name="iai_kitchen:arena:door_hinge">
    <visual>
      <origin xyz="0.0 0.0 0.0" rpy="0.0 0.0 0.0"/>
      <geometry>
        <box size="0.05 0.05 2.0"/>
      </geometry>
      <material name="hinge_red"/>
    </visual>
    <collision>
      <origin xyz="0.0 0.0 0.0" rpy="0.0 0.0 0.0"/>
      <geometry>
        <box size="0.05 0.05 2.0"/>
      </geometry>
    </collision>
  </link>
  <link name="iai_kitchen:arena:door_handle_link">
    <visual>
      <origin xyz="0.0 0.0 0.0" rpy="0.0 0.0 0.0"/>
      <geometry>
        <cylinder radius="0.013" length="0.1"/>
      </geometry>
    </visual>
    <collision>
      <origin xyz="0.0 0.0 0.0" rpy="0.0 0.0 0.0"/>
      <geometry>
        <cylinder radius="0.013" length="0.1"/>
      </geometry>
    </collision>
  </link>
  <link name="iai_kitchen:arena:door_handle_outside">
    <visual>
      <origin xyz="0.0 0.0 0.0" rpy="0.0 0.0 0.0"/>
      <geometry>
        <box size="0.015 0.15 0.01"/>
      </geometry>
      <material name="handle_blue"/>
    </visual>
    <collision>
      <origin xyz="0.0 0.0 0.0" rpy="0.0 0.0 0.0"/>
      <geometry>
        <box size="0.015 0.15 0.01"/>
      </geometry>
    </collision>
  </link>
  <link name="iai_kitchen:arena:door_handle_inside">
    <visual>
      <origin xyz="0.0 0.0 0.0" rpy="0.0 0.0 0.0"/>
      <geometry>
        <box size="0.015 0.15 0.01"/>
      </geometry>
      <material name="handle_blue"/>
    </visual>
    <collision>
      <origin xyz="0.0 0.0 0.0" rpy="0.0 0.0 0.0"/>
      <geometry>
        <box size="0.015 0.15 0.01"/>
      </geometry>
    </collision>
  </link>
  <joint name="iai_kitchen:arena:door_origin_revolute_joint" type="revolute">
    <origin xyz="0.0 0.0 0.0" rpy="0.0 0.0 1.57"/>
    <axis xyz="0.0 0.0 1.0"/>
    <parent link="iai_kitchen:arena:door_hinge"/>
    <child link="iai_kitchen:arena:door_center"/>
    <limit effort="100.0" lower="-1.4" upper="0.0" velocity="10.0"/>
  </joint>
  <joint name="iai_kitchen:arena:door_hinge_joint" type="fixed">
    <origin xyz="0.58 -0.44 1.04" rpy="0.0 0.0 0.0"/>
    <axis xyz="0.0 0.0 0.0"/>
    <parent link="urdf_offset"/>
    <child link="iai_kitchen:arena:door_hinge"/>
    <limit effort="1.0" lower="0.0" upper="1.5708" velocity="1.0"/>
  </joint>
  <joint name="iai_kitchen:arena:door_handle_joint" type="revolute">
    <origin xyz="0.82 0.0 0.02" rpy="1.5707963267948966 0.0 0.0"/>
    <axis xyz="0.0 0.0 1.0"/>
    <parent link="iai_kitchen:arena:door_center"/>
    <child link="iai_kitchen:arena:door_handle_link"/>
    <limit effort="1.0" lower="0.0" upper="0.6283185307179586" velocity="1.0"/>
  </joint>
  <joint name="iai_kitchen:arena:door_handle_inside_joint" type="fixed">
    <origin xyz="-0.04 0.0 0.06" rpy="0.0 0.0 1.5707963267948966"/>
    <parent link="iai_kitchen:arena:door_handle_link"/>
    <child link="iai_kitchen:arena:door_handle_inside"/>
  </joint>
  <joint name="iai_kitchen:arena:door_handle_outside_joint" type="fixed">
    <origin xyz="-0.075 0.0 -0.05" rpy="0.0 0.0 -1.5707963267948966"/>
    <parent link="iai_kitchen:arena:door_handle_link"/>
    <child link="iai_kitchen:arena:door_handle_outside"/>
  </joint>
  <link name="living_room:arena:door_center">
    <visual>
      <origin xyz="0.4275 0.0 0.0" rpy="0.0 0.0 0.0"/>
      <geometry>
        <box size="0.855 0.04 2.0"/>
      </geometry>
      <material name="door_green"/>
    </visual>
    <collision>
      <origin xyz="0.4275 0.0 0.0" rpy="0.0 0.0 0.0"/>
      <geometry>
        <box size="0.855 0.04 2.0"/>
      </geometry>
    </collision>
  </link>
  <link name="living_room:arena:door_hinge">
    <visual>
      <origin xyz="0.0 0.0 0.0" rpy="0.0 0.0 0.0"/>
      <geometry>
        <box size="0.05 0.05 2.0"/>
      </geometry>
      <material name="hinge_red"/>
    </visual>
    <collision>
      <origin xyz="0.0 0.0 0.0" rpy="0.0 0.0 0.0"/>
      <geometry>
        <box size="0.05 0.05 2.0"/>
      </geometry>
    </collision>
  </link>
  <link name="living_room:arena:door_handle_link">
    <visual>
      <origin xyz="0.0 0.0 0.0" rpy="0.0 0.0 0.0"/>
      <geometry>
        <cylinder radius="0.013" length="0.1"/>
      </geometry>
    </visual>
    <collision>
      <origin xyz="0.0 0.0 0.0" rpy="0.0 0.0 0.0"/>
      <geometry>
        <cylinder radius="0.013" length="0.1"/>
      </geometry>
    </collision>
  </link>
  <link name="living_room:arena:door_handle_outside">
    <visual>
      <origin xyz="0.0 0.0 0.0" rpy="0.0 0.0 0.0"/>
      <geometry>
        <box size="0.015 0.15 0.01"/>
      </geometry>
      <material name="handle_blue"/>
    </visual>
    <collision>
      <origin xyz="0.0 0.0 0.0" rpy="0.0 0.0 0.0"/>
      <geometry>
        <box size="0.015 0.15 0.01"/>
      </geometry>
    </collision>
  </link>
  <link name="living_room:arena:door_handle_inside">
    <visual>
      <origin xyz="0.0 0.0 0.0" rpy="0.0 0.0 0.0"/>
      <geometry>
        <box size="0.015 0.15 0.01"/>
      </geometry>
      <material name="handle_blue"/>
    </visual>
    <collision>
      <origin xyz="0.0 0.0 0.0" rpy="0.0 0.0 0.0"/>
      <geometry>
        <box size="0.015 0.15 0.01"/>
      </geometry>
    </collision>
  </link>
  <joint name="living_room:arena:door_origin_revolute_joint" type="revolute">
    <origin xyz="0.0 0.0 0.0" rpy="0.0 0.0 1.57"/>
    <axis xyz="0.0 0.0 1.0"/>
    <parent link="living_room:arena:door_hinge"/>
    <child link="living_room:arena:door_center"/>
    <limit effort="100.0" lower="-1.4" upper="0.0" velocity="10.0"/>
  </joint>
  <joint name="living_room:arena:door_hinge_joint" type="fixed">
    <origin xyz="0.28 3.37 1.04" rpy="0.0 0.0 0.0"/>
    <axis xyz="0.0 0.0 0.0"/>
    <parent link="urdf_offset"/>
    <child link="living_room:arena:door_hinge"/>
    <limit effort="1.0" lower="0.0" upper="1.5708" velocity="1.0"/>
  </joint>
  <joint name="living_room:arena:door_handle_joint" type="revolute">
    <origin xyz="0.79 0.0 0.02" rpy="1.5707963267948966 0.0 0.0"/>
    <axis xyz="0.0 0.0 1.0"/>
    <parent link="living_room:arena:door_center"/>
    <child link="living_room:arena:door_handle_link"/>
    <limit effort="1.0" lower="0.0" upper="0.6283185307179586" velocity="1.0"/>
  </joint>
  <joint name="living_room:arena:door_handle_inside_joint" type="fixed">
    <origin xyz="-0.04 0.0 0.06" rpy="0.0 0.0 1.5707963267948966"/>
    <parent link="living_room:arena:door_handle_link"/>
    <child link="living_room:arena:door_handle_inside"/>
  </joint>
  <joint name="living_room:arena:door_handle_outside_joint" type="fixed">
    <origin xyz="-0.075 0.0 -0.05" rpy="0.0 0.0 -1.5707963267948966"/>
    <parent link="living_room:arena:door_handle_link"/>
    <child link="living_room:arena:door_handle_outside"/>
  </joint>
  <link name="urdf_main"/>
  <joint name="map_urdf_joint" type="fixed">
    <origin xyz="0.0 0.0 0.0" rpy="0.0 0.0 0.0"/>
    <parent link="urdf_main"/>
    <child link="urdf_offset"/>
  </joint>
  <link name="urdf_offset"/>
</robot>